[2023-01-04T16:39:38.334+0000] {taskinstance.py:1087} INFO - Dependencies all met for <TaskInstance: accidents_etl_pipeline.create_dashboard_task manual__2023-01-04T16:32:30.140376+00:00 [queued]>
[2023-01-04T16:39:38.344+0000] {taskinstance.py:1087} INFO - Dependencies all met for <TaskInstance: accidents_etl_pipeline.create_dashboard_task manual__2023-01-04T16:32:30.140376+00:00 [queued]>
[2023-01-04T16:39:38.345+0000] {taskinstance.py:1283} INFO - 
--------------------------------------------------------------------------------
[2023-01-04T16:39:38.345+0000] {taskinstance.py:1284} INFO - Starting attempt 2 of 2
[2023-01-04T16:39:38.350+0000] {taskinstance.py:1285} INFO - 
--------------------------------------------------------------------------------
[2023-01-04T16:39:38.367+0000] {taskinstance.py:1304} INFO - Executing <Task(PythonOperator): create_dashboard_task> on 2023-01-04 16:32:30.140376+00:00
[2023-01-04T16:39:38.373+0000] {standard_task_runner.py:55} INFO - Started process 343 to run task
[2023-01-04T16:39:38.376+0000] {standard_task_runner.py:82} INFO - Running: ['***', 'tasks', 'run', 'accidents_etl_pipeline', 'create_dashboard_task', 'manual__2023-01-04T16:32:30.140376+00:00', '--job-id', '67', '--raw', '--subdir', 'DAGS_FOLDER/accidents_etl.py', '--cfg-path', '/tmp/tmpursdnxxc']
[2023-01-04T16:39:38.379+0000] {standard_task_runner.py:83} INFO - Job 67: Subtask create_dashboard_task
[2023-01-04T16:39:38.449+0000] {task_command.py:389} INFO - Running <TaskInstance: accidents_etl_pipeline.create_dashboard_task manual__2023-01-04T16:32:30.140376+00:00 [running]> on host 4de77850e514
[2023-01-04T16:39:38.529+0000] {taskinstance.py:1513} INFO - Exporting the following env vars:
AIRFLOW_CTX_DAG_OWNER=***
AIRFLOW_CTX_DAG_ID=accidents_etl_pipeline
AIRFLOW_CTX_TASK_ID=create_dashboard_task
AIRFLOW_CTX_EXECUTION_DATE=2023-01-04T16:32:30.140376+00:00
AIRFLOW_CTX_TRY_NUMBER=2
AIRFLOW_CTX_DAG_RUN_ID=manual__2023-01-04T16:32:30.140376+00:00
[2023-01-04T16:39:39.739+0000] {logging_mixin.py:137} WARNING - /home/***/.local/lib/python3.7/site-packages/***/operators/python.py:192 DtypeWarning: Columns (35) have mixed types.Specify dtype option on import or set low_memory=False.
[2023-01-04T16:39:40.939+0000] {logging_mixin.py:137} INFO - Dash is running on http://0.0.0.0:8050/
[2023-01-04T16:39:40.939+0000] {dash.py:1968} INFO - Dash is running on http://0.0.0.0:8050/

[2023-01-04T16:39:40.946+0000] {logging_mixin.py:137} INFO -  * Serving Flask app '***'
[2023-01-04T16:39:40.947+0000] {logging_mixin.py:137} INFO -  * Debug mode: off
[2023-01-04T16:39:40.948+0000] {_internal.py:224} INFO - [31m[1mWARNING: This is a development server. Do not use it in a production deployment. Use a production WSGI server instead.[0m
 * Running on all addresses (0.0.0.0)
 * Running on http://127.0.0.1:8050
 * Running on http://172.18.0.5:8050
[2023-01-04T16:39:40.948+0000] {_internal.py:224} INFO - [33mPress CTRL+C to quit[0m
[2023-01-04T16:41:23.347+0000] {_internal.py:224} INFO - 172.18.0.1 - - [04/Jan/2023 16:41:23] "GET / HTTP/1.1" 200 -
[2023-01-04T16:41:23.407+0000] {_internal.py:224} INFO - 172.18.0.1 - - [04/Jan/2023 16:41:23] "GET /_dash-component-suites/dash/deps/polyfill@7.v2_7_1m1672847646.12.1.min.js HTTP/1.1" 200 -
[2023-01-04T16:41:23.408+0000] {_internal.py:224} INFO - 172.18.0.1 - - [04/Jan/2023 16:41:23] "GET /_dash-component-suites/dash/deps/react@16.v2_7_1m1672847646.14.0.min.js HTTP/1.1" 200 -
[2023-01-04T16:41:23.410+0000] {_internal.py:224} INFO - 172.18.0.1 - - [04/Jan/2023 16:41:23] "GET /_dash-component-suites/dash/deps/react-dom@16.v2_7_1m1672847646.14.0.min.js HTTP/1.1" 200 -
[2023-01-04T16:41:23.415+0000] {_internal.py:224} INFO - 172.18.0.1 - - [04/Jan/2023 16:41:23] "GET /_dash-component-suites/dash/dash-renderer/build/dash_renderer.v2_7_1m1672847646.min.js HTTP/1.1" 200 -
[2023-01-04T16:41:23.419+0000] {_internal.py:224} INFO - 172.18.0.1 - - [04/Jan/2023 16:41:23] "GET /_dash-component-suites/dash/deps/prop-types@15.v2_7_1m1672847646.8.1.min.js HTTP/1.1" 200 -
[2023-01-04T16:41:23.422+0000] {_internal.py:224} INFO - 172.18.0.1 - - [04/Jan/2023 16:41:23] "GET /_dash-component-suites/dash/dcc/dash_core_components-shared.v2_7_1m1672847646.js HTTP/1.1" 200 -
[2023-01-04T16:41:23.423+0000] {_internal.py:224} INFO - 172.18.0.1 - - [04/Jan/2023 16:41:23] "GET /_dash-component-suites/dash/dcc/dash_core_components.v2_7_1m1672847646.js HTTP/1.1" 200 -
[2023-01-04T16:41:23.426+0000] {_internal.py:224} INFO - 172.18.0.1 - - [04/Jan/2023 16:41:23] "GET /_dash-component-suites/dash/html/dash_html_components.v2_0_7m1672847646.min.js HTTP/1.1" 200 -
[2023-01-04T16:41:23.430+0000] {_internal.py:224} INFO - 172.18.0.1 - - [04/Jan/2023 16:41:23] "GET /_dash-component-suites/dash/dash_table/bundle.v5_2_1m1672847646.js HTTP/1.1" 200 -
[2023-01-04T16:41:23.554+0000] {_internal.py:224} INFO - 172.18.0.1 - - [04/Jan/2023 16:41:23] "GET /_dash-dependencies HTTP/1.1" 200 -
[2023-01-04T16:41:23.878+0000] {_internal.py:224} INFO - 172.18.0.1 - - [04/Jan/2023 16:41:23] "GET /_dash-layout HTTP/1.1" 200 -
[2023-01-04T16:41:23.878+0000] {_internal.py:224} INFO - 172.18.0.1 - - [04/Jan/2023 16:41:23] "GET /_favicon.ico?v=2.7.1 HTTP/1.1" 200 -
[2023-01-04T16:41:23.958+0000] {_internal.py:224} INFO - 172.18.0.1 - - [04/Jan/2023 16:41:23] "GET /_dash-component-suites/dash/dcc/async-graph.js HTTP/1.1" 200 -
[2023-01-04T16:41:23.963+0000] {_internal.py:224} INFO - 172.18.0.1 - - [04/Jan/2023 16:41:23] "GET /_dash-component-suites/dash/dcc/async-plotlyjs.js HTTP/1.1" 200 -
[2023-01-04T18:55:04.903+0000] {local_task_job.py:143} ERROR - Heartbeat time limit exceeded!
[2023-01-04T18:55:04.920+0000] {process_utils.py:133} INFO - Sending Signals.SIGTERM to group 343. PIDs of all processes in the group: [343]
[2023-01-04T18:55:04.925+0000] {process_utils.py:84} INFO - Sending the signal Signals.SIGTERM to group 343
[2023-01-04T18:55:04.926+0000] {taskinstance.py:1483} ERROR - Received SIGTERM. Terminating subprocesses.
[2023-01-04T18:55:04.946+0000] {taskinstance.py:1772} ERROR - Task failed with exception
Traceback (most recent call last):
  File "/home/airflow/.local/lib/python3.7/site-packages/airflow/operators/python.py", line 175, in execute
    return_value = self.execute_callable()
  File "/home/airflow/.local/lib/python3.7/site-packages/airflow/operators/python.py", line 192, in execute_callable
    return self.python_callable(*self.op_args, **self.op_kwargs)
  File "/opt/airflow/dags/DashboardCreator.py", line 85, in createDashboard
    app.run_server(host = "0.0.0.0")
  File "/home/airflow/.local/lib/python3.7/site-packages/dash/dash.py", line 2133, in run_server
    self.run(*args, **kwargs)
  File "/home/airflow/.local/lib/python3.7/site-packages/dash/dash.py", line 1980, in run
    self.server.run(host=host, port=port, debug=debug, **flask_run_options)
  File "/home/airflow/.local/lib/python3.7/site-packages/flask/app.py", line 1188, in run
    run_simple(t.cast(str, host), port, self, **options)
  File "/home/airflow/.local/lib/python3.7/site-packages/werkzeug/serving.py", line 1098, in run_simple
    srv.serve_forever()
  File "/home/airflow/.local/lib/python3.7/site-packages/werkzeug/serving.py", line 741, in serve_forever
    super().serve_forever(poll_interval=poll_interval)
  File "/usr/local/lib/python3.7/socketserver.py", line 232, in serve_forever
    ready = selector.select(poll_interval)
  File "/usr/local/lib/python3.7/selectors.py", line 415, in select
    fd_event_list = self._selector.poll(timeout)
  File "/home/airflow/.local/lib/python3.7/site-packages/airflow/models/taskinstance.py", line 1485, in signal_handler
    raise AirflowException("Task received SIGTERM signal")
airflow.exceptions.AirflowException: Task received SIGTERM signal
[2023-01-04T18:55:04.968+0000] {taskinstance.py:1327} INFO - Marking task as FAILED. dag_id=accidents_etl_pipeline, task_id=create_dashboard_task, execution_date=20230104T163230, start_date=20230104T163938, end_date=20230104T185504
[2023-01-04T18:55:05.014+0000] {standard_task_runner.py:105} ERROR - Failed to execute job 67 for task create_dashboard_task (Task received SIGTERM signal; 343)
[2023-01-04T18:55:05.059+0000] {process_utils.py:79} INFO - Process psutil.Process(pid=343, status='terminated', exitcode=1, started='16:39:37') (343) terminated with exit code 1
