[2023-01-03T22:46:46.092+0000] {processor.py:153} INFO - Started process (PID=1933) to work on /opt/airflow/dags/accidents_etl.py
[2023-01-03T22:46:46.092+0000] {processor.py:743} INFO - Processing file /opt/airflow/dags/accidents_etl.py for tasks to queue
[2023-01-03T22:46:46.093+0000] {logging_mixin.py:137} INFO - [2023-01-03T22:46:46.093+0000] {dagbag.py:538} INFO - Filling up the DagBag from /opt/airflow/dags/accidents_etl.py
[2023-01-03T22:46:46.126+0000] {logging_mixin.py:137} INFO - [2023-01-03T22:46:46.122+0000] {dagbag.py:343} ERROR - Failed to import: /opt/airflow/dags/accidents_etl.py
Traceback (most recent call last):
  File "/home/airflow/.local/lib/python3.7/site-packages/airflow/models/dagbag.py", line 339, in parse
    loader.exec_module(new_module)
  File "<frozen importlib._bootstrap_external>", line 728, in exec_module
  File "<frozen importlib._bootstrap>", line 219, in _call_with_frames_removed
  File "/opt/airflow/dags/accidents_etl.py", line 5, in <module>
    from Milestone3_1 import clean_and_transform
ModuleNotFoundError: No module named 'Milestone3_1'
[2023-01-03T22:46:46.127+0000] {processor.py:755} WARNING - No viable dags retrieved from /opt/airflow/dags/accidents_etl.py
[2023-01-03T22:46:46.146+0000] {processor.py:175} INFO - Processing /opt/airflow/dags/accidents_etl.py took 0.057 seconds
[2023-01-03T22:47:16.273+0000] {processor.py:153} INFO - Started process (PID=1986) to work on /opt/airflow/dags/accidents_etl.py
[2023-01-03T22:47:16.275+0000] {processor.py:743} INFO - Processing file /opt/airflow/dags/accidents_etl.py for tasks to queue
[2023-01-03T22:47:16.276+0000] {logging_mixin.py:137} INFO - [2023-01-03T22:47:16.276+0000] {dagbag.py:538} INFO - Filling up the DagBag from /opt/airflow/dags/accidents_etl.py
[2023-01-03T22:47:16.296+0000] {logging_mixin.py:137} INFO - [2023-01-03T22:47:16.292+0000] {dagbag.py:343} ERROR - Failed to import: /opt/airflow/dags/accidents_etl.py
Traceback (most recent call last):
  File "/home/airflow/.local/lib/python3.7/site-packages/airflow/models/dagbag.py", line 339, in parse
    loader.exec_module(new_module)
  File "<frozen importlib._bootstrap_external>", line 728, in exec_module
  File "<frozen importlib._bootstrap>", line 219, in _call_with_frames_removed
  File "/opt/airflow/dags/accidents_etl.py", line 5, in <module>
    from Milestone3_1 import clean_and_transform
ModuleNotFoundError: No module named 'Milestone3_1'
[2023-01-03T22:47:16.296+0000] {processor.py:755} WARNING - No viable dags retrieved from /opt/airflow/dags/accidents_etl.py
[2023-01-03T22:47:16.322+0000] {processor.py:175} INFO - Processing /opt/airflow/dags/accidents_etl.py took 0.052 seconds
[2023-01-03T22:47:46.484+0000] {processor.py:153} INFO - Started process (PID=2039) to work on /opt/airflow/dags/accidents_etl.py
[2023-01-03T22:47:46.486+0000] {processor.py:743} INFO - Processing file /opt/airflow/dags/accidents_etl.py for tasks to queue
[2023-01-03T22:47:46.487+0000] {logging_mixin.py:137} INFO - [2023-01-03T22:47:46.487+0000] {dagbag.py:538} INFO - Filling up the DagBag from /opt/airflow/dags/accidents_etl.py
[2023-01-03T22:47:46.509+0000] {logging_mixin.py:137} INFO - [2023-01-03T22:47:46.506+0000] {dagbag.py:343} ERROR - Failed to import: /opt/airflow/dags/accidents_etl.py
Traceback (most recent call last):
  File "/home/airflow/.local/lib/python3.7/site-packages/airflow/models/dagbag.py", line 339, in parse
    loader.exec_module(new_module)
  File "<frozen importlib._bootstrap_external>", line 728, in exec_module
  File "<frozen importlib._bootstrap>", line 219, in _call_with_frames_removed
  File "/opt/airflow/dags/accidents_etl.py", line 5, in <module>
    from Milestone3_1 import clean_and_transform
ModuleNotFoundError: No module named 'Milestone3_1'
[2023-01-03T22:47:46.510+0000] {processor.py:755} WARNING - No viable dags retrieved from /opt/airflow/dags/accidents_etl.py
[2023-01-03T22:47:46.615+0000] {processor.py:175} INFO - Processing /opt/airflow/dags/accidents_etl.py took 0.136 seconds
[2023-01-03T22:48:16.670+0000] {processor.py:153} INFO - Started process (PID=2116) to work on /opt/airflow/dags/accidents_etl.py
[2023-01-03T22:48:16.672+0000] {processor.py:743} INFO - Processing file /opt/airflow/dags/accidents_etl.py for tasks to queue
[2023-01-03T22:48:16.674+0000] {logging_mixin.py:137} INFO - [2023-01-03T22:48:16.673+0000] {dagbag.py:538} INFO - Filling up the DagBag from /opt/airflow/dags/accidents_etl.py
[2023-01-03T22:48:16.691+0000] {logging_mixin.py:137} INFO - [2023-01-03T22:48:16.688+0000] {dagbag.py:343} ERROR - Failed to import: /opt/airflow/dags/accidents_etl.py
Traceback (most recent call last):
  File "/home/airflow/.local/lib/python3.7/site-packages/airflow/models/dagbag.py", line 339, in parse
    loader.exec_module(new_module)
  File "<frozen importlib._bootstrap_external>", line 728, in exec_module
  File "<frozen importlib._bootstrap>", line 219, in _call_with_frames_removed
  File "/opt/airflow/dags/accidents_etl.py", line 5, in <module>
    from Milestone3_1 import clean_and_transform
ModuleNotFoundError: No module named 'Milestone3_1'
[2023-01-03T22:48:16.692+0000] {processor.py:755} WARNING - No viable dags retrieved from /opt/airflow/dags/accidents_etl.py
[2023-01-03T22:48:16.718+0000] {processor.py:175} INFO - Processing /opt/airflow/dags/accidents_etl.py took 0.051 seconds
[2023-01-03T22:48:46.841+0000] {processor.py:153} INFO - Started process (PID=2169) to work on /opt/airflow/dags/accidents_etl.py
[2023-01-03T22:48:46.842+0000] {processor.py:743} INFO - Processing file /opt/airflow/dags/accidents_etl.py for tasks to queue
[2023-01-03T22:48:46.842+0000] {logging_mixin.py:137} INFO - [2023-01-03T22:48:46.842+0000] {dagbag.py:538} INFO - Filling up the DagBag from /opt/airflow/dags/accidents_etl.py
[2023-01-03T22:48:46.861+0000] {logging_mixin.py:137} INFO - [2023-01-03T22:48:46.858+0000] {dagbag.py:343} ERROR - Failed to import: /opt/airflow/dags/accidents_etl.py
Traceback (most recent call last):
  File "/home/airflow/.local/lib/python3.7/site-packages/airflow/models/dagbag.py", line 339, in parse
    loader.exec_module(new_module)
  File "<frozen importlib._bootstrap_external>", line 728, in exec_module
  File "<frozen importlib._bootstrap>", line 219, in _call_with_frames_removed
  File "/opt/airflow/dags/accidents_etl.py", line 5, in <module>
    from Milestone3_1 import clean_and_transform
ModuleNotFoundError: No module named 'Milestone3_1'
[2023-01-03T22:48:46.862+0000] {processor.py:755} WARNING - No viable dags retrieved from /opt/airflow/dags/accidents_etl.py
[2023-01-03T22:48:46.887+0000] {processor.py:175} INFO - Processing /opt/airflow/dags/accidents_etl.py took 0.049 seconds
[2023-01-03T22:49:17.073+0000] {processor.py:153} INFO - Started process (PID=2247) to work on /opt/airflow/dags/accidents_etl.py
[2023-01-03T22:49:17.074+0000] {processor.py:743} INFO - Processing file /opt/airflow/dags/accidents_etl.py for tasks to queue
[2023-01-03T22:49:17.076+0000] {logging_mixin.py:137} INFO - [2023-01-03T22:49:17.075+0000] {dagbag.py:538} INFO - Filling up the DagBag from /opt/airflow/dags/accidents_etl.py
[2023-01-03T22:49:17.098+0000] {logging_mixin.py:137} INFO - [2023-01-03T22:49:17.095+0000] {dagbag.py:343} ERROR - Failed to import: /opt/airflow/dags/accidents_etl.py
Traceback (most recent call last):
  File "/home/airflow/.local/lib/python3.7/site-packages/airflow/models/dagbag.py", line 339, in parse
    loader.exec_module(new_module)
  File "<frozen importlib._bootstrap_external>", line 728, in exec_module
  File "<frozen importlib._bootstrap>", line 219, in _call_with_frames_removed
  File "/opt/airflow/dags/accidents_etl.py", line 5, in <module>
    from Milestone3_1 import clean_and_transform
ModuleNotFoundError: No module named 'Milestone3_1'
[2023-01-03T22:49:17.099+0000] {processor.py:755} WARNING - No viable dags retrieved from /opt/airflow/dags/accidents_etl.py
[2023-01-03T22:49:17.132+0000] {processor.py:175} INFO - Processing /opt/airflow/dags/accidents_etl.py took 0.065 seconds
[2023-01-03T22:49:47.246+0000] {processor.py:153} INFO - Started process (PID=2300) to work on /opt/airflow/dags/accidents_etl.py
[2023-01-03T22:49:47.247+0000] {processor.py:743} INFO - Processing file /opt/airflow/dags/accidents_etl.py for tasks to queue
[2023-01-03T22:49:47.248+0000] {logging_mixin.py:137} INFO - [2023-01-03T22:49:47.248+0000] {dagbag.py:538} INFO - Filling up the DagBag from /opt/airflow/dags/accidents_etl.py
[2023-01-03T22:49:47.269+0000] {logging_mixin.py:137} INFO - [2023-01-03T22:49:47.265+0000] {dagbag.py:343} ERROR - Failed to import: /opt/airflow/dags/accidents_etl.py
Traceback (most recent call last):
  File "/home/airflow/.local/lib/python3.7/site-packages/airflow/models/dagbag.py", line 339, in parse
    loader.exec_module(new_module)
  File "<frozen importlib._bootstrap_external>", line 728, in exec_module
  File "<frozen importlib._bootstrap>", line 219, in _call_with_frames_removed
  File "/opt/airflow/dags/accidents_etl.py", line 5, in <module>
    from Milestone3_1 import clean_and_transform
ModuleNotFoundError: No module named 'Milestone3_1'
[2023-01-03T22:49:47.271+0000] {processor.py:755} WARNING - No viable dags retrieved from /opt/airflow/dags/accidents_etl.py
[2023-01-03T22:49:47.297+0000] {processor.py:175} INFO - Processing /opt/airflow/dags/accidents_etl.py took 0.057 seconds
[2023-01-03T22:50:17.476+0000] {processor.py:153} INFO - Started process (PID=2359) to work on /opt/airflow/dags/accidents_etl.py
[2023-01-03T22:50:17.477+0000] {processor.py:743} INFO - Processing file /opt/airflow/dags/accidents_etl.py for tasks to queue
[2023-01-03T22:50:17.477+0000] {logging_mixin.py:137} INFO - [2023-01-03T22:50:17.477+0000] {dagbag.py:538} INFO - Filling up the DagBag from /opt/airflow/dags/accidents_etl.py
[2023-01-03T22:50:17.496+0000] {logging_mixin.py:137} INFO - [2023-01-03T22:50:17.493+0000] {dagbag.py:343} ERROR - Failed to import: /opt/airflow/dags/accidents_etl.py
Traceback (most recent call last):
  File "/home/airflow/.local/lib/python3.7/site-packages/airflow/models/dagbag.py", line 339, in parse
    loader.exec_module(new_module)
  File "<frozen importlib._bootstrap_external>", line 728, in exec_module
  File "<frozen importlib._bootstrap>", line 219, in _call_with_frames_removed
  File "/opt/airflow/dags/accidents_etl.py", line 5, in <module>
    from Milestone3_1 import clean_and_transform
ModuleNotFoundError: No module named 'Milestone3_1'
[2023-01-03T22:50:17.497+0000] {processor.py:755} WARNING - No viable dags retrieved from /opt/airflow/dags/accidents_etl.py
[2023-01-03T22:50:17.524+0000] {processor.py:175} INFO - Processing /opt/airflow/dags/accidents_etl.py took 0.051 seconds
[2023-01-03T22:50:47.657+0000] {processor.py:153} INFO - Started process (PID=2430) to work on /opt/airflow/dags/accidents_etl.py
[2023-01-03T22:50:47.658+0000] {processor.py:743} INFO - Processing file /opt/airflow/dags/accidents_etl.py for tasks to queue
[2023-01-03T22:50:47.659+0000] {logging_mixin.py:137} INFO - [2023-01-03T22:50:47.658+0000] {dagbag.py:538} INFO - Filling up the DagBag from /opt/airflow/dags/accidents_etl.py
[2023-01-03T22:50:47.679+0000] {logging_mixin.py:137} INFO - [2023-01-03T22:50:47.677+0000] {dagbag.py:343} ERROR - Failed to import: /opt/airflow/dags/accidents_etl.py
Traceback (most recent call last):
  File "/home/airflow/.local/lib/python3.7/site-packages/airflow/models/dagbag.py", line 339, in parse
    loader.exec_module(new_module)
  File "<frozen importlib._bootstrap_external>", line 728, in exec_module
  File "<frozen importlib._bootstrap>", line 219, in _call_with_frames_removed
  File "/opt/airflow/dags/accidents_etl.py", line 5, in <module>
    from Milestone3_1 import clean_and_transform
ModuleNotFoundError: No module named 'Milestone3_1'
[2023-01-03T22:50:47.680+0000] {processor.py:755} WARNING - No viable dags retrieved from /opt/airflow/dags/accidents_etl.py
[2023-01-03T22:50:47.705+0000] {processor.py:175} INFO - Processing /opt/airflow/dags/accidents_etl.py took 0.052 seconds
[2023-01-03T22:51:17.855+0000] {processor.py:153} INFO - Started process (PID=2483) to work on /opt/airflow/dags/accidents_etl.py
[2023-01-03T22:51:17.856+0000] {processor.py:743} INFO - Processing file /opt/airflow/dags/accidents_etl.py for tasks to queue
[2023-01-03T22:51:17.857+0000] {logging_mixin.py:137} INFO - [2023-01-03T22:51:17.857+0000] {dagbag.py:538} INFO - Filling up the DagBag from /opt/airflow/dags/accidents_etl.py
[2023-01-03T22:51:17.875+0000] {logging_mixin.py:137} INFO - [2023-01-03T22:51:17.873+0000] {dagbag.py:343} ERROR - Failed to import: /opt/airflow/dags/accidents_etl.py
Traceback (most recent call last):
  File "/home/airflow/.local/lib/python3.7/site-packages/airflow/models/dagbag.py", line 339, in parse
    loader.exec_module(new_module)
  File "<frozen importlib._bootstrap_external>", line 728, in exec_module
  File "<frozen importlib._bootstrap>", line 219, in _call_with_frames_removed
  File "/opt/airflow/dags/accidents_etl.py", line 5, in <module>
    from Milestone3_1 import clean_and_transform
ModuleNotFoundError: No module named 'Milestone3_1'
[2023-01-03T22:51:17.876+0000] {processor.py:755} WARNING - No viable dags retrieved from /opt/airflow/dags/accidents_etl.py
[2023-01-03T22:51:17.898+0000] {processor.py:175} INFO - Processing /opt/airflow/dags/accidents_etl.py took 0.045 seconds
[2023-01-03T22:51:48.059+0000] {processor.py:153} INFO - Started process (PID=2560) to work on /opt/airflow/dags/accidents_etl.py
[2023-01-03T22:51:48.060+0000] {processor.py:743} INFO - Processing file /opt/airflow/dags/accidents_etl.py for tasks to queue
[2023-01-03T22:51:48.061+0000] {logging_mixin.py:137} INFO - [2023-01-03T22:51:48.061+0000] {dagbag.py:538} INFO - Filling up the DagBag from /opt/airflow/dags/accidents_etl.py
[2023-01-03T22:51:48.078+0000] {logging_mixin.py:137} INFO - [2023-01-03T22:51:48.076+0000] {dagbag.py:343} ERROR - Failed to import: /opt/airflow/dags/accidents_etl.py
Traceback (most recent call last):
  File "/home/airflow/.local/lib/python3.7/site-packages/airflow/models/dagbag.py", line 339, in parse
    loader.exec_module(new_module)
  File "<frozen importlib._bootstrap_external>", line 728, in exec_module
  File "<frozen importlib._bootstrap>", line 219, in _call_with_frames_removed
  File "/opt/airflow/dags/accidents_etl.py", line 5, in <module>
    from Milestone3_1 import clean_and_transform
ModuleNotFoundError: No module named 'Milestone3_1'
[2023-01-03T22:51:48.079+0000] {processor.py:755} WARNING - No viable dags retrieved from /opt/airflow/dags/accidents_etl.py
[2023-01-03T22:51:48.102+0000] {processor.py:175} INFO - Processing /opt/airflow/dags/accidents_etl.py took 0.046 seconds
[2023-01-03T22:52:18.236+0000] {processor.py:153} INFO - Started process (PID=2613) to work on /opt/airflow/dags/accidents_etl.py
[2023-01-03T22:52:18.238+0000] {processor.py:743} INFO - Processing file /opt/airflow/dags/accidents_etl.py for tasks to queue
[2023-01-03T22:52:18.239+0000] {logging_mixin.py:137} INFO - [2023-01-03T22:52:18.239+0000] {dagbag.py:538} INFO - Filling up the DagBag from /opt/airflow/dags/accidents_etl.py
[2023-01-03T22:52:18.257+0000] {logging_mixin.py:137} INFO - [2023-01-03T22:52:18.254+0000] {dagbag.py:343} ERROR - Failed to import: /opt/airflow/dags/accidents_etl.py
Traceback (most recent call last):
  File "/home/airflow/.local/lib/python3.7/site-packages/airflow/models/dagbag.py", line 339, in parse
    loader.exec_module(new_module)
  File "<frozen importlib._bootstrap_external>", line 728, in exec_module
  File "<frozen importlib._bootstrap>", line 219, in _call_with_frames_removed
  File "/opt/airflow/dags/accidents_etl.py", line 5, in <module>
    from Milestone3_1 import clean_and_transform
ModuleNotFoundError: No module named 'Milestone3_1'
[2023-01-03T22:52:18.258+0000] {processor.py:755} WARNING - No viable dags retrieved from /opt/airflow/dags/accidents_etl.py
[2023-01-03T22:52:18.279+0000] {processor.py:175} INFO - Processing /opt/airflow/dags/accidents_etl.py took 0.048 seconds
[2023-01-03T22:52:48.421+0000] {processor.py:153} INFO - Started process (PID=2690) to work on /opt/airflow/dags/accidents_etl.py
[2023-01-03T22:52:48.422+0000] {processor.py:743} INFO - Processing file /opt/airflow/dags/accidents_etl.py for tasks to queue
[2023-01-03T22:52:48.423+0000] {logging_mixin.py:137} INFO - [2023-01-03T22:52:48.422+0000] {dagbag.py:538} INFO - Filling up the DagBag from /opt/airflow/dags/accidents_etl.py
[2023-01-03T22:52:48.444+0000] {logging_mixin.py:137} INFO - [2023-01-03T22:52:48.441+0000] {dagbag.py:343} ERROR - Failed to import: /opt/airflow/dags/accidents_etl.py
Traceback (most recent call last):
  File "/home/airflow/.local/lib/python3.7/site-packages/airflow/models/dagbag.py", line 339, in parse
    loader.exec_module(new_module)
  File "<frozen importlib._bootstrap_external>", line 728, in exec_module
  File "<frozen importlib._bootstrap>", line 219, in _call_with_frames_removed
  File "/opt/airflow/dags/accidents_etl.py", line 5, in <module>
    from Milestone3_1 import clean_and_transform
ModuleNotFoundError: No module named 'Milestone3_1'
[2023-01-03T22:52:48.445+0000] {processor.py:755} WARNING - No viable dags retrieved from /opt/airflow/dags/accidents_etl.py
[2023-01-03T22:52:48.469+0000] {processor.py:175} INFO - Processing /opt/airflow/dags/accidents_etl.py took 0.050 seconds
[2023-01-03T22:53:18.596+0000] {processor.py:153} INFO - Started process (PID=2743) to work on /opt/airflow/dags/accidents_etl.py
[2023-01-03T22:53:18.597+0000] {processor.py:743} INFO - Processing file /opt/airflow/dags/accidents_etl.py for tasks to queue
[2023-01-03T22:53:18.598+0000] {logging_mixin.py:137} INFO - [2023-01-03T22:53:18.598+0000] {dagbag.py:538} INFO - Filling up the DagBag from /opt/airflow/dags/accidents_etl.py
[2023-01-03T22:53:18.618+0000] {logging_mixin.py:137} INFO - [2023-01-03T22:53:18.615+0000] {dagbag.py:343} ERROR - Failed to import: /opt/airflow/dags/accidents_etl.py
Traceback (most recent call last):
  File "/home/airflow/.local/lib/python3.7/site-packages/airflow/models/dagbag.py", line 339, in parse
    loader.exec_module(new_module)
  File "<frozen importlib._bootstrap_external>", line 728, in exec_module
  File "<frozen importlib._bootstrap>", line 219, in _call_with_frames_removed
  File "/opt/airflow/dags/accidents_etl.py", line 5, in <module>
    from Milestone3_1 import clean_and_transform
ModuleNotFoundError: No module named 'Milestone3_1'
[2023-01-03T22:53:18.619+0000] {processor.py:755} WARNING - No viable dags retrieved from /opt/airflow/dags/accidents_etl.py
[2023-01-03T22:53:18.646+0000] {processor.py:175} INFO - Processing /opt/airflow/dags/accidents_etl.py took 0.053 seconds
[2023-01-03T22:53:48.794+0000] {processor.py:153} INFO - Started process (PID=2796) to work on /opt/airflow/dags/accidents_etl.py
[2023-01-03T22:53:48.795+0000] {processor.py:743} INFO - Processing file /opt/airflow/dags/accidents_etl.py for tasks to queue
[2023-01-03T22:53:48.796+0000] {logging_mixin.py:137} INFO - [2023-01-03T22:53:48.796+0000] {dagbag.py:538} INFO - Filling up the DagBag from /opt/airflow/dags/accidents_etl.py
[2023-01-03T22:53:48.816+0000] {logging_mixin.py:137} INFO - [2023-01-03T22:53:48.814+0000] {dagbag.py:343} ERROR - Failed to import: /opt/airflow/dags/accidents_etl.py
Traceback (most recent call last):
  File "/home/airflow/.local/lib/python3.7/site-packages/airflow/models/dagbag.py", line 339, in parse
    loader.exec_module(new_module)
  File "<frozen importlib._bootstrap_external>", line 728, in exec_module
  File "<frozen importlib._bootstrap>", line 219, in _call_with_frames_removed
  File "/opt/airflow/dags/accidents_etl.py", line 5, in <module>
    from Milestone3_1 import clean_and_transform
ModuleNotFoundError: No module named 'Milestone3_1'
[2023-01-03T22:53:48.817+0000] {processor.py:755} WARNING - No viable dags retrieved from /opt/airflow/dags/accidents_etl.py
[2023-01-03T22:53:48.838+0000] {processor.py:175} INFO - Processing /opt/airflow/dags/accidents_etl.py took 0.046 seconds
[2023-01-03T22:54:18.974+0000] {processor.py:153} INFO - Started process (PID=2873) to work on /opt/airflow/dags/accidents_etl.py
[2023-01-03T22:54:18.975+0000] {processor.py:743} INFO - Processing file /opt/airflow/dags/accidents_etl.py for tasks to queue
[2023-01-03T22:54:18.976+0000] {logging_mixin.py:137} INFO - [2023-01-03T22:54:18.976+0000] {dagbag.py:538} INFO - Filling up the DagBag from /opt/airflow/dags/accidents_etl.py
[2023-01-03T22:54:18.996+0000] {logging_mixin.py:137} INFO - [2023-01-03T22:54:18.993+0000] {dagbag.py:343} ERROR - Failed to import: /opt/airflow/dags/accidents_etl.py
Traceback (most recent call last):
  File "/home/airflow/.local/lib/python3.7/site-packages/airflow/models/dagbag.py", line 339, in parse
    loader.exec_module(new_module)
  File "<frozen importlib._bootstrap_external>", line 728, in exec_module
  File "<frozen importlib._bootstrap>", line 219, in _call_with_frames_removed
  File "/opt/airflow/dags/accidents_etl.py", line 5, in <module>
    from Milestone3_1 import clean_and_transform
ModuleNotFoundError: No module named 'Milestone3_1'
[2023-01-03T22:54:18.997+0000] {processor.py:755} WARNING - No viable dags retrieved from /opt/airflow/dags/accidents_etl.py
[2023-01-03T22:54:19.023+0000] {processor.py:175} INFO - Processing /opt/airflow/dags/accidents_etl.py took 0.053 seconds
[2023-01-03T22:54:49.167+0000] {processor.py:153} INFO - Started process (PID=2926) to work on /opt/airflow/dags/accidents_etl.py
[2023-01-03T22:54:49.169+0000] {processor.py:743} INFO - Processing file /opt/airflow/dags/accidents_etl.py for tasks to queue
[2023-01-03T22:54:49.171+0000] {logging_mixin.py:137} INFO - [2023-01-03T22:54:49.171+0000] {dagbag.py:538} INFO - Filling up the DagBag from /opt/airflow/dags/accidents_etl.py
[2023-01-03T22:54:49.191+0000] {logging_mixin.py:137} INFO - [2023-01-03T22:54:49.187+0000] {dagbag.py:343} ERROR - Failed to import: /opt/airflow/dags/accidents_etl.py
Traceback (most recent call last):
  File "/home/airflow/.local/lib/python3.7/site-packages/airflow/models/dagbag.py", line 339, in parse
    loader.exec_module(new_module)
  File "<frozen importlib._bootstrap_external>", line 728, in exec_module
  File "<frozen importlib._bootstrap>", line 219, in _call_with_frames_removed
  File "/opt/airflow/dags/accidents_etl.py", line 5, in <module>
    from Milestone3_1 import clean_and_transform
ModuleNotFoundError: No module named 'Milestone3_1'
[2023-01-03T22:54:49.191+0000] {processor.py:755} WARNING - No viable dags retrieved from /opt/airflow/dags/accidents_etl.py
[2023-01-03T22:54:49.216+0000] {processor.py:175} INFO - Processing /opt/airflow/dags/accidents_etl.py took 0.052 seconds
[2023-01-03T22:55:19.345+0000] {processor.py:153} INFO - Started process (PID=3003) to work on /opt/airflow/dags/accidents_etl.py
[2023-01-03T22:55:19.346+0000] {processor.py:743} INFO - Processing file /opt/airflow/dags/accidents_etl.py for tasks to queue
[2023-01-03T22:55:19.347+0000] {logging_mixin.py:137} INFO - [2023-01-03T22:55:19.346+0000] {dagbag.py:538} INFO - Filling up the DagBag from /opt/airflow/dags/accidents_etl.py
[2023-01-03T22:55:19.362+0000] {logging_mixin.py:137} INFO - [2023-01-03T22:55:19.360+0000] {dagbag.py:343} ERROR - Failed to import: /opt/airflow/dags/accidents_etl.py
Traceback (most recent call last):
  File "/home/airflow/.local/lib/python3.7/site-packages/airflow/models/dagbag.py", line 339, in parse
    loader.exec_module(new_module)
  File "<frozen importlib._bootstrap_external>", line 728, in exec_module
  File "<frozen importlib._bootstrap>", line 219, in _call_with_frames_removed
  File "/opt/airflow/dags/accidents_etl.py", line 5, in <module>
    from Milestone3_1 import clean_and_transform
ModuleNotFoundError: No module named 'Milestone3_1'
[2023-01-03T22:55:19.363+0000] {processor.py:755} WARNING - No viable dags retrieved from /opt/airflow/dags/accidents_etl.py
[2023-01-03T22:55:19.389+0000] {processor.py:175} INFO - Processing /opt/airflow/dags/accidents_etl.py took 0.048 seconds
[2023-01-03T22:55:49.549+0000] {processor.py:153} INFO - Started process (PID=3056) to work on /opt/airflow/dags/accidents_etl.py
[2023-01-03T22:55:49.550+0000] {processor.py:743} INFO - Processing file /opt/airflow/dags/accidents_etl.py for tasks to queue
[2023-01-03T22:55:49.552+0000] {logging_mixin.py:137} INFO - [2023-01-03T22:55:49.551+0000] {dagbag.py:538} INFO - Filling up the DagBag from /opt/airflow/dags/accidents_etl.py
[2023-01-03T22:55:49.572+0000] {logging_mixin.py:137} INFO - [2023-01-03T22:55:49.567+0000] {dagbag.py:343} ERROR - Failed to import: /opt/airflow/dags/accidents_etl.py
Traceback (most recent call last):
  File "/home/airflow/.local/lib/python3.7/site-packages/airflow/models/dagbag.py", line 339, in parse
    loader.exec_module(new_module)
  File "<frozen importlib._bootstrap_external>", line 728, in exec_module
  File "<frozen importlib._bootstrap>", line 219, in _call_with_frames_removed
  File "/opt/airflow/dags/accidents_etl.py", line 5, in <module>
    from Milestone3_1 import clean_and_transform
ModuleNotFoundError: No module named 'Milestone3_1'
[2023-01-03T22:55:49.573+0000] {processor.py:755} WARNING - No viable dags retrieved from /opt/airflow/dags/accidents_etl.py
[2023-01-03T22:55:49.593+0000] {processor.py:175} INFO - Processing /opt/airflow/dags/accidents_etl.py took 0.048 seconds
[2023-01-03T22:56:19.727+0000] {processor.py:153} INFO - Started process (PID=3118) to work on /opt/airflow/dags/accidents_etl.py
[2023-01-03T22:56:19.728+0000] {processor.py:743} INFO - Processing file /opt/airflow/dags/accidents_etl.py for tasks to queue
[2023-01-03T22:56:19.729+0000] {logging_mixin.py:137} INFO - [2023-01-03T22:56:19.728+0000] {dagbag.py:538} INFO - Filling up the DagBag from /opt/airflow/dags/accidents_etl.py
[2023-01-03T22:56:19.748+0000] {logging_mixin.py:137} INFO - [2023-01-03T22:56:19.745+0000] {dagbag.py:343} ERROR - Failed to import: /opt/airflow/dags/accidents_etl.py
Traceback (most recent call last):
  File "/home/airflow/.local/lib/python3.7/site-packages/airflow/models/dagbag.py", line 339, in parse
    loader.exec_module(new_module)
  File "<frozen importlib._bootstrap_external>", line 728, in exec_module
  File "<frozen importlib._bootstrap>", line 219, in _call_with_frames_removed
  File "/opt/airflow/dags/accidents_etl.py", line 5, in <module>
    from Milestone3_1 import clean_and_transform
ModuleNotFoundError: No module named 'Milestone3_1'
[2023-01-03T22:56:19.749+0000] {processor.py:755} WARNING - No viable dags retrieved from /opt/airflow/dags/accidents_etl.py
[2023-01-03T22:56:19.774+0000] {processor.py:175} INFO - Processing /opt/airflow/dags/accidents_etl.py took 0.052 seconds
[2023-01-03T22:56:49.943+0000] {processor.py:153} INFO - Started process (PID=3186) to work on /opt/airflow/dags/accidents_etl.py
[2023-01-03T22:56:49.944+0000] {processor.py:743} INFO - Processing file /opt/airflow/dags/accidents_etl.py for tasks to queue
[2023-01-03T22:56:49.945+0000] {logging_mixin.py:137} INFO - [2023-01-03T22:56:49.945+0000] {dagbag.py:538} INFO - Filling up the DagBag from /opt/airflow/dags/accidents_etl.py
[2023-01-03T22:56:49.967+0000] {logging_mixin.py:137} INFO - [2023-01-03T22:56:49.962+0000] {dagbag.py:343} ERROR - Failed to import: /opt/airflow/dags/accidents_etl.py
Traceback (most recent call last):
  File "/home/airflow/.local/lib/python3.7/site-packages/airflow/models/dagbag.py", line 339, in parse
    loader.exec_module(new_module)
  File "<frozen importlib._bootstrap_external>", line 728, in exec_module
  File "<frozen importlib._bootstrap>", line 219, in _call_with_frames_removed
  File "/opt/airflow/dags/accidents_etl.py", line 5, in <module>
    from Milestone3_1 import clean_and_transform
ModuleNotFoundError: No module named 'Milestone3_1'
[2023-01-03T22:56:49.970+0000] {processor.py:755} WARNING - No viable dags retrieved from /opt/airflow/dags/accidents_etl.py
[2023-01-03T22:56:49.997+0000] {processor.py:175} INFO - Processing /opt/airflow/dags/accidents_etl.py took 0.057 seconds
[2023-01-03T22:57:20.116+0000] {processor.py:153} INFO - Started process (PID=3239) to work on /opt/airflow/dags/accidents_etl.py
[2023-01-03T22:57:20.117+0000] {processor.py:743} INFO - Processing file /opt/airflow/dags/accidents_etl.py for tasks to queue
[2023-01-03T22:57:20.118+0000] {logging_mixin.py:137} INFO - [2023-01-03T22:57:20.118+0000] {dagbag.py:538} INFO - Filling up the DagBag from /opt/airflow/dags/accidents_etl.py
[2023-01-03T22:57:20.144+0000] {logging_mixin.py:137} INFO - [2023-01-03T22:57:20.138+0000] {dagbag.py:343} ERROR - Failed to import: /opt/airflow/dags/accidents_etl.py
Traceback (most recent call last):
  File "/home/airflow/.local/lib/python3.7/site-packages/airflow/models/dagbag.py", line 339, in parse
    loader.exec_module(new_module)
  File "<frozen importlib._bootstrap_external>", line 728, in exec_module
  File "<frozen importlib._bootstrap>", line 219, in _call_with_frames_removed
  File "/opt/airflow/dags/accidents_etl.py", line 5, in <module>
    from Milestone3_1 import clean_and_transform
ModuleNotFoundError: No module named 'Milestone3_1'
[2023-01-03T22:57:20.146+0000] {processor.py:755} WARNING - No viable dags retrieved from /opt/airflow/dags/accidents_etl.py
[2023-01-03T22:57:20.178+0000] {processor.py:175} INFO - Processing /opt/airflow/dags/accidents_etl.py took 0.066 seconds
[2023-01-03T22:57:50.337+0000] {processor.py:153} INFO - Started process (PID=3316) to work on /opt/airflow/dags/accidents_etl.py
[2023-01-03T22:57:50.338+0000] {processor.py:743} INFO - Processing file /opt/airflow/dags/accidents_etl.py for tasks to queue
[2023-01-03T22:57:50.339+0000] {logging_mixin.py:137} INFO - [2023-01-03T22:57:50.339+0000] {dagbag.py:538} INFO - Filling up the DagBag from /opt/airflow/dags/accidents_etl.py
[2023-01-03T22:57:50.359+0000] {logging_mixin.py:137} INFO - [2023-01-03T22:57:50.355+0000] {dagbag.py:343} ERROR - Failed to import: /opt/airflow/dags/accidents_etl.py
Traceback (most recent call last):
  File "/home/airflow/.local/lib/python3.7/site-packages/airflow/models/dagbag.py", line 339, in parse
    loader.exec_module(new_module)
  File "<frozen importlib._bootstrap_external>", line 728, in exec_module
  File "<frozen importlib._bootstrap>", line 219, in _call_with_frames_removed
  File "/opt/airflow/dags/accidents_etl.py", line 5, in <module>
    from Milestone3_1 import clean_and_transform
ModuleNotFoundError: No module named 'Milestone3_1'
[2023-01-03T22:57:50.360+0000] {processor.py:755} WARNING - No viable dags retrieved from /opt/airflow/dags/accidents_etl.py
[2023-01-03T22:57:50.387+0000] {processor.py:175} INFO - Processing /opt/airflow/dags/accidents_etl.py took 0.054 seconds
[2023-01-03T22:58:20.519+0000] {processor.py:153} INFO - Started process (PID=3369) to work on /opt/airflow/dags/accidents_etl.py
[2023-01-03T22:58:20.520+0000] {processor.py:743} INFO - Processing file /opt/airflow/dags/accidents_etl.py for tasks to queue
[2023-01-03T22:58:20.520+0000] {logging_mixin.py:137} INFO - [2023-01-03T22:58:20.520+0000] {dagbag.py:538} INFO - Filling up the DagBag from /opt/airflow/dags/accidents_etl.py
[2023-01-03T22:58:20.541+0000] {logging_mixin.py:137} INFO - [2023-01-03T22:58:20.537+0000] {dagbag.py:343} ERROR - Failed to import: /opt/airflow/dags/accidents_etl.py
Traceback (most recent call last):
  File "/home/airflow/.local/lib/python3.7/site-packages/airflow/models/dagbag.py", line 339, in parse
    loader.exec_module(new_module)
  File "<frozen importlib._bootstrap_external>", line 728, in exec_module
  File "<frozen importlib._bootstrap>", line 219, in _call_with_frames_removed
  File "/opt/airflow/dags/accidents_etl.py", line 5, in <module>
    from Milestone3_1 import clean_and_transform
ModuleNotFoundError: No module named 'Milestone3_1'
[2023-01-03T22:58:20.542+0000] {processor.py:755} WARNING - No viable dags retrieved from /opt/airflow/dags/accidents_etl.py
[2023-01-03T22:58:20.567+0000] {processor.py:175} INFO - Processing /opt/airflow/dags/accidents_etl.py took 0.052 seconds
[2023-01-03T22:58:50.714+0000] {processor.py:153} INFO - Started process (PID=3446) to work on /opt/airflow/dags/accidents_etl.py
[2023-01-03T22:58:50.714+0000] {processor.py:743} INFO - Processing file /opt/airflow/dags/accidents_etl.py for tasks to queue
[2023-01-03T22:58:50.715+0000] {logging_mixin.py:137} INFO - [2023-01-03T22:58:50.715+0000] {dagbag.py:538} INFO - Filling up the DagBag from /opt/airflow/dags/accidents_etl.py
[2023-01-03T22:58:50.735+0000] {logging_mixin.py:137} INFO - [2023-01-03T22:58:50.731+0000] {dagbag.py:343} ERROR - Failed to import: /opt/airflow/dags/accidents_etl.py
Traceback (most recent call last):
  File "/home/airflow/.local/lib/python3.7/site-packages/airflow/models/dagbag.py", line 339, in parse
    loader.exec_module(new_module)
  File "<frozen importlib._bootstrap_external>", line 728, in exec_module
  File "<frozen importlib._bootstrap>", line 219, in _call_with_frames_removed
  File "/opt/airflow/dags/accidents_etl.py", line 5, in <module>
    from Milestone3_1 import clean_and_transform
ModuleNotFoundError: No module named 'Milestone3_1'
[2023-01-03T22:58:50.736+0000] {processor.py:755} WARNING - No viable dags retrieved from /opt/airflow/dags/accidents_etl.py
[2023-01-03T22:58:50.764+0000] {processor.py:175} INFO - Processing /opt/airflow/dags/accidents_etl.py took 0.052 seconds
[2023-01-03T22:59:20.896+0000] {processor.py:153} INFO - Started process (PID=3499) to work on /opt/airflow/dags/accidents_etl.py
[2023-01-03T22:59:20.897+0000] {processor.py:743} INFO - Processing file /opt/airflow/dags/accidents_etl.py for tasks to queue
[2023-01-03T22:59:20.898+0000] {logging_mixin.py:137} INFO - [2023-01-03T22:59:20.897+0000] {dagbag.py:538} INFO - Filling up the DagBag from /opt/airflow/dags/accidents_etl.py
[2023-01-03T22:59:20.917+0000] {logging_mixin.py:137} INFO - [2023-01-03T22:59:20.915+0000] {dagbag.py:343} ERROR - Failed to import: /opt/airflow/dags/accidents_etl.py
Traceback (most recent call last):
  File "/home/airflow/.local/lib/python3.7/site-packages/airflow/models/dagbag.py", line 339, in parse
    loader.exec_module(new_module)
  File "<frozen importlib._bootstrap_external>", line 728, in exec_module
  File "<frozen importlib._bootstrap>", line 219, in _call_with_frames_removed
  File "/opt/airflow/dags/accidents_etl.py", line 5, in <module>
    from Milestone3_1 import clean_and_transform
ModuleNotFoundError: No module named 'Milestone3_1'
[2023-01-03T22:59:20.918+0000] {processor.py:755} WARNING - No viable dags retrieved from /opt/airflow/dags/accidents_etl.py
[2023-01-03T22:59:20.939+0000] {processor.py:175} INFO - Processing /opt/airflow/dags/accidents_etl.py took 0.046 seconds
[2023-01-03T22:59:51.092+0000] {processor.py:153} INFO - Started process (PID=3561) to work on /opt/airflow/dags/accidents_etl.py
[2023-01-03T22:59:51.093+0000] {processor.py:743} INFO - Processing file /opt/airflow/dags/accidents_etl.py for tasks to queue
[2023-01-03T22:59:51.094+0000] {logging_mixin.py:137} INFO - [2023-01-03T22:59:51.094+0000] {dagbag.py:538} INFO - Filling up the DagBag from /opt/airflow/dags/accidents_etl.py
[2023-01-03T22:59:51.113+0000] {logging_mixin.py:137} INFO - [2023-01-03T22:59:51.110+0000] {dagbag.py:343} ERROR - Failed to import: /opt/airflow/dags/accidents_etl.py
Traceback (most recent call last):
  File "/home/airflow/.local/lib/python3.7/site-packages/airflow/models/dagbag.py", line 339, in parse
    loader.exec_module(new_module)
  File "<frozen importlib._bootstrap_external>", line 728, in exec_module
  File "<frozen importlib._bootstrap>", line 219, in _call_with_frames_removed
  File "/opt/airflow/dags/accidents_etl.py", line 5, in <module>
    from Milestone3_1 import clean_and_transform
ModuleNotFoundError: No module named 'Milestone3_1'
[2023-01-03T22:59:51.114+0000] {processor.py:755} WARNING - No viable dags retrieved from /opt/airflow/dags/accidents_etl.py
[2023-01-03T22:59:51.137+0000] {processor.py:175} INFO - Processing /opt/airflow/dags/accidents_etl.py took 0.047 seconds
[2023-01-03T23:00:21.268+0000] {processor.py:153} INFO - Started process (PID=3629) to work on /opt/airflow/dags/accidents_etl.py
[2023-01-03T23:00:21.269+0000] {processor.py:743} INFO - Processing file /opt/airflow/dags/accidents_etl.py for tasks to queue
[2023-01-03T23:00:21.270+0000] {logging_mixin.py:137} INFO - [2023-01-03T23:00:21.270+0000] {dagbag.py:538} INFO - Filling up the DagBag from /opt/airflow/dags/accidents_etl.py
[2023-01-03T23:00:21.291+0000] {logging_mixin.py:137} INFO - [2023-01-03T23:00:21.287+0000] {dagbag.py:343} ERROR - Failed to import: /opt/airflow/dags/accidents_etl.py
Traceback (most recent call last):
  File "/home/airflow/.local/lib/python3.7/site-packages/airflow/models/dagbag.py", line 339, in parse
    loader.exec_module(new_module)
  File "<frozen importlib._bootstrap_external>", line 728, in exec_module
  File "<frozen importlib._bootstrap>", line 219, in _call_with_frames_removed
  File "/opt/airflow/dags/accidents_etl.py", line 5, in <module>
    from Milestone3_1 import clean_and_transform
ModuleNotFoundError: No module named 'Milestone3_1'
[2023-01-03T23:00:21.292+0000] {processor.py:755} WARNING - No viable dags retrieved from /opt/airflow/dags/accidents_etl.py
[2023-01-03T23:00:21.319+0000] {processor.py:175} INFO - Processing /opt/airflow/dags/accidents_etl.py took 0.055 seconds
[2023-01-03T23:00:51.457+0000] {processor.py:153} INFO - Started process (PID=3682) to work on /opt/airflow/dags/accidents_etl.py
[2023-01-03T23:00:51.458+0000] {processor.py:743} INFO - Processing file /opt/airflow/dags/accidents_etl.py for tasks to queue
[2023-01-03T23:00:51.459+0000] {logging_mixin.py:137} INFO - [2023-01-03T23:00:51.459+0000] {dagbag.py:538} INFO - Filling up the DagBag from /opt/airflow/dags/accidents_etl.py
[2023-01-03T23:00:51.477+0000] {logging_mixin.py:137} INFO - [2023-01-03T23:00:51.474+0000] {dagbag.py:343} ERROR - Failed to import: /opt/airflow/dags/accidents_etl.py
Traceback (most recent call last):
  File "/home/airflow/.local/lib/python3.7/site-packages/airflow/models/dagbag.py", line 339, in parse
    loader.exec_module(new_module)
  File "<frozen importlib._bootstrap_external>", line 728, in exec_module
  File "<frozen importlib._bootstrap>", line 219, in _call_with_frames_removed
  File "/opt/airflow/dags/accidents_etl.py", line 5, in <module>
    from Milestone3_1 import clean_and_transform
ModuleNotFoundError: No module named 'Milestone3_1'
[2023-01-03T23:00:51.478+0000] {processor.py:755} WARNING - No viable dags retrieved from /opt/airflow/dags/accidents_etl.py
[2023-01-03T23:00:51.509+0000] {processor.py:175} INFO - Processing /opt/airflow/dags/accidents_etl.py took 0.055 seconds
[2023-01-03T23:01:21.643+0000] {processor.py:153} INFO - Started process (PID=3760) to work on /opt/airflow/dags/accidents_etl.py
[2023-01-03T23:01:21.644+0000] {processor.py:743} INFO - Processing file /opt/airflow/dags/accidents_etl.py for tasks to queue
[2023-01-03T23:01:21.645+0000] {logging_mixin.py:137} INFO - [2023-01-03T23:01:21.644+0000] {dagbag.py:538} INFO - Filling up the DagBag from /opt/airflow/dags/accidents_etl.py
[2023-01-03T23:01:21.664+0000] {logging_mixin.py:137} INFO - [2023-01-03T23:01:21.661+0000] {dagbag.py:343} ERROR - Failed to import: /opt/airflow/dags/accidents_etl.py
Traceback (most recent call last):
  File "/home/airflow/.local/lib/python3.7/site-packages/airflow/models/dagbag.py", line 339, in parse
    loader.exec_module(new_module)
  File "<frozen importlib._bootstrap_external>", line 728, in exec_module
  File "<frozen importlib._bootstrap>", line 219, in _call_with_frames_removed
  File "/opt/airflow/dags/accidents_etl.py", line 5, in <module>
    from Milestone3_1 import clean_and_transform
ModuleNotFoundError: No module named 'Milestone3_1'
[2023-01-03T23:01:21.664+0000] {processor.py:755} WARNING - No viable dags retrieved from /opt/airflow/dags/accidents_etl.py
[2023-01-03T23:01:21.697+0000] {processor.py:175} INFO - Processing /opt/airflow/dags/accidents_etl.py took 0.057 seconds
[2023-01-03T23:01:51.852+0000] {processor.py:153} INFO - Started process (PID=3813) to work on /opt/airflow/dags/accidents_etl.py
[2023-01-03T23:01:51.853+0000] {processor.py:743} INFO - Processing file /opt/airflow/dags/accidents_etl.py for tasks to queue
[2023-01-03T23:01:51.854+0000] {logging_mixin.py:137} INFO - [2023-01-03T23:01:51.853+0000] {dagbag.py:538} INFO - Filling up the DagBag from /opt/airflow/dags/accidents_etl.py
[2023-01-03T23:01:51.874+0000] {logging_mixin.py:137} INFO - [2023-01-03T23:01:51.870+0000] {dagbag.py:343} ERROR - Failed to import: /opt/airflow/dags/accidents_etl.py
Traceback (most recent call last):
  File "/home/airflow/.local/lib/python3.7/site-packages/airflow/models/dagbag.py", line 339, in parse
    loader.exec_module(new_module)
  File "<frozen importlib._bootstrap_external>", line 728, in exec_module
  File "<frozen importlib._bootstrap>", line 219, in _call_with_frames_removed
  File "/opt/airflow/dags/accidents_etl.py", line 5, in <module>
    from Milestone3_1 import clean_and_transform
ModuleNotFoundError: No module named 'Milestone3_1'
[2023-01-03T23:01:51.876+0000] {processor.py:755} WARNING - No viable dags retrieved from /opt/airflow/dags/accidents_etl.py
[2023-01-03T23:01:51.898+0000] {processor.py:175} INFO - Processing /opt/airflow/dags/accidents_etl.py took 0.049 seconds
[2023-01-03T23:02:22.033+0000] {processor.py:153} INFO - Started process (PID=3890) to work on /opt/airflow/dags/accidents_etl.py
[2023-01-03T23:02:22.035+0000] {processor.py:743} INFO - Processing file /opt/airflow/dags/accidents_etl.py for tasks to queue
[2023-01-03T23:02:22.036+0000] {logging_mixin.py:137} INFO - [2023-01-03T23:02:22.036+0000] {dagbag.py:538} INFO - Filling up the DagBag from /opt/airflow/dags/accidents_etl.py
[2023-01-03T23:02:22.057+0000] {logging_mixin.py:137} INFO - [2023-01-03T23:02:22.054+0000] {dagbag.py:343} ERROR - Failed to import: /opt/airflow/dags/accidents_etl.py
Traceback (most recent call last):
  File "/home/airflow/.local/lib/python3.7/site-packages/airflow/models/dagbag.py", line 339, in parse
    loader.exec_module(new_module)
  File "<frozen importlib._bootstrap_external>", line 728, in exec_module
  File "<frozen importlib._bootstrap>", line 219, in _call_with_frames_removed
  File "/opt/airflow/dags/accidents_etl.py", line 5, in <module>
    from Milestone3_1 import clean_and_transform
ModuleNotFoundError: No module named 'Milestone3_1'
[2023-01-03T23:02:22.058+0000] {processor.py:755} WARNING - No viable dags retrieved from /opt/airflow/dags/accidents_etl.py
[2023-01-03T23:02:22.084+0000] {processor.py:175} INFO - Processing /opt/airflow/dags/accidents_etl.py took 0.055 seconds
[2023-01-03T23:02:52.228+0000] {processor.py:153} INFO - Started process (PID=3943) to work on /opt/airflow/dags/accidents_etl.py
[2023-01-03T23:02:52.229+0000] {processor.py:743} INFO - Processing file /opt/airflow/dags/accidents_etl.py for tasks to queue
[2023-01-03T23:02:52.229+0000] {logging_mixin.py:137} INFO - [2023-01-03T23:02:52.229+0000] {dagbag.py:538} INFO - Filling up the DagBag from /opt/airflow/dags/accidents_etl.py
[2023-01-03T23:02:52.250+0000] {logging_mixin.py:137} INFO - [2023-01-03T23:02:52.247+0000] {dagbag.py:343} ERROR - Failed to import: /opt/airflow/dags/accidents_etl.py
Traceback (most recent call last):
  File "/home/airflow/.local/lib/python3.7/site-packages/airflow/models/dagbag.py", line 339, in parse
    loader.exec_module(new_module)
  File "<frozen importlib._bootstrap_external>", line 728, in exec_module
  File "<frozen importlib._bootstrap>", line 219, in _call_with_frames_removed
  File "/opt/airflow/dags/accidents_etl.py", line 5, in <module>
    from Milestone3_1 import clean_and_transform
ModuleNotFoundError: No module named 'Milestone3_1'
[2023-01-03T23:02:52.250+0000] {processor.py:755} WARNING - No viable dags retrieved from /opt/airflow/dags/accidents_etl.py
[2023-01-03T23:02:52.275+0000] {processor.py:175} INFO - Processing /opt/airflow/dags/accidents_etl.py took 0.050 seconds
[2023-01-03T23:03:22.414+0000] {processor.py:153} INFO - Started process (PID=3996) to work on /opt/airflow/dags/accidents_etl.py
[2023-01-03T23:03:22.415+0000] {processor.py:743} INFO - Processing file /opt/airflow/dags/accidents_etl.py for tasks to queue
[2023-01-03T23:03:22.416+0000] {logging_mixin.py:137} INFO - [2023-01-03T23:03:22.416+0000] {dagbag.py:538} INFO - Filling up the DagBag from /opt/airflow/dags/accidents_etl.py
[2023-01-03T23:03:22.436+0000] {logging_mixin.py:137} INFO - [2023-01-03T23:03:22.432+0000] {dagbag.py:343} ERROR - Failed to import: /opt/airflow/dags/accidents_etl.py
Traceback (most recent call last):
  File "/home/airflow/.local/lib/python3.7/site-packages/airflow/models/dagbag.py", line 339, in parse
    loader.exec_module(new_module)
  File "<frozen importlib._bootstrap_external>", line 728, in exec_module
  File "<frozen importlib._bootstrap>", line 219, in _call_with_frames_removed
  File "/opt/airflow/dags/accidents_etl.py", line 5, in <module>
    from Milestone3_1 import clean_and_transform
ModuleNotFoundError: No module named 'Milestone3_1'
[2023-01-03T23:03:22.437+0000] {processor.py:755} WARNING - No viable dags retrieved from /opt/airflow/dags/accidents_etl.py
[2023-01-03T23:03:22.463+0000] {processor.py:175} INFO - Processing /opt/airflow/dags/accidents_etl.py took 0.053 seconds
[2023-01-03T23:03:52.616+0000] {processor.py:153} INFO - Started process (PID=4074) to work on /opt/airflow/dags/accidents_etl.py
[2023-01-03T23:03:52.617+0000] {processor.py:743} INFO - Processing file /opt/airflow/dags/accidents_etl.py for tasks to queue
[2023-01-03T23:03:52.618+0000] {logging_mixin.py:137} INFO - [2023-01-03T23:03:52.618+0000] {dagbag.py:538} INFO - Filling up the DagBag from /opt/airflow/dags/accidents_etl.py
[2023-01-03T23:03:52.638+0000] {logging_mixin.py:137} INFO - [2023-01-03T23:03:52.634+0000] {dagbag.py:343} ERROR - Failed to import: /opt/airflow/dags/accidents_etl.py
Traceback (most recent call last):
  File "/home/airflow/.local/lib/python3.7/site-packages/airflow/models/dagbag.py", line 339, in parse
    loader.exec_module(new_module)
  File "<frozen importlib._bootstrap_external>", line 728, in exec_module
  File "<frozen importlib._bootstrap>", line 219, in _call_with_frames_removed
  File "/opt/airflow/dags/accidents_etl.py", line 5, in <module>
    from Milestone3_1 import clean_and_transform
ModuleNotFoundError: No module named 'Milestone3_1'
[2023-01-03T23:03:52.639+0000] {processor.py:755} WARNING - No viable dags retrieved from /opt/airflow/dags/accidents_etl.py
[2023-01-03T23:03:52.662+0000] {processor.py:175} INFO - Processing /opt/airflow/dags/accidents_etl.py took 0.049 seconds
[2023-01-03T23:04:22.795+0000] {processor.py:153} INFO - Started process (PID=4128) to work on /opt/airflow/dags/accidents_etl.py
[2023-01-03T23:04:22.796+0000] {processor.py:743} INFO - Processing file /opt/airflow/dags/accidents_etl.py for tasks to queue
[2023-01-03T23:04:22.796+0000] {logging_mixin.py:137} INFO - [2023-01-03T23:04:22.796+0000] {dagbag.py:538} INFO - Filling up the DagBag from /opt/airflow/dags/accidents_etl.py
[2023-01-03T23:04:22.818+0000] {logging_mixin.py:137} INFO - [2023-01-03T23:04:22.815+0000] {dagbag.py:343} ERROR - Failed to import: /opt/airflow/dags/accidents_etl.py
Traceback (most recent call last):
  File "/home/airflow/.local/lib/python3.7/site-packages/airflow/models/dagbag.py", line 339, in parse
    loader.exec_module(new_module)
  File "<frozen importlib._bootstrap_external>", line 728, in exec_module
  File "<frozen importlib._bootstrap>", line 219, in _call_with_frames_removed
  File "/opt/airflow/dags/accidents_etl.py", line 5, in <module>
    from Milestone3_1 import clean_and_transform
ModuleNotFoundError: No module named 'Milestone3_1'
[2023-01-03T23:04:22.818+0000] {processor.py:755} WARNING - No viable dags retrieved from /opt/airflow/dags/accidents_etl.py
[2023-01-03T23:04:22.843+0000] {processor.py:175} INFO - Processing /opt/airflow/dags/accidents_etl.py took 0.051 seconds
[2023-01-03T23:04:53.006+0000] {processor.py:153} INFO - Started process (PID=4205) to work on /opt/airflow/dags/accidents_etl.py
[2023-01-03T23:04:53.007+0000] {processor.py:743} INFO - Processing file /opt/airflow/dags/accidents_etl.py for tasks to queue
[2023-01-03T23:04:53.008+0000] {logging_mixin.py:137} INFO - [2023-01-03T23:04:53.008+0000] {dagbag.py:538} INFO - Filling up the DagBag from /opt/airflow/dags/accidents_etl.py
[2023-01-03T23:04:53.029+0000] {logging_mixin.py:137} INFO - [2023-01-03T23:04:53.026+0000] {dagbag.py:343} ERROR - Failed to import: /opt/airflow/dags/accidents_etl.py
Traceback (most recent call last):
  File "/home/airflow/.local/lib/python3.7/site-packages/airflow/models/dagbag.py", line 339, in parse
    loader.exec_module(new_module)
  File "<frozen importlib._bootstrap_external>", line 728, in exec_module
  File "<frozen importlib._bootstrap>", line 219, in _call_with_frames_removed
  File "/opt/airflow/dags/accidents_etl.py", line 5, in <module>
    from Milestone3_1 import clean_and_transform
ModuleNotFoundError: No module named 'Milestone3_1'
[2023-01-03T23:04:53.030+0000] {processor.py:755} WARNING - No viable dags retrieved from /opt/airflow/dags/accidents_etl.py
[2023-01-03T23:04:53.058+0000] {processor.py:175} INFO - Processing /opt/airflow/dags/accidents_etl.py took 0.057 seconds
[2023-01-03T23:05:23.181+0000] {processor.py:153} INFO - Started process (PID=4259) to work on /opt/airflow/dags/accidents_etl.py
[2023-01-03T23:05:23.182+0000] {processor.py:743} INFO - Processing file /opt/airflow/dags/accidents_etl.py for tasks to queue
[2023-01-03T23:05:23.183+0000] {logging_mixin.py:137} INFO - [2023-01-03T23:05:23.182+0000] {dagbag.py:538} INFO - Filling up the DagBag from /opt/airflow/dags/accidents_etl.py
[2023-01-03T23:05:23.202+0000] {logging_mixin.py:137} INFO - [2023-01-03T23:05:23.197+0000] {dagbag.py:343} ERROR - Failed to import: /opt/airflow/dags/accidents_etl.py
Traceback (most recent call last):
  File "/home/airflow/.local/lib/python3.7/site-packages/airflow/models/dagbag.py", line 339, in parse
    loader.exec_module(new_module)
  File "<frozen importlib._bootstrap_external>", line 728, in exec_module
  File "<frozen importlib._bootstrap>", line 219, in _call_with_frames_removed
  File "/opt/airflow/dags/accidents_etl.py", line 5, in <module>
    from Milestone3_1 import clean_and_transform
ModuleNotFoundError: No module named 'Milestone3_1'
[2023-01-03T23:05:23.204+0000] {processor.py:755} WARNING - No viable dags retrieved from /opt/airflow/dags/accidents_etl.py
[2023-01-03T23:05:23.230+0000] {processor.py:175} INFO - Processing /opt/airflow/dags/accidents_etl.py took 0.052 seconds
[2023-01-03T23:05:53.388+0000] {processor.py:153} INFO - Started process (PID=4312) to work on /opt/airflow/dags/accidents_etl.py
[2023-01-03T23:05:53.389+0000] {processor.py:743} INFO - Processing file /opt/airflow/dags/accidents_etl.py for tasks to queue
[2023-01-03T23:05:53.390+0000] {logging_mixin.py:137} INFO - [2023-01-03T23:05:53.390+0000] {dagbag.py:538} INFO - Filling up the DagBag from /opt/airflow/dags/accidents_etl.py
[2023-01-03T23:05:53.412+0000] {logging_mixin.py:137} INFO - [2023-01-03T23:05:53.409+0000] {dagbag.py:343} ERROR - Failed to import: /opt/airflow/dags/accidents_etl.py
Traceback (most recent call last):
  File "/home/airflow/.local/lib/python3.7/site-packages/airflow/models/dagbag.py", line 339, in parse
    loader.exec_module(new_module)
  File "<frozen importlib._bootstrap_external>", line 728, in exec_module
  File "<frozen importlib._bootstrap>", line 219, in _call_with_frames_removed
  File "/opt/airflow/dags/accidents_etl.py", line 5, in <module>
    from Milestone3_1 import clean_and_transform
ModuleNotFoundError: No module named 'Milestone3_1'
[2023-01-03T23:05:53.413+0000] {processor.py:755} WARNING - No viable dags retrieved from /opt/airflow/dags/accidents_etl.py
[2023-01-03T23:05:53.483+0000] {processor.py:175} INFO - Processing /opt/airflow/dags/accidents_etl.py took 0.098 seconds
[2023-01-03T23:06:23.564+0000] {processor.py:153} INFO - Started process (PID=4389) to work on /opt/airflow/dags/accidents_etl.py
[2023-01-03T23:06:23.566+0000] {processor.py:743} INFO - Processing file /opt/airflow/dags/accidents_etl.py for tasks to queue
[2023-01-03T23:06:23.568+0000] {logging_mixin.py:137} INFO - [2023-01-03T23:06:23.567+0000] {dagbag.py:538} INFO - Filling up the DagBag from /opt/airflow/dags/accidents_etl.py
[2023-01-03T23:06:23.590+0000] {logging_mixin.py:137} INFO - [2023-01-03T23:06:23.587+0000] {dagbag.py:343} ERROR - Failed to import: /opt/airflow/dags/accidents_etl.py
Traceback (most recent call last):
  File "/home/airflow/.local/lib/python3.7/site-packages/airflow/models/dagbag.py", line 339, in parse
    loader.exec_module(new_module)
  File "<frozen importlib._bootstrap_external>", line 728, in exec_module
  File "<frozen importlib._bootstrap>", line 219, in _call_with_frames_removed
  File "/opt/airflow/dags/accidents_etl.py", line 5, in <module>
    from Milestone3_1 import clean_and_transform
ModuleNotFoundError: No module named 'Milestone3_1'
[2023-01-03T23:06:23.591+0000] {processor.py:755} WARNING - No viable dags retrieved from /opt/airflow/dags/accidents_etl.py
[2023-01-03T23:06:23.614+0000] {processor.py:175} INFO - Processing /opt/airflow/dags/accidents_etl.py took 0.053 seconds
[2023-01-03T23:06:53.752+0000] {processor.py:153} INFO - Started process (PID=4442) to work on /opt/airflow/dags/accidents_etl.py
[2023-01-03T23:06:53.753+0000] {processor.py:743} INFO - Processing file /opt/airflow/dags/accidents_etl.py for tasks to queue
[2023-01-03T23:06:53.754+0000] {logging_mixin.py:137} INFO - [2023-01-03T23:06:53.754+0000] {dagbag.py:538} INFO - Filling up the DagBag from /opt/airflow/dags/accidents_etl.py
[2023-01-03T23:06:53.776+0000] {logging_mixin.py:137} INFO - [2023-01-03T23:06:53.773+0000] {dagbag.py:343} ERROR - Failed to import: /opt/airflow/dags/accidents_etl.py
Traceback (most recent call last):
  File "/home/airflow/.local/lib/python3.7/site-packages/airflow/models/dagbag.py", line 339, in parse
    loader.exec_module(new_module)
  File "<frozen importlib._bootstrap_external>", line 728, in exec_module
  File "<frozen importlib._bootstrap>", line 219, in _call_with_frames_removed
  File "/opt/airflow/dags/accidents_etl.py", line 5, in <module>
    from Milestone3_1 import clean_and_transform
ModuleNotFoundError: No module named 'Milestone3_1'
[2023-01-03T23:06:53.777+0000] {processor.py:755} WARNING - No viable dags retrieved from /opt/airflow/dags/accidents_etl.py
[2023-01-03T23:06:53.799+0000] {processor.py:175} INFO - Processing /opt/airflow/dags/accidents_etl.py took 0.050 seconds
[2023-01-03T23:07:23.944+0000] {processor.py:153} INFO - Started process (PID=4519) to work on /opt/airflow/dags/accidents_etl.py
[2023-01-03T23:07:23.945+0000] {processor.py:743} INFO - Processing file /opt/airflow/dags/accidents_etl.py for tasks to queue
[2023-01-03T23:07:23.947+0000] {logging_mixin.py:137} INFO - [2023-01-03T23:07:23.946+0000] {dagbag.py:538} INFO - Filling up the DagBag from /opt/airflow/dags/accidents_etl.py
[2023-01-03T23:07:23.966+0000] {logging_mixin.py:137} INFO - [2023-01-03T23:07:23.962+0000] {dagbag.py:343} ERROR - Failed to import: /opt/airflow/dags/accidents_etl.py
Traceback (most recent call last):
  File "/home/airflow/.local/lib/python3.7/site-packages/airflow/models/dagbag.py", line 339, in parse
    loader.exec_module(new_module)
  File "<frozen importlib._bootstrap_external>", line 728, in exec_module
  File "<frozen importlib._bootstrap>", line 219, in _call_with_frames_removed
  File "/opt/airflow/dags/accidents_etl.py", line 5, in <module>
    from Milestone3_1 import clean_and_transform
ModuleNotFoundError: No module named 'Milestone3_1'
[2023-01-03T23:07:23.968+0000] {processor.py:755} WARNING - No viable dags retrieved from /opt/airflow/dags/accidents_etl.py
[2023-01-03T23:07:23.992+0000] {processor.py:175} INFO - Processing /opt/airflow/dags/accidents_etl.py took 0.052 seconds
[2023-01-03T23:07:54.134+0000] {processor.py:153} INFO - Started process (PID=4573) to work on /opt/airflow/dags/accidents_etl.py
[2023-01-03T23:07:54.135+0000] {processor.py:743} INFO - Processing file /opt/airflow/dags/accidents_etl.py for tasks to queue
[2023-01-03T23:07:54.136+0000] {logging_mixin.py:137} INFO - [2023-01-03T23:07:54.136+0000] {dagbag.py:538} INFO - Filling up the DagBag from /opt/airflow/dags/accidents_etl.py
[2023-01-03T23:07:54.153+0000] {logging_mixin.py:137} INFO - [2023-01-03T23:07:54.150+0000] {dagbag.py:343} ERROR - Failed to import: /opt/airflow/dags/accidents_etl.py
Traceback (most recent call last):
  File "/home/airflow/.local/lib/python3.7/site-packages/airflow/models/dagbag.py", line 339, in parse
    loader.exec_module(new_module)
  File "<frozen importlib._bootstrap_external>", line 728, in exec_module
  File "<frozen importlib._bootstrap>", line 219, in _call_with_frames_removed
  File "/opt/airflow/dags/accidents_etl.py", line 5, in <module>
    from Milestone3_1 import clean_and_transform
ModuleNotFoundError: No module named 'Milestone3_1'
[2023-01-03T23:07:54.154+0000] {processor.py:755} WARNING - No viable dags retrieved from /opt/airflow/dags/accidents_etl.py
[2023-01-03T23:07:54.181+0000] {processor.py:175} INFO - Processing /opt/airflow/dags/accidents_etl.py took 0.051 seconds
[2023-01-03T23:08:24.304+0000] {processor.py:153} INFO - Started process (PID=4635) to work on /opt/airflow/dags/accidents_etl.py
[2023-01-03T23:08:24.305+0000] {processor.py:743} INFO - Processing file /opt/airflow/dags/accidents_etl.py for tasks to queue
[2023-01-03T23:08:24.307+0000] {logging_mixin.py:137} INFO - [2023-01-03T23:08:24.306+0000] {dagbag.py:538} INFO - Filling up the DagBag from /opt/airflow/dags/accidents_etl.py
[2023-01-03T23:08:24.337+0000] {logging_mixin.py:137} INFO - [2023-01-03T23:08:24.333+0000] {dagbag.py:343} ERROR - Failed to import: /opt/airflow/dags/accidents_etl.py
Traceback (most recent call last):
  File "/home/airflow/.local/lib/python3.7/site-packages/airflow/models/dagbag.py", line 339, in parse
    loader.exec_module(new_module)
  File "<frozen importlib._bootstrap_external>", line 728, in exec_module
  File "<frozen importlib._bootstrap>", line 219, in _call_with_frames_removed
  File "/opt/airflow/dags/accidents_etl.py", line 5, in <module>
    from Milestone3_1 import clean_and_transform
ModuleNotFoundError: No module named 'Milestone3_1'
[2023-01-03T23:08:24.338+0000] {processor.py:755} WARNING - No viable dags retrieved from /opt/airflow/dags/accidents_etl.py
[2023-01-03T23:08:24.398+0000] {processor.py:175} INFO - Processing /opt/airflow/dags/accidents_etl.py took 0.098 seconds
[2023-01-03T23:08:54.494+0000] {processor.py:153} INFO - Started process (PID=4703) to work on /opt/airflow/dags/accidents_etl.py
[2023-01-03T23:08:54.495+0000] {processor.py:743} INFO - Processing file /opt/airflow/dags/accidents_etl.py for tasks to queue
[2023-01-03T23:08:54.496+0000] {logging_mixin.py:137} INFO - [2023-01-03T23:08:54.496+0000] {dagbag.py:538} INFO - Filling up the DagBag from /opt/airflow/dags/accidents_etl.py
[2023-01-03T23:08:55.832+0000] {logging_mixin.py:137} INFO - [2023-01-03T23:08:55.828+0000] {dagbag.py:343} ERROR - Failed to import: /opt/airflow/dags/accidents_etl.py
Traceback (most recent call last):
  File "/home/airflow/.local/lib/python3.7/site-packages/airflow/models/dagbag.py", line 339, in parse
    loader.exec_module(new_module)
  File "<frozen importlib._bootstrap_external>", line 728, in exec_module
  File "<frozen importlib._bootstrap>", line 219, in _call_with_frames_removed
  File "/opt/airflow/dags/accidents_etl.py", line 17, in <module>
    'start_date': datetime(2022, 1, 1),
NameError: name 'datetime' is not defined
[2023-01-03T23:08:55.833+0000] {processor.py:755} WARNING - No viable dags retrieved from /opt/airflow/dags/accidents_etl.py
[2023-01-03T23:08:55.852+0000] {processor.py:175} INFO - Processing /opt/airflow/dags/accidents_etl.py took 1.361 seconds
[2023-01-03T23:09:26.031+0000] {processor.py:153} INFO - Started process (PID=4764) to work on /opt/airflow/dags/accidents_etl.py
[2023-01-03T23:09:26.032+0000] {processor.py:743} INFO - Processing file /opt/airflow/dags/accidents_etl.py for tasks to queue
[2023-01-03T23:09:26.033+0000] {logging_mixin.py:137} INFO - [2023-01-03T23:09:26.033+0000] {dagbag.py:538} INFO - Filling up the DagBag from /opt/airflow/dags/accidents_etl.py
[2023-01-03T23:09:26.759+0000] {logging_mixin.py:137} INFO - [2023-01-03T23:09:26.755+0000] {dagbag.py:343} ERROR - Failed to import: /opt/airflow/dags/accidents_etl.py
Traceback (most recent call last):
  File "/home/airflow/.local/lib/python3.7/site-packages/airflow/models/dagbag.py", line 339, in parse
    loader.exec_module(new_module)
  File "<frozen importlib._bootstrap_external>", line 728, in exec_module
  File "<frozen importlib._bootstrap>", line 219, in _call_with_frames_removed
  File "/opt/airflow/dags/accidents_etl.py", line 17, in <module>
    'start_date': datetime(2022, 1, 1),
NameError: name 'datetime' is not defined
[2023-01-03T23:09:26.760+0000] {processor.py:755} WARNING - No viable dags retrieved from /opt/airflow/dags/accidents_etl.py
[2023-01-03T23:09:26.783+0000] {processor.py:175} INFO - Processing /opt/airflow/dags/accidents_etl.py took 0.755 seconds
[2023-01-03T23:09:56.897+0000] {processor.py:153} INFO - Started process (PID=4835) to work on /opt/airflow/dags/accidents_etl.py
[2023-01-03T23:09:56.898+0000] {processor.py:743} INFO - Processing file /opt/airflow/dags/accidents_etl.py for tasks to queue
[2023-01-03T23:09:56.899+0000] {logging_mixin.py:137} INFO - [2023-01-03T23:09:56.898+0000] {dagbag.py:538} INFO - Filling up the DagBag from /opt/airflow/dags/accidents_etl.py
[2023-01-03T23:09:57.661+0000] {logging_mixin.py:137} INFO - [2023-01-03T23:09:57.657+0000] {dagbag.py:343} ERROR - Failed to import: /opt/airflow/dags/accidents_etl.py
Traceback (most recent call last):
  File "/home/airflow/.local/lib/python3.7/site-packages/airflow/models/dagbag.py", line 339, in parse
    loader.exec_module(new_module)
  File "<frozen importlib._bootstrap_external>", line 728, in exec_module
  File "<frozen importlib._bootstrap>", line 219, in _call_with_frames_removed
  File "/opt/airflow/dags/accidents_etl.py", line 17, in <module>
    'start_date': datetime(2022, 1, 1),
NameError: name 'datetime' is not defined
[2023-01-03T23:09:57.662+0000] {processor.py:755} WARNING - No viable dags retrieved from /opt/airflow/dags/accidents_etl.py
[2023-01-03T23:09:57.684+0000] {processor.py:175} INFO - Processing /opt/airflow/dags/accidents_etl.py took 0.790 seconds
[2023-01-03T23:10:27.888+0000] {processor.py:153} INFO - Started process (PID=4891) to work on /opt/airflow/dags/accidents_etl.py
[2023-01-03T23:10:27.889+0000] {processor.py:743} INFO - Processing file /opt/airflow/dags/accidents_etl.py for tasks to queue
[2023-01-03T23:10:27.890+0000] {logging_mixin.py:137} INFO - [2023-01-03T23:10:27.890+0000] {dagbag.py:538} INFO - Filling up the DagBag from /opt/airflow/dags/accidents_etl.py
[2023-01-03T23:10:28.643+0000] {logging_mixin.py:137} INFO - [2023-01-03T23:10:28.637+0000] {dagbag.py:343} ERROR - Failed to import: /opt/airflow/dags/accidents_etl.py
Traceback (most recent call last):
  File "/home/airflow/.local/lib/python3.7/site-packages/airflow/models/dagbag.py", line 339, in parse
    loader.exec_module(new_module)
  File "<frozen importlib._bootstrap_external>", line 728, in exec_module
  File "<frozen importlib._bootstrap>", line 219, in _call_with_frames_removed
  File "/opt/airflow/dags/accidents_etl.py", line 17, in <module>
    'start_date': datetime(2022, 1, 1),
NameError: name 'datetime' is not defined
[2023-01-03T23:10:28.645+0000] {processor.py:755} WARNING - No viable dags retrieved from /opt/airflow/dags/accidents_etl.py
[2023-01-03T23:10:28.719+0000] {processor.py:175} INFO - Processing /opt/airflow/dags/accidents_etl.py took 0.835 seconds
[2023-01-03T23:10:58.906+0000] {processor.py:153} INFO - Started process (PID=4967) to work on /opt/airflow/dags/accidents_etl.py
[2023-01-03T23:10:58.907+0000] {processor.py:743} INFO - Processing file /opt/airflow/dags/accidents_etl.py for tasks to queue
[2023-01-03T23:10:58.909+0000] {logging_mixin.py:137} INFO - [2023-01-03T23:10:58.909+0000] {dagbag.py:538} INFO - Filling up the DagBag from /opt/airflow/dags/accidents_etl.py
[2023-01-03T23:10:59.733+0000] {logging_mixin.py:137} INFO - [2023-01-03T23:10:59.726+0000] {dagbag.py:343} ERROR - Failed to import: /opt/airflow/dags/accidents_etl.py
Traceback (most recent call last):
  File "/home/airflow/.local/lib/python3.7/site-packages/airflow/models/dagbag.py", line 339, in parse
    loader.exec_module(new_module)
  File "<frozen importlib._bootstrap_external>", line 728, in exec_module
  File "<frozen importlib._bootstrap>", line 219, in _call_with_frames_removed
  File "/opt/airflow/dags/accidents_etl.py", line 17, in <module>
    'start_date': datetime(2022, 1, 1),
NameError: name 'datetime' is not defined
[2023-01-03T23:10:59.735+0000] {processor.py:755} WARNING - No viable dags retrieved from /opt/airflow/dags/accidents_etl.py
[2023-01-03T23:10:59.755+0000] {processor.py:175} INFO - Processing /opt/airflow/dags/accidents_etl.py took 0.853 seconds
[2023-01-03T23:11:29.938+0000] {processor.py:153} INFO - Started process (PID=5021) to work on /opt/airflow/dags/accidents_etl.py
[2023-01-03T23:11:29.939+0000] {processor.py:743} INFO - Processing file /opt/airflow/dags/accidents_etl.py for tasks to queue
[2023-01-03T23:11:29.940+0000] {logging_mixin.py:137} INFO - [2023-01-03T23:11:29.940+0000] {dagbag.py:538} INFO - Filling up the DagBag from /opt/airflow/dags/accidents_etl.py
[2023-01-03T23:11:30.688+0000] {logging_mixin.py:137} INFO - [2023-01-03T23:11:30.683+0000] {dagbag.py:343} ERROR - Failed to import: /opt/airflow/dags/accidents_etl.py
Traceback (most recent call last):
  File "/home/airflow/.local/lib/python3.7/site-packages/airflow/models/dagbag.py", line 339, in parse
    loader.exec_module(new_module)
  File "<frozen importlib._bootstrap_external>", line 728, in exec_module
  File "<frozen importlib._bootstrap>", line 219, in _call_with_frames_removed
  File "/opt/airflow/dags/accidents_etl.py", line 17, in <module>
    'start_date': datetime(2022, 1, 1),
NameError: name 'datetime' is not defined
[2023-01-03T23:11:30.688+0000] {processor.py:755} WARNING - No viable dags retrieved from /opt/airflow/dags/accidents_etl.py
[2023-01-03T23:11:30.711+0000] {processor.py:175} INFO - Processing /opt/airflow/dags/accidents_etl.py took 0.777 seconds
[2023-01-03T23:12:00.926+0000] {processor.py:153} INFO - Started process (PID=5100) to work on /opt/airflow/dags/accidents_etl.py
[2023-01-03T23:12:00.927+0000] {processor.py:743} INFO - Processing file /opt/airflow/dags/accidents_etl.py for tasks to queue
[2023-01-03T23:12:00.928+0000] {logging_mixin.py:137} INFO - [2023-01-03T23:12:00.928+0000] {dagbag.py:538} INFO - Filling up the DagBag from /opt/airflow/dags/accidents_etl.py
[2023-01-03T23:12:01.735+0000] {logging_mixin.py:137} INFO - [2023-01-03T23:12:01.731+0000] {dagbag.py:343} ERROR - Failed to import: /opt/airflow/dags/accidents_etl.py
Traceback (most recent call last):
  File "/home/airflow/.local/lib/python3.7/site-packages/airflow/models/dagbag.py", line 339, in parse
    loader.exec_module(new_module)
  File "<frozen importlib._bootstrap_external>", line 728, in exec_module
  File "<frozen importlib._bootstrap>", line 219, in _call_with_frames_removed
  File "/opt/airflow/dags/accidents_etl.py", line 17, in <module>
    'start_date': datetime(2022, 1, 1),
NameError: name 'datetime' is not defined
[2023-01-03T23:12:01.736+0000] {processor.py:755} WARNING - No viable dags retrieved from /opt/airflow/dags/accidents_etl.py
[2023-01-03T23:12:01.753+0000] {processor.py:175} INFO - Processing /opt/airflow/dags/accidents_etl.py took 0.831 seconds
[2023-01-03T23:12:31.926+0000] {processor.py:153} INFO - Started process (PID=5154) to work on /opt/airflow/dags/accidents_etl.py
[2023-01-03T23:12:31.927+0000] {processor.py:743} INFO - Processing file /opt/airflow/dags/accidents_etl.py for tasks to queue
[2023-01-03T23:12:31.928+0000] {logging_mixin.py:137} INFO - [2023-01-03T23:12:31.928+0000] {dagbag.py:538} INFO - Filling up the DagBag from /opt/airflow/dags/accidents_etl.py
[2023-01-03T23:12:32.624+0000] {logging_mixin.py:137} INFO - [2023-01-03T23:12:32.621+0000] {dagbag.py:343} ERROR - Failed to import: /opt/airflow/dags/accidents_etl.py
Traceback (most recent call last):
  File "/home/airflow/.local/lib/python3.7/site-packages/airflow/models/dagbag.py", line 339, in parse
    loader.exec_module(new_module)
  File "<frozen importlib._bootstrap_external>", line 728, in exec_module
  File "<frozen importlib._bootstrap>", line 219, in _call_with_frames_removed
  File "/opt/airflow/dags/accidents_etl.py", line 17, in <module>
    'start_date': datetime(2022, 1, 1),
NameError: name 'datetime' is not defined
[2023-01-03T23:12:32.625+0000] {processor.py:755} WARNING - No viable dags retrieved from /opt/airflow/dags/accidents_etl.py
[2023-01-03T23:12:32.647+0000] {processor.py:175} INFO - Processing /opt/airflow/dags/accidents_etl.py took 0.724 seconds
[2023-01-03T23:13:02.836+0000] {processor.py:153} INFO - Started process (PID=5232) to work on /opt/airflow/dags/accidents_etl.py
[2023-01-03T23:13:02.838+0000] {processor.py:743} INFO - Processing file /opt/airflow/dags/accidents_etl.py for tasks to queue
[2023-01-03T23:13:02.839+0000] {logging_mixin.py:137} INFO - [2023-01-03T23:13:02.839+0000] {dagbag.py:538} INFO - Filling up the DagBag from /opt/airflow/dags/accidents_etl.py
[2023-01-03T23:13:03.608+0000] {logging_mixin.py:137} INFO - [2023-01-03T23:13:03.603+0000] {dagbag.py:343} ERROR - Failed to import: /opt/airflow/dags/accidents_etl.py
Traceback (most recent call last):
  File "/home/airflow/.local/lib/python3.7/site-packages/airflow/models/dagbag.py", line 339, in parse
    loader.exec_module(new_module)
  File "<frozen importlib._bootstrap_external>", line 728, in exec_module
  File "<frozen importlib._bootstrap>", line 219, in _call_with_frames_removed
  File "/opt/airflow/dags/accidents_etl.py", line 17, in <module>
    'start_date': datetime(2022, 1, 1),
NameError: name 'datetime' is not defined
[2023-01-03T23:13:03.609+0000] {processor.py:755} WARNING - No viable dags retrieved from /opt/airflow/dags/accidents_etl.py
[2023-01-03T23:13:03.627+0000] {processor.py:175} INFO - Processing /opt/airflow/dags/accidents_etl.py took 0.795 seconds
[2023-01-03T23:13:33.816+0000] {processor.py:153} INFO - Started process (PID=5286) to work on /opt/airflow/dags/accidents_etl.py
[2023-01-03T23:13:33.817+0000] {processor.py:743} INFO - Processing file /opt/airflow/dags/accidents_etl.py for tasks to queue
[2023-01-03T23:13:33.818+0000] {logging_mixin.py:137} INFO - [2023-01-03T23:13:33.818+0000] {dagbag.py:538} INFO - Filling up the DagBag from /opt/airflow/dags/accidents_etl.py
[2023-01-03T23:13:34.543+0000] {logging_mixin.py:137} INFO - [2023-01-03T23:13:34.540+0000] {dagbag.py:343} ERROR - Failed to import: /opt/airflow/dags/accidents_etl.py
Traceback (most recent call last):
  File "/home/airflow/.local/lib/python3.7/site-packages/airflow/models/dagbag.py", line 339, in parse
    loader.exec_module(new_module)
  File "<frozen importlib._bootstrap_external>", line 728, in exec_module
  File "<frozen importlib._bootstrap>", line 219, in _call_with_frames_removed
  File "/opt/airflow/dags/accidents_etl.py", line 17, in <module>
    'start_date': datetime(2022, 1, 1),
NameError: name 'datetime' is not defined
[2023-01-03T23:13:34.544+0000] {processor.py:755} WARNING - No viable dags retrieved from /opt/airflow/dags/accidents_etl.py
[2023-01-03T23:13:34.563+0000] {processor.py:175} INFO - Processing /opt/airflow/dags/accidents_etl.py took 0.749 seconds
[2023-01-03T23:14:04.767+0000] {processor.py:153} INFO - Started process (PID=5364) to work on /opt/airflow/dags/accidents_etl.py
[2023-01-03T23:14:04.769+0000] {processor.py:743} INFO - Processing file /opt/airflow/dags/accidents_etl.py for tasks to queue
[2023-01-03T23:14:04.771+0000] {logging_mixin.py:137} INFO - [2023-01-03T23:14:04.771+0000] {dagbag.py:538} INFO - Filling up the DagBag from /opt/airflow/dags/accidents_etl.py
[2023-01-03T23:14:05.723+0000] {logging_mixin.py:137} INFO - [2023-01-03T23:14:05.719+0000] {dagbag.py:343} ERROR - Failed to import: /opt/airflow/dags/accidents_etl.py
Traceback (most recent call last):
  File "/home/airflow/.local/lib/python3.7/site-packages/airflow/models/dagbag.py", line 339, in parse
    loader.exec_module(new_module)
  File "<frozen importlib._bootstrap_external>", line 728, in exec_module
  File "<frozen importlib._bootstrap>", line 219, in _call_with_frames_removed
  File "/opt/airflow/dags/accidents_etl.py", line 17, in <module>
    'start_date': datetime(2022, 1, 1),
NameError: name 'datetime' is not defined
[2023-01-03T23:14:05.724+0000] {processor.py:755} WARNING - No viable dags retrieved from /opt/airflow/dags/accidents_etl.py
[2023-01-03T23:14:05.749+0000] {processor.py:175} INFO - Processing /opt/airflow/dags/accidents_etl.py took 0.986 seconds
[2023-01-03T23:14:35.927+0000] {processor.py:153} INFO - Started process (PID=5418) to work on /opt/airflow/dags/accidents_etl.py
[2023-01-03T23:14:35.928+0000] {processor.py:743} INFO - Processing file /opt/airflow/dags/accidents_etl.py for tasks to queue
[2023-01-03T23:14:35.929+0000] {logging_mixin.py:137} INFO - [2023-01-03T23:14:35.929+0000] {dagbag.py:538} INFO - Filling up the DagBag from /opt/airflow/dags/accidents_etl.py
[2023-01-03T23:14:36.655+0000] {logging_mixin.py:137} INFO - [2023-01-03T23:14:36.652+0000] {dagbag.py:343} ERROR - Failed to import: /opt/airflow/dags/accidents_etl.py
Traceback (most recent call last):
  File "/home/airflow/.local/lib/python3.7/site-packages/airflow/models/dagbag.py", line 339, in parse
    loader.exec_module(new_module)
  File "<frozen importlib._bootstrap_external>", line 728, in exec_module
  File "<frozen importlib._bootstrap>", line 219, in _call_with_frames_removed
  File "/opt/airflow/dags/accidents_etl.py", line 17, in <module>
    'start_date': datetime(2022, 1, 1),
NameError: name 'datetime' is not defined
[2023-01-03T23:14:36.656+0000] {processor.py:755} WARNING - No viable dags retrieved from /opt/airflow/dags/accidents_etl.py
[2023-01-03T23:14:36.673+0000] {processor.py:175} INFO - Processing /opt/airflow/dags/accidents_etl.py took 0.750 seconds
[2023-01-03T23:15:06.874+0000] {processor.py:153} INFO - Started process (PID=5496) to work on /opt/airflow/dags/accidents_etl.py
[2023-01-03T23:15:06.875+0000] {processor.py:743} INFO - Processing file /opt/airflow/dags/accidents_etl.py for tasks to queue
[2023-01-03T23:15:06.876+0000] {logging_mixin.py:137} INFO - [2023-01-03T23:15:06.876+0000] {dagbag.py:538} INFO - Filling up the DagBag from /opt/airflow/dags/accidents_etl.py
[2023-01-03T23:15:07.549+0000] {logging_mixin.py:137} INFO - [2023-01-03T23:15:07.544+0000] {dagbag.py:343} ERROR - Failed to import: /opt/airflow/dags/accidents_etl.py
Traceback (most recent call last):
  File "/home/airflow/.local/lib/python3.7/site-packages/airflow/models/dagbag.py", line 339, in parse
    loader.exec_module(new_module)
  File "<frozen importlib._bootstrap_external>", line 728, in exec_module
  File "<frozen importlib._bootstrap>", line 219, in _call_with_frames_removed
  File "/opt/airflow/dags/accidents_etl.py", line 17, in <module>
    'start_date': datetime(2022, 1, 1),
NameError: name 'datetime' is not defined
[2023-01-03T23:15:07.549+0000] {processor.py:755} WARNING - No viable dags retrieved from /opt/airflow/dags/accidents_etl.py
[2023-01-03T23:15:07.569+0000] {processor.py:175} INFO - Processing /opt/airflow/dags/accidents_etl.py took 0.699 seconds
[2023-01-03T23:15:37.752+0000] {processor.py:153} INFO - Started process (PID=5550) to work on /opt/airflow/dags/accidents_etl.py
[2023-01-03T23:15:37.753+0000] {processor.py:743} INFO - Processing file /opt/airflow/dags/accidents_etl.py for tasks to queue
[2023-01-03T23:15:37.754+0000] {logging_mixin.py:137} INFO - [2023-01-03T23:15:37.754+0000] {dagbag.py:538} INFO - Filling up the DagBag from /opt/airflow/dags/accidents_etl.py
[2023-01-03T23:15:38.409+0000] {logging_mixin.py:137} INFO - [2023-01-03T23:15:38.405+0000] {dagbag.py:343} ERROR - Failed to import: /opt/airflow/dags/accidents_etl.py
Traceback (most recent call last):
  File "/home/airflow/.local/lib/python3.7/site-packages/airflow/models/dagbag.py", line 339, in parse
    loader.exec_module(new_module)
  File "<frozen importlib._bootstrap_external>", line 728, in exec_module
  File "<frozen importlib._bootstrap>", line 219, in _call_with_frames_removed
  File "/opt/airflow/dags/accidents_etl.py", line 17, in <module>
    'start_date': datetime(2022, 1, 1),
NameError: name 'datetime' is not defined
[2023-01-03T23:15:38.411+0000] {processor.py:755} WARNING - No viable dags retrieved from /opt/airflow/dags/accidents_etl.py
[2023-01-03T23:15:38.430+0000] {processor.py:175} INFO - Processing /opt/airflow/dags/accidents_etl.py took 0.681 seconds
[2023-01-03T23:16:08.660+0000] {processor.py:153} INFO - Started process (PID=5628) to work on /opt/airflow/dags/accidents_etl.py
[2023-01-03T23:16:08.661+0000] {processor.py:743} INFO - Processing file /opt/airflow/dags/accidents_etl.py for tasks to queue
[2023-01-03T23:16:08.662+0000] {logging_mixin.py:137} INFO - [2023-01-03T23:16:08.662+0000] {dagbag.py:538} INFO - Filling up the DagBag from /opt/airflow/dags/accidents_etl.py
[2023-01-03T23:16:09.452+0000] {logging_mixin.py:137} INFO - [2023-01-03T23:16:09.448+0000] {dagbag.py:343} ERROR - Failed to import: /opt/airflow/dags/accidents_etl.py
Traceback (most recent call last):
  File "/home/airflow/.local/lib/python3.7/site-packages/airflow/models/dagbag.py", line 339, in parse
    loader.exec_module(new_module)
  File "<frozen importlib._bootstrap_external>", line 728, in exec_module
  File "<frozen importlib._bootstrap>", line 219, in _call_with_frames_removed
  File "/opt/airflow/dags/accidents_etl.py", line 17, in <module>
    'start_date': datetime(2022, 1, 1),
NameError: name 'datetime' is not defined
[2023-01-03T23:16:09.453+0000] {processor.py:755} WARNING - No viable dags retrieved from /opt/airflow/dags/accidents_etl.py
[2023-01-03T23:16:09.476+0000] {processor.py:175} INFO - Processing /opt/airflow/dags/accidents_etl.py took 0.819 seconds
[2023-01-03T23:16:39.528+0000] {processor.py:153} INFO - Started process (PID=5682) to work on /opt/airflow/dags/accidents_etl.py
[2023-01-03T23:16:39.529+0000] {processor.py:743} INFO - Processing file /opt/airflow/dags/accidents_etl.py for tasks to queue
[2023-01-03T23:16:39.530+0000] {logging_mixin.py:137} INFO - [2023-01-03T23:16:39.530+0000] {dagbag.py:538} INFO - Filling up the DagBag from /opt/airflow/dags/accidents_etl.py
[2023-01-03T23:16:40.223+0000] {logging_mixin.py:137} INFO - [2023-01-03T23:16:40.219+0000] {dagbag.py:343} ERROR - Failed to import: /opt/airflow/dags/accidents_etl.py
Traceback (most recent call last):
  File "/home/airflow/.local/lib/python3.7/site-packages/airflow/models/dagbag.py", line 339, in parse
    loader.exec_module(new_module)
  File "<frozen importlib._bootstrap_external>", line 728, in exec_module
  File "<frozen importlib._bootstrap>", line 219, in _call_with_frames_removed
  File "/opt/airflow/dags/accidents_etl.py", line 17, in <module>
    'start_date': datetime(2022, 1, 1),
NameError: name 'datetime' is not defined
[2023-01-03T23:16:40.224+0000] {processor.py:755} WARNING - No viable dags retrieved from /opt/airflow/dags/accidents_etl.py
[2023-01-03T23:16:40.245+0000] {processor.py:175} INFO - Processing /opt/airflow/dags/accidents_etl.py took 0.720 seconds
[2023-01-03T23:17:10.467+0000] {processor.py:153} INFO - Started process (PID=5760) to work on /opt/airflow/dags/accidents_etl.py
[2023-01-03T23:17:10.469+0000] {processor.py:743} INFO - Processing file /opt/airflow/dags/accidents_etl.py for tasks to queue
[2023-01-03T23:17:10.470+0000] {logging_mixin.py:137} INFO - [2023-01-03T23:17:10.470+0000] {dagbag.py:538} INFO - Filling up the DagBag from /opt/airflow/dags/accidents_etl.py
[2023-01-03T23:17:11.176+0000] {logging_mixin.py:137} INFO - [2023-01-03T23:17:11.166+0000] {dagbag.py:343} ERROR - Failed to import: /opt/airflow/dags/accidents_etl.py
Traceback (most recent call last):
  File "/home/airflow/.local/lib/python3.7/site-packages/airflow/models/dagbag.py", line 339, in parse
    loader.exec_module(new_module)
  File "<frozen importlib._bootstrap_external>", line 728, in exec_module
  File "<frozen importlib._bootstrap>", line 219, in _call_with_frames_removed
  File "/opt/airflow/dags/accidents_etl.py", line 17, in <module>
    'start_date': datetime(2022, 1, 1),
NameError: name 'datetime' is not defined
[2023-01-03T23:17:11.178+0000] {processor.py:755} WARNING - No viable dags retrieved from /opt/airflow/dags/accidents_etl.py
[2023-01-03T23:17:11.197+0000] {processor.py:175} INFO - Processing /opt/airflow/dags/accidents_etl.py took 0.733 seconds
[2023-01-03T23:17:41.367+0000] {processor.py:153} INFO - Started process (PID=5814) to work on /opt/airflow/dags/accidents_etl.py
[2023-01-03T23:17:41.368+0000] {processor.py:743} INFO - Processing file /opt/airflow/dags/accidents_etl.py for tasks to queue
[2023-01-03T23:17:41.369+0000] {logging_mixin.py:137} INFO - [2023-01-03T23:17:41.369+0000] {dagbag.py:538} INFO - Filling up the DagBag from /opt/airflow/dags/accidents_etl.py
[2023-01-03T23:17:42.029+0000] {logging_mixin.py:137} INFO - [2023-01-03T23:17:42.026+0000] {dagbag.py:343} ERROR - Failed to import: /opt/airflow/dags/accidents_etl.py
Traceback (most recent call last):
  File "/home/airflow/.local/lib/python3.7/site-packages/airflow/models/dagbag.py", line 339, in parse
    loader.exec_module(new_module)
  File "<frozen importlib._bootstrap_external>", line 728, in exec_module
  File "<frozen importlib._bootstrap>", line 219, in _call_with_frames_removed
  File "/opt/airflow/dags/accidents_etl.py", line 17, in <module>
    'start_date': datetime(2022, 1, 1),
NameError: name 'datetime' is not defined
[2023-01-03T23:17:42.030+0000] {processor.py:755} WARNING - No viable dags retrieved from /opt/airflow/dags/accidents_etl.py
[2023-01-03T23:17:42.049+0000] {processor.py:175} INFO - Processing /opt/airflow/dags/accidents_etl.py took 0.686 seconds
[2023-01-03T23:18:12.100+0000] {processor.py:153} INFO - Started process (PID=5892) to work on /opt/airflow/dags/accidents_etl.py
[2023-01-03T23:18:12.101+0000] {processor.py:743} INFO - Processing file /opt/airflow/dags/accidents_etl.py for tasks to queue
[2023-01-03T23:18:12.102+0000] {logging_mixin.py:137} INFO - [2023-01-03T23:18:12.102+0000] {dagbag.py:538} INFO - Filling up the DagBag from /opt/airflow/dags/accidents_etl.py
[2023-01-03T23:18:12.815+0000] {logging_mixin.py:137} INFO - [2023-01-03T23:18:12.812+0000] {dagbag.py:343} ERROR - Failed to import: /opt/airflow/dags/accidents_etl.py
Traceback (most recent call last):
  File "/home/airflow/.local/lib/python3.7/site-packages/airflow/models/dagbag.py", line 339, in parse
    loader.exec_module(new_module)
  File "<frozen importlib._bootstrap_external>", line 728, in exec_module
  File "<frozen importlib._bootstrap>", line 219, in _call_with_frames_removed
  File "/opt/airflow/dags/accidents_etl.py", line 17, in <module>
    'start_date': datetime(2022, 1, 1),
NameError: name 'datetime' is not defined
[2023-01-03T23:18:12.816+0000] {processor.py:755} WARNING - No viable dags retrieved from /opt/airflow/dags/accidents_etl.py
[2023-01-03T23:18:12.837+0000] {processor.py:175} INFO - Processing /opt/airflow/dags/accidents_etl.py took 0.741 seconds
[2023-01-03T23:18:43.021+0000] {processor.py:153} INFO - Started process (PID=5946) to work on /opt/airflow/dags/accidents_etl.py
[2023-01-03T23:18:43.021+0000] {processor.py:743} INFO - Processing file /opt/airflow/dags/accidents_etl.py for tasks to queue
[2023-01-03T23:18:43.022+0000] {logging_mixin.py:137} INFO - [2023-01-03T23:18:43.022+0000] {dagbag.py:538} INFO - Filling up the DagBag from /opt/airflow/dags/accidents_etl.py
[2023-01-03T23:18:43.719+0000] {logging_mixin.py:137} INFO - [2023-01-03T23:18:43.714+0000] {dagbag.py:343} ERROR - Failed to import: /opt/airflow/dags/accidents_etl.py
Traceback (most recent call last):
  File "/home/airflow/.local/lib/python3.7/site-packages/airflow/models/dagbag.py", line 339, in parse
    loader.exec_module(new_module)
  File "<frozen importlib._bootstrap_external>", line 728, in exec_module
  File "<frozen importlib._bootstrap>", line 219, in _call_with_frames_removed
  File "/opt/airflow/dags/accidents_etl.py", line 17, in <module>
    'start_date': datetime(2022, 1, 1),
NameError: name 'datetime' is not defined
[2023-01-03T23:18:43.720+0000] {processor.py:755} WARNING - No viable dags retrieved from /opt/airflow/dags/accidents_etl.py
[2023-01-03T23:18:43.747+0000] {processor.py:175} INFO - Processing /opt/airflow/dags/accidents_etl.py took 0.730 seconds
[2023-01-03T23:19:13.933+0000] {processor.py:153} INFO - Started process (PID=6025) to work on /opt/airflow/dags/accidents_etl.py
[2023-01-03T23:19:13.935+0000] {processor.py:743} INFO - Processing file /opt/airflow/dags/accidents_etl.py for tasks to queue
[2023-01-03T23:19:13.937+0000] {logging_mixin.py:137} INFO - [2023-01-03T23:19:13.937+0000] {dagbag.py:538} INFO - Filling up the DagBag from /opt/airflow/dags/accidents_etl.py
[2023-01-03T23:19:14.607+0000] {logging_mixin.py:137} INFO - [2023-01-03T23:19:14.601+0000] {dagbag.py:343} ERROR - Failed to import: /opt/airflow/dags/accidents_etl.py
Traceback (most recent call last):
  File "/home/airflow/.local/lib/python3.7/site-packages/airflow/models/dagbag.py", line 339, in parse
    loader.exec_module(new_module)
  File "<frozen importlib._bootstrap_external>", line 728, in exec_module
  File "<frozen importlib._bootstrap>", line 219, in _call_with_frames_removed
  File "/opt/airflow/dags/accidents_etl.py", line 17, in <module>
    'start_date': datetime(2022, 1, 1),
NameError: name 'datetime' is not defined
[2023-01-03T23:19:14.608+0000] {processor.py:755} WARNING - No viable dags retrieved from /opt/airflow/dags/accidents_etl.py
[2023-01-03T23:19:14.627+0000] {processor.py:175} INFO - Processing /opt/airflow/dags/accidents_etl.py took 0.698 seconds
[2023-01-03T23:19:44.670+0000] {processor.py:153} INFO - Started process (PID=6079) to work on /opt/airflow/dags/accidents_etl.py
[2023-01-03T23:19:44.671+0000] {processor.py:743} INFO - Processing file /opt/airflow/dags/accidents_etl.py for tasks to queue
[2023-01-03T23:19:44.672+0000] {logging_mixin.py:137} INFO - [2023-01-03T23:19:44.672+0000] {dagbag.py:538} INFO - Filling up the DagBag from /opt/airflow/dags/accidents_etl.py
[2023-01-03T23:19:45.332+0000] {logging_mixin.py:137} INFO - [2023-01-03T23:19:45.327+0000] {dagbag.py:343} ERROR - Failed to import: /opt/airflow/dags/accidents_etl.py
Traceback (most recent call last):
  File "/home/airflow/.local/lib/python3.7/site-packages/airflow/models/dagbag.py", line 339, in parse
    loader.exec_module(new_module)
  File "<frozen importlib._bootstrap_external>", line 728, in exec_module
  File "<frozen importlib._bootstrap>", line 219, in _call_with_frames_removed
  File "/opt/airflow/dags/accidents_etl.py", line 17, in <module>
    'start_date': datetime(2022, 1, 1),
NameError: name 'datetime' is not defined
[2023-01-03T23:19:45.333+0000] {processor.py:755} WARNING - No viable dags retrieved from /opt/airflow/dags/accidents_etl.py
[2023-01-03T23:19:45.362+0000] {processor.py:175} INFO - Processing /opt/airflow/dags/accidents_etl.py took 0.696 seconds
[2023-01-03T23:20:15.563+0000] {processor.py:153} INFO - Started process (PID=6157) to work on /opt/airflow/dags/accidents_etl.py
[2023-01-03T23:20:15.564+0000] {processor.py:743} INFO - Processing file /opt/airflow/dags/accidents_etl.py for tasks to queue
[2023-01-03T23:20:15.565+0000] {logging_mixin.py:137} INFO - [2023-01-03T23:20:15.565+0000] {dagbag.py:538} INFO - Filling up the DagBag from /opt/airflow/dags/accidents_etl.py
[2023-01-03T23:20:16.250+0000] {logging_mixin.py:137} INFO - [2023-01-03T23:20:16.246+0000] {dagbag.py:343} ERROR - Failed to import: /opt/airflow/dags/accidents_etl.py
Traceback (most recent call last):
  File "/home/airflow/.local/lib/python3.7/site-packages/airflow/models/dagbag.py", line 339, in parse
    loader.exec_module(new_module)
  File "<frozen importlib._bootstrap_external>", line 728, in exec_module
  File "<frozen importlib._bootstrap>", line 219, in _call_with_frames_removed
  File "/opt/airflow/dags/accidents_etl.py", line 17, in <module>
    'start_date': datetime(2022, 1, 1),
NameError: name 'datetime' is not defined
[2023-01-03T23:20:16.251+0000] {processor.py:755} WARNING - No viable dags retrieved from /opt/airflow/dags/accidents_etl.py
[2023-01-03T23:20:16.265+0000] {processor.py:175} INFO - Processing /opt/airflow/dags/accidents_etl.py took 0.705 seconds
[2023-01-03T23:20:46.436+0000] {processor.py:153} INFO - Started process (PID=6211) to work on /opt/airflow/dags/accidents_etl.py
[2023-01-03T23:20:46.438+0000] {processor.py:743} INFO - Processing file /opt/airflow/dags/accidents_etl.py for tasks to queue
[2023-01-03T23:20:46.439+0000] {logging_mixin.py:137} INFO - [2023-01-03T23:20:46.439+0000] {dagbag.py:538} INFO - Filling up the DagBag from /opt/airflow/dags/accidents_etl.py
[2023-01-03T23:20:47.082+0000] {logging_mixin.py:137} INFO - [2023-01-03T23:20:47.079+0000] {dagbag.py:343} ERROR - Failed to import: /opt/airflow/dags/accidents_etl.py
Traceback (most recent call last):
  File "/home/airflow/.local/lib/python3.7/site-packages/airflow/models/dagbag.py", line 339, in parse
    loader.exec_module(new_module)
  File "<frozen importlib._bootstrap_external>", line 728, in exec_module
  File "<frozen importlib._bootstrap>", line 219, in _call_with_frames_removed
  File "/opt/airflow/dags/accidents_etl.py", line 17, in <module>
    'start_date': datetime(2022, 1, 1),
NameError: name 'datetime' is not defined
[2023-01-03T23:20:47.083+0000] {processor.py:755} WARNING - No viable dags retrieved from /opt/airflow/dags/accidents_etl.py
[2023-01-03T23:20:47.102+0000] {processor.py:175} INFO - Processing /opt/airflow/dags/accidents_etl.py took 0.670 seconds
[2023-01-03T23:21:17.274+0000] {processor.py:153} INFO - Started process (PID=6290) to work on /opt/airflow/dags/accidents_etl.py
[2023-01-03T23:21:17.275+0000] {processor.py:743} INFO - Processing file /opt/airflow/dags/accidents_etl.py for tasks to queue
[2023-01-03T23:21:17.277+0000] {logging_mixin.py:137} INFO - [2023-01-03T23:21:17.276+0000] {dagbag.py:538} INFO - Filling up the DagBag from /opt/airflow/dags/accidents_etl.py
[2023-01-03T23:21:17.986+0000] {logging_mixin.py:137} INFO - [2023-01-03T23:21:17.982+0000] {dagbag.py:343} ERROR - Failed to import: /opt/airflow/dags/accidents_etl.py
Traceback (most recent call last):
  File "/home/airflow/.local/lib/python3.7/site-packages/airflow/models/dagbag.py", line 339, in parse
    loader.exec_module(new_module)
  File "<frozen importlib._bootstrap_external>", line 728, in exec_module
  File "<frozen importlib._bootstrap>", line 219, in _call_with_frames_removed
  File "/opt/airflow/dags/accidents_etl.py", line 17, in <module>
    'start_date': datetime(2022, 1, 1),
NameError: name 'datetime' is not defined
[2023-01-03T23:21:17.987+0000] {processor.py:755} WARNING - No viable dags retrieved from /opt/airflow/dags/accidents_etl.py
[2023-01-03T23:21:18.013+0000] {processor.py:175} INFO - Processing /opt/airflow/dags/accidents_etl.py took 0.742 seconds
[2023-01-03T23:21:48.205+0000] {processor.py:153} INFO - Started process (PID=6344) to work on /opt/airflow/dags/accidents_etl.py
[2023-01-03T23:21:48.206+0000] {processor.py:743} INFO - Processing file /opt/airflow/dags/accidents_etl.py for tasks to queue
[2023-01-03T23:21:48.207+0000] {logging_mixin.py:137} INFO - [2023-01-03T23:21:48.207+0000] {dagbag.py:538} INFO - Filling up the DagBag from /opt/airflow/dags/accidents_etl.py
[2023-01-03T23:21:48.877+0000] {logging_mixin.py:137} INFO - [2023-01-03T23:21:48.873+0000] {dagbag.py:343} ERROR - Failed to import: /opt/airflow/dags/accidents_etl.py
Traceback (most recent call last):
  File "/home/airflow/.local/lib/python3.7/site-packages/airflow/models/dagbag.py", line 339, in parse
    loader.exec_module(new_module)
  File "<frozen importlib._bootstrap_external>", line 728, in exec_module
  File "<frozen importlib._bootstrap>", line 219, in _call_with_frames_removed
  File "/opt/airflow/dags/accidents_etl.py", line 17, in <module>
    'start_date': datetime(2022, 1, 1),
NameError: name 'datetime' is not defined
[2023-01-03T23:21:48.877+0000] {processor.py:755} WARNING - No viable dags retrieved from /opt/airflow/dags/accidents_etl.py
[2023-01-03T23:21:48.900+0000] {processor.py:175} INFO - Processing /opt/airflow/dags/accidents_etl.py took 0.700 seconds
[2023-01-03T23:22:19.073+0000] {processor.py:153} INFO - Started process (PID=6423) to work on /opt/airflow/dags/accidents_etl.py
[2023-01-03T23:22:19.074+0000] {processor.py:743} INFO - Processing file /opt/airflow/dags/accidents_etl.py for tasks to queue
[2023-01-03T23:22:19.075+0000] {logging_mixin.py:137} INFO - [2023-01-03T23:22:19.075+0000] {dagbag.py:538} INFO - Filling up the DagBag from /opt/airflow/dags/accidents_etl.py
[2023-01-03T23:22:19.739+0000] {logging_mixin.py:137} INFO - [2023-01-03T23:22:19.735+0000] {dagbag.py:343} ERROR - Failed to import: /opt/airflow/dags/accidents_etl.py
Traceback (most recent call last):
  File "/home/airflow/.local/lib/python3.7/site-packages/airflow/models/dagbag.py", line 339, in parse
    loader.exec_module(new_module)
  File "<frozen importlib._bootstrap_external>", line 728, in exec_module
  File "<frozen importlib._bootstrap>", line 219, in _call_with_frames_removed
  File "/opt/airflow/dags/accidents_etl.py", line 17, in <module>
    'start_date': datetime(2022, 1, 1),
NameError: name 'datetime' is not defined
[2023-01-03T23:22:19.740+0000] {processor.py:755} WARNING - No viable dags retrieved from /opt/airflow/dags/accidents_etl.py
[2023-01-03T23:22:19.761+0000] {processor.py:175} INFO - Processing /opt/airflow/dags/accidents_etl.py took 0.691 seconds
[2023-01-03T23:22:49.921+0000] {processor.py:153} INFO - Started process (PID=6477) to work on /opt/airflow/dags/accidents_etl.py
[2023-01-03T23:22:49.922+0000] {processor.py:743} INFO - Processing file /opt/airflow/dags/accidents_etl.py for tasks to queue
[2023-01-03T23:22:49.922+0000] {logging_mixin.py:137} INFO - [2023-01-03T23:22:49.922+0000] {dagbag.py:538} INFO - Filling up the DagBag from /opt/airflow/dags/accidents_etl.py
[2023-01-03T23:22:50.568+0000] {logging_mixin.py:137} INFO - [2023-01-03T23:22:50.563+0000] {dagbag.py:343} ERROR - Failed to import: /opt/airflow/dags/accidents_etl.py
Traceback (most recent call last):
  File "/home/airflow/.local/lib/python3.7/site-packages/airflow/models/dagbag.py", line 339, in parse
    loader.exec_module(new_module)
  File "<frozen importlib._bootstrap_external>", line 728, in exec_module
  File "<frozen importlib._bootstrap>", line 219, in _call_with_frames_removed
  File "/opt/airflow/dags/accidents_etl.py", line 17, in <module>
    'start_date': datetime(2022, 1, 1),
NameError: name 'datetime' is not defined
[2023-01-03T23:22:50.570+0000] {processor.py:755} WARNING - No viable dags retrieved from /opt/airflow/dags/accidents_etl.py
[2023-01-03T23:22:50.590+0000] {processor.py:175} INFO - Processing /opt/airflow/dags/accidents_etl.py took 0.672 seconds
[2023-01-03T23:23:20.773+0000] {processor.py:153} INFO - Started process (PID=6555) to work on /opt/airflow/dags/accidents_etl.py
[2023-01-03T23:23:20.774+0000] {processor.py:743} INFO - Processing file /opt/airflow/dags/accidents_etl.py for tasks to queue
[2023-01-03T23:23:20.775+0000] {logging_mixin.py:137} INFO - [2023-01-03T23:23:20.774+0000] {dagbag.py:538} INFO - Filling up the DagBag from /opt/airflow/dags/accidents_etl.py
[2023-01-03T23:23:21.465+0000] {logging_mixin.py:137} INFO - [2023-01-03T23:23:21.462+0000] {dagbag.py:343} ERROR - Failed to import: /opt/airflow/dags/accidents_etl.py
Traceback (most recent call last):
  File "/home/airflow/.local/lib/python3.7/site-packages/airflow/models/dagbag.py", line 339, in parse
    loader.exec_module(new_module)
  File "<frozen importlib._bootstrap_external>", line 728, in exec_module
  File "<frozen importlib._bootstrap>", line 219, in _call_with_frames_removed
  File "/opt/airflow/dags/accidents_etl.py", line 17, in <module>
    'start_date': datetime(2022, 1, 1),
NameError: name 'datetime' is not defined
[2023-01-03T23:23:21.466+0000] {processor.py:755} WARNING - No viable dags retrieved from /opt/airflow/dags/accidents_etl.py
[2023-01-03T23:23:21.486+0000] {processor.py:175} INFO - Processing /opt/airflow/dags/accidents_etl.py took 0.717 seconds
[2023-01-03T23:23:51.679+0000] {processor.py:153} INFO - Started process (PID=6609) to work on /opt/airflow/dags/accidents_etl.py
[2023-01-03T23:23:51.680+0000] {processor.py:743} INFO - Processing file /opt/airflow/dags/accidents_etl.py for tasks to queue
[2023-01-03T23:23:51.681+0000] {logging_mixin.py:137} INFO - [2023-01-03T23:23:51.681+0000] {dagbag.py:538} INFO - Filling up the DagBag from /opt/airflow/dags/accidents_etl.py
[2023-01-03T23:23:52.399+0000] {logging_mixin.py:137} INFO - [2023-01-03T23:23:52.394+0000] {dagbag.py:343} ERROR - Failed to import: /opt/airflow/dags/accidents_etl.py
Traceback (most recent call last):
  File "/home/airflow/.local/lib/python3.7/site-packages/airflow/models/dagbag.py", line 339, in parse
    loader.exec_module(new_module)
  File "<frozen importlib._bootstrap_external>", line 728, in exec_module
  File "<frozen importlib._bootstrap>", line 219, in _call_with_frames_removed
  File "/opt/airflow/dags/accidents_etl.py", line 17, in <module>
    'start_date': datetime(2022, 1, 1),
NameError: name 'datetime' is not defined
[2023-01-03T23:23:52.401+0000] {processor.py:755} WARNING - No viable dags retrieved from /opt/airflow/dags/accidents_etl.py
[2023-01-03T23:23:52.424+0000] {processor.py:175} INFO - Processing /opt/airflow/dags/accidents_etl.py took 0.749 seconds
[2023-01-03T23:24:22.601+0000] {processor.py:153} INFO - Started process (PID=6687) to work on /opt/airflow/dags/accidents_etl.py
[2023-01-03T23:24:22.603+0000] {processor.py:743} INFO - Processing file /opt/airflow/dags/accidents_etl.py for tasks to queue
[2023-01-03T23:24:22.604+0000] {logging_mixin.py:137} INFO - [2023-01-03T23:24:22.604+0000] {dagbag.py:538} INFO - Filling up the DagBag from /opt/airflow/dags/accidents_etl.py
[2023-01-03T23:24:23.317+0000] {logging_mixin.py:137} INFO - [2023-01-03T23:24:23.314+0000] {dagbag.py:343} ERROR - Failed to import: /opt/airflow/dags/accidents_etl.py
Traceback (most recent call last):
  File "/home/airflow/.local/lib/python3.7/site-packages/airflow/models/dagbag.py", line 339, in parse
    loader.exec_module(new_module)
  File "<frozen importlib._bootstrap_external>", line 728, in exec_module
  File "<frozen importlib._bootstrap>", line 219, in _call_with_frames_removed
  File "/opt/airflow/dags/accidents_etl.py", line 17, in <module>
    'start_date': datetime(2022, 1, 1),
NameError: name 'datetime' is not defined
[2023-01-03T23:24:23.318+0000] {processor.py:755} WARNING - No viable dags retrieved from /opt/airflow/dags/accidents_etl.py
[2023-01-03T23:24:23.337+0000] {processor.py:175} INFO - Processing /opt/airflow/dags/accidents_etl.py took 0.740 seconds
[2023-01-03T23:24:53.525+0000] {processor.py:153} INFO - Started process (PID=6741) to work on /opt/airflow/dags/accidents_etl.py
[2023-01-03T23:24:53.526+0000] {processor.py:743} INFO - Processing file /opt/airflow/dags/accidents_etl.py for tasks to queue
[2023-01-03T23:24:53.528+0000] {logging_mixin.py:137} INFO - [2023-01-03T23:24:53.527+0000] {dagbag.py:538} INFO - Filling up the DagBag from /opt/airflow/dags/accidents_etl.py
[2023-01-03T23:24:54.250+0000] {logging_mixin.py:137} INFO - [2023-01-03T23:24:54.247+0000] {dagbag.py:343} ERROR - Failed to import: /opt/airflow/dags/accidents_etl.py
Traceback (most recent call last):
  File "/home/airflow/.local/lib/python3.7/site-packages/airflow/models/dagbag.py", line 339, in parse
    loader.exec_module(new_module)
  File "<frozen importlib._bootstrap_external>", line 728, in exec_module
  File "<frozen importlib._bootstrap>", line 219, in _call_with_frames_removed
  File "/opt/airflow/dags/accidents_etl.py", line 17, in <module>
    'start_date': datetime(2022, 1, 1),
NameError: name 'datetime' is not defined
[2023-01-03T23:24:54.251+0000] {processor.py:755} WARNING - No viable dags retrieved from /opt/airflow/dags/accidents_etl.py
[2023-01-03T23:24:54.271+0000] {processor.py:175} INFO - Processing /opt/airflow/dags/accidents_etl.py took 0.749 seconds
[2023-01-03T23:25:24.450+0000] {processor.py:153} INFO - Started process (PID=6820) to work on /opt/airflow/dags/accidents_etl.py
[2023-01-03T23:25:24.451+0000] {processor.py:743} INFO - Processing file /opt/airflow/dags/accidents_etl.py for tasks to queue
[2023-01-03T23:25:24.452+0000] {logging_mixin.py:137} INFO - [2023-01-03T23:25:24.452+0000] {dagbag.py:538} INFO - Filling up the DagBag from /opt/airflow/dags/accidents_etl.py
[2023-01-03T23:25:25.218+0000] {logging_mixin.py:137} INFO - [2023-01-03T23:25:25.215+0000] {dagbag.py:343} ERROR - Failed to import: /opt/airflow/dags/accidents_etl.py
Traceback (most recent call last):
  File "/home/airflow/.local/lib/python3.7/site-packages/airflow/models/dagbag.py", line 339, in parse
    loader.exec_module(new_module)
  File "<frozen importlib._bootstrap_external>", line 728, in exec_module
  File "<frozen importlib._bootstrap>", line 219, in _call_with_frames_removed
  File "/opt/airflow/dags/accidents_etl.py", line 17, in <module>
    'start_date': datetime(2022, 1, 1),
NameError: name 'datetime' is not defined
[2023-01-03T23:25:25.220+0000] {processor.py:755} WARNING - No viable dags retrieved from /opt/airflow/dags/accidents_etl.py
[2023-01-03T23:25:25.236+0000] {processor.py:175} INFO - Processing /opt/airflow/dags/accidents_etl.py took 0.789 seconds
[2023-01-03T23:25:55.410+0000] {processor.py:153} INFO - Started process (PID=6874) to work on /opt/airflow/dags/accidents_etl.py
[2023-01-03T23:25:55.411+0000] {processor.py:743} INFO - Processing file /opt/airflow/dags/accidents_etl.py for tasks to queue
[2023-01-03T23:25:55.412+0000] {logging_mixin.py:137} INFO - [2023-01-03T23:25:55.412+0000] {dagbag.py:538} INFO - Filling up the DagBag from /opt/airflow/dags/accidents_etl.py
[2023-01-03T23:25:56.105+0000] {logging_mixin.py:137} INFO - [2023-01-03T23:25:56.098+0000] {dagbag.py:343} ERROR - Failed to import: /opt/airflow/dags/accidents_etl.py
Traceback (most recent call last):
  File "/home/airflow/.local/lib/python3.7/site-packages/airflow/models/dagbag.py", line 339, in parse
    loader.exec_module(new_module)
  File "<frozen importlib._bootstrap_external>", line 728, in exec_module
  File "<frozen importlib._bootstrap>", line 219, in _call_with_frames_removed
  File "/opt/airflow/dags/accidents_etl.py", line 17, in <module>
    'start_date': datetime(2022, 1, 1),
NameError: name 'datetime' is not defined
[2023-01-03T23:25:56.107+0000] {processor.py:755} WARNING - No viable dags retrieved from /opt/airflow/dags/accidents_etl.py
[2023-01-03T23:25:56.124+0000] {processor.py:175} INFO - Processing /opt/airflow/dags/accidents_etl.py took 0.718 seconds
[2023-01-03T23:26:26.209+0000] {processor.py:153} INFO - Started process (PID=6937) to work on /opt/airflow/dags/accidents_etl.py
[2023-01-03T23:26:26.210+0000] {processor.py:743} INFO - Processing file /opt/airflow/dags/accidents_etl.py for tasks to queue
[2023-01-03T23:26:26.211+0000] {logging_mixin.py:137} INFO - [2023-01-03T23:26:26.211+0000] {dagbag.py:538} INFO - Filling up the DagBag from /opt/airflow/dags/accidents_etl.py
[2023-01-03T23:26:26.983+0000] {logging_mixin.py:137} INFO - [2023-01-03T23:26:26.980+0000] {dagbag.py:343} ERROR - Failed to import: /opt/airflow/dags/accidents_etl.py
Traceback (most recent call last):
  File "/home/airflow/.local/lib/python3.7/site-packages/airflow/models/dagbag.py", line 339, in parse
    loader.exec_module(new_module)
  File "<frozen importlib._bootstrap_external>", line 728, in exec_module
  File "<frozen importlib._bootstrap>", line 219, in _call_with_frames_removed
  File "/opt/airflow/dags/accidents_etl.py", line 17, in <module>
    'start_date': datetime(2022, 1, 1),
NameError: name 'datetime' is not defined
[2023-01-03T23:26:26.984+0000] {processor.py:755} WARNING - No viable dags retrieved from /opt/airflow/dags/accidents_etl.py
[2023-01-03T23:26:27.005+0000] {processor.py:175} INFO - Processing /opt/airflow/dags/accidents_etl.py took 0.799 seconds
[2023-01-03T23:26:57.230+0000] {processor.py:153} INFO - Started process (PID=7006) to work on /opt/airflow/dags/accidents_etl.py
[2023-01-03T23:26:57.232+0000] {processor.py:743} INFO - Processing file /opt/airflow/dags/accidents_etl.py for tasks to queue
[2023-01-03T23:26:57.232+0000] {logging_mixin.py:137} INFO - [2023-01-03T23:26:57.232+0000] {dagbag.py:538} INFO - Filling up the DagBag from /opt/airflow/dags/accidents_etl.py
[2023-01-03T23:26:57.914+0000] {logging_mixin.py:137} INFO - [2023-01-03T23:26:57.910+0000] {dagbag.py:343} ERROR - Failed to import: /opt/airflow/dags/accidents_etl.py
Traceback (most recent call last):
  File "/home/airflow/.local/lib/python3.7/site-packages/airflow/models/dagbag.py", line 339, in parse
    loader.exec_module(new_module)
  File "<frozen importlib._bootstrap_external>", line 728, in exec_module
  File "<frozen importlib._bootstrap>", line 219, in _call_with_frames_removed
  File "/opt/airflow/dags/accidents_etl.py", line 17, in <module>
    'start_date': datetime(2022, 1, 1),
NameError: name 'datetime' is not defined
[2023-01-03T23:26:57.915+0000] {processor.py:755} WARNING - No viable dags retrieved from /opt/airflow/dags/accidents_etl.py
[2023-01-03T23:26:57.932+0000] {processor.py:175} INFO - Processing /opt/airflow/dags/accidents_etl.py took 0.705 seconds
[2023-01-03T23:27:28.110+0000] {processor.py:153} INFO - Started process (PID=7067) to work on /opt/airflow/dags/accidents_etl.py
[2023-01-03T23:27:28.111+0000] {processor.py:743} INFO - Processing file /opt/airflow/dags/accidents_etl.py for tasks to queue
[2023-01-03T23:27:28.112+0000] {logging_mixin.py:137} INFO - [2023-01-03T23:27:28.112+0000] {dagbag.py:538} INFO - Filling up the DagBag from /opt/airflow/dags/accidents_etl.py
[2023-01-03T23:27:28.839+0000] {logging_mixin.py:137} INFO - [2023-01-03T23:27:28.833+0000] {dagbag.py:343} ERROR - Failed to import: /opt/airflow/dags/accidents_etl.py
Traceback (most recent call last):
  File "/home/airflow/.local/lib/python3.7/site-packages/airflow/models/dagbag.py", line 339, in parse
    loader.exec_module(new_module)
  File "<frozen importlib._bootstrap_external>", line 728, in exec_module
  File "<frozen importlib._bootstrap>", line 219, in _call_with_frames_removed
  File "/opt/airflow/dags/accidents_etl.py", line 17, in <module>
    'start_date': datetime(2022, 1, 1),
NameError: name 'datetime' is not defined
[2023-01-03T23:27:28.840+0000] {processor.py:755} WARNING - No viable dags retrieved from /opt/airflow/dags/accidents_etl.py
[2023-01-03T23:27:28.860+0000] {processor.py:175} INFO - Processing /opt/airflow/dags/accidents_etl.py took 0.753 seconds
[2023-01-03T23:27:59.040+0000] {processor.py:153} INFO - Started process (PID=7139) to work on /opt/airflow/dags/accidents_etl.py
[2023-01-03T23:27:59.041+0000] {processor.py:743} INFO - Processing file /opt/airflow/dags/accidents_etl.py for tasks to queue
[2023-01-03T23:27:59.042+0000] {logging_mixin.py:137} INFO - [2023-01-03T23:27:59.042+0000] {dagbag.py:538} INFO - Filling up the DagBag from /opt/airflow/dags/accidents_etl.py
[2023-01-03T23:27:59.713+0000] {logging_mixin.py:137} INFO - [2023-01-03T23:27:59.710+0000] {dagbag.py:343} ERROR - Failed to import: /opt/airflow/dags/accidents_etl.py
Traceback (most recent call last):
  File "/home/airflow/.local/lib/python3.7/site-packages/airflow/models/dagbag.py", line 339, in parse
    loader.exec_module(new_module)
  File "<frozen importlib._bootstrap_external>", line 728, in exec_module
  File "<frozen importlib._bootstrap>", line 219, in _call_with_frames_removed
  File "/opt/airflow/dags/accidents_etl.py", line 17, in <module>
    'start_date': datetime(2022, 1, 1),
NameError: name 'datetime' is not defined
[2023-01-03T23:27:59.714+0000] {processor.py:755} WARNING - No viable dags retrieved from /opt/airflow/dags/accidents_etl.py
[2023-01-03T23:27:59.732+0000] {processor.py:175} INFO - Processing /opt/airflow/dags/accidents_etl.py took 0.695 seconds
[2023-01-03T23:28:29.917+0000] {processor.py:153} INFO - Started process (PID=7193) to work on /opt/airflow/dags/accidents_etl.py
[2023-01-03T23:28:29.918+0000] {processor.py:743} INFO - Processing file /opt/airflow/dags/accidents_etl.py for tasks to queue
[2023-01-03T23:28:29.919+0000] {logging_mixin.py:137} INFO - [2023-01-03T23:28:29.919+0000] {dagbag.py:538} INFO - Filling up the DagBag from /opt/airflow/dags/accidents_etl.py
[2023-01-03T23:28:30.724+0000] {logging_mixin.py:137} INFO - [2023-01-03T23:28:30.720+0000] {dagbag.py:343} ERROR - Failed to import: /opt/airflow/dags/accidents_etl.py
Traceback (most recent call last):
  File "/home/airflow/.local/lib/python3.7/site-packages/airflow/models/dagbag.py", line 339, in parse
    loader.exec_module(new_module)
  File "<frozen importlib._bootstrap_external>", line 728, in exec_module
  File "<frozen importlib._bootstrap>", line 219, in _call_with_frames_removed
  File "/opt/airflow/dags/accidents_etl.py", line 17, in <module>
    'start_date': datetime(2022, 1, 1),
NameError: name 'datetime' is not defined
[2023-01-03T23:28:30.726+0000] {processor.py:755} WARNING - No viable dags retrieved from /opt/airflow/dags/accidents_etl.py
[2023-01-03T23:28:30.751+0000] {processor.py:175} INFO - Processing /opt/airflow/dags/accidents_etl.py took 0.838 seconds
[2023-01-03T23:29:00.952+0000] {processor.py:153} INFO - Started process (PID=7271) to work on /opt/airflow/dags/accidents_etl.py
[2023-01-03T23:29:00.953+0000] {processor.py:743} INFO - Processing file /opt/airflow/dags/accidents_etl.py for tasks to queue
[2023-01-03T23:29:00.953+0000] {logging_mixin.py:137} INFO - [2023-01-03T23:29:00.953+0000] {dagbag.py:538} INFO - Filling up the DagBag from /opt/airflow/dags/accidents_etl.py
[2023-01-03T23:29:01.602+0000] {logging_mixin.py:137} INFO - [2023-01-03T23:29:01.597+0000] {dagbag.py:343} ERROR - Failed to import: /opt/airflow/dags/accidents_etl.py
Traceback (most recent call last):
  File "/home/airflow/.local/lib/python3.7/site-packages/airflow/models/dagbag.py", line 339, in parse
    loader.exec_module(new_module)
  File "<frozen importlib._bootstrap_external>", line 728, in exec_module
  File "<frozen importlib._bootstrap>", line 219, in _call_with_frames_removed
  File "/opt/airflow/dags/accidents_etl.py", line 17, in <module>
    'start_date': datetime(2022, 1, 1),
NameError: name 'datetime' is not defined
[2023-01-03T23:29:01.604+0000] {processor.py:755} WARNING - No viable dags retrieved from /opt/airflow/dags/accidents_etl.py
[2023-01-03T23:29:01.625+0000] {processor.py:175} INFO - Processing /opt/airflow/dags/accidents_etl.py took 0.676 seconds
[2023-01-03T23:29:31.820+0000] {processor.py:153} INFO - Started process (PID=7325) to work on /opt/airflow/dags/accidents_etl.py
[2023-01-03T23:29:31.822+0000] {processor.py:743} INFO - Processing file /opt/airflow/dags/accidents_etl.py for tasks to queue
[2023-01-03T23:29:31.823+0000] {logging_mixin.py:137} INFO - [2023-01-03T23:29:31.823+0000] {dagbag.py:538} INFO - Filling up the DagBag from /opt/airflow/dags/accidents_etl.py
[2023-01-03T23:29:32.507+0000] {logging_mixin.py:137} INFO - [2023-01-03T23:29:32.504+0000] {dagbag.py:343} ERROR - Failed to import: /opt/airflow/dags/accidents_etl.py
Traceback (most recent call last):
  File "/home/airflow/.local/lib/python3.7/site-packages/airflow/models/dagbag.py", line 339, in parse
    loader.exec_module(new_module)
  File "<frozen importlib._bootstrap_external>", line 728, in exec_module
  File "<frozen importlib._bootstrap>", line 219, in _call_with_frames_removed
  File "/opt/airflow/dags/accidents_etl.py", line 17, in <module>
    'start_date': datetime(2022, 1, 1),
NameError: name 'datetime' is not defined
[2023-01-03T23:29:32.508+0000] {processor.py:755} WARNING - No viable dags retrieved from /opt/airflow/dags/accidents_etl.py
[2023-01-03T23:29:32.588+0000] {processor.py:175} INFO - Processing /opt/airflow/dags/accidents_etl.py took 0.772 seconds
[2023-01-03T23:30:02.821+0000] {processor.py:153} INFO - Started process (PID=7403) to work on /opt/airflow/dags/accidents_etl.py
[2023-01-03T23:30:02.822+0000] {processor.py:743} INFO - Processing file /opt/airflow/dags/accidents_etl.py for tasks to queue
[2023-01-03T23:30:02.823+0000] {logging_mixin.py:137} INFO - [2023-01-03T23:30:02.823+0000] {dagbag.py:538} INFO - Filling up the DagBag from /opt/airflow/dags/accidents_etl.py
[2023-01-03T23:30:03.541+0000] {logging_mixin.py:137} INFO - [2023-01-03T23:30:03.538+0000] {dagbag.py:343} ERROR - Failed to import: /opt/airflow/dags/accidents_etl.py
Traceback (most recent call last):
  File "/home/airflow/.local/lib/python3.7/site-packages/airflow/models/dagbag.py", line 339, in parse
    loader.exec_module(new_module)
  File "<frozen importlib._bootstrap_external>", line 728, in exec_module
  File "<frozen importlib._bootstrap>", line 219, in _call_with_frames_removed
  File "/opt/airflow/dags/accidents_etl.py", line 17, in <module>
    'start_date': datetime(2022, 1, 1),
NameError: name 'datetime' is not defined
[2023-01-03T23:30:03.542+0000] {processor.py:755} WARNING - No viable dags retrieved from /opt/airflow/dags/accidents_etl.py
[2023-01-03T23:30:03.558+0000] {processor.py:175} INFO - Processing /opt/airflow/dags/accidents_etl.py took 0.739 seconds
[2023-01-03T23:30:33.720+0000] {processor.py:153} INFO - Started process (PID=7457) to work on /opt/airflow/dags/accidents_etl.py
[2023-01-03T23:30:33.721+0000] {processor.py:743} INFO - Processing file /opt/airflow/dags/accidents_etl.py for tasks to queue
[2023-01-03T23:30:33.722+0000] {logging_mixin.py:137} INFO - [2023-01-03T23:30:33.722+0000] {dagbag.py:538} INFO - Filling up the DagBag from /opt/airflow/dags/accidents_etl.py
[2023-01-03T23:30:34.392+0000] {logging_mixin.py:137} INFO - [2023-01-03T23:30:34.388+0000] {dagbag.py:343} ERROR - Failed to import: /opt/airflow/dags/accidents_etl.py
Traceback (most recent call last):
  File "/home/airflow/.local/lib/python3.7/site-packages/airflow/models/dagbag.py", line 339, in parse
    loader.exec_module(new_module)
  File "<frozen importlib._bootstrap_external>", line 728, in exec_module
  File "<frozen importlib._bootstrap>", line 219, in _call_with_frames_removed
  File "/opt/airflow/dags/accidents_etl.py", line 17, in <module>
    'start_date': datetime(2022, 1, 1),
NameError: name 'datetime' is not defined
[2023-01-03T23:30:34.393+0000] {processor.py:755} WARNING - No viable dags retrieved from /opt/airflow/dags/accidents_etl.py
[2023-01-03T23:30:34.414+0000] {processor.py:175} INFO - Processing /opt/airflow/dags/accidents_etl.py took 0.697 seconds
[2023-01-03T23:31:04.603+0000] {processor.py:153} INFO - Started process (PID=7535) to work on /opt/airflow/dags/accidents_etl.py
[2023-01-03T23:31:04.604+0000] {processor.py:743} INFO - Processing file /opt/airflow/dags/accidents_etl.py for tasks to queue
[2023-01-03T23:31:04.605+0000] {logging_mixin.py:137} INFO - [2023-01-03T23:31:04.605+0000] {dagbag.py:538} INFO - Filling up the DagBag from /opt/airflow/dags/accidents_etl.py
[2023-01-03T23:31:05.287+0000] {logging_mixin.py:137} INFO - [2023-01-03T23:31:05.282+0000] {dagbag.py:343} ERROR - Failed to import: /opt/airflow/dags/accidents_etl.py
Traceback (most recent call last):
  File "/home/airflow/.local/lib/python3.7/site-packages/airflow/models/dagbag.py", line 339, in parse
    loader.exec_module(new_module)
  File "<frozen importlib._bootstrap_external>", line 728, in exec_module
  File "<frozen importlib._bootstrap>", line 219, in _call_with_frames_removed
  File "/opt/airflow/dags/accidents_etl.py", line 17, in <module>
    'start_date': datetime(2022, 1, 1),
NameError: name 'datetime' is not defined
[2023-01-03T23:31:05.288+0000] {processor.py:755} WARNING - No viable dags retrieved from /opt/airflow/dags/accidents_etl.py
[2023-01-03T23:31:05.307+0000] {processor.py:175} INFO - Processing /opt/airflow/dags/accidents_etl.py took 0.708 seconds
[2023-01-03T23:31:35.479+0000] {processor.py:153} INFO - Started process (PID=7589) to work on /opt/airflow/dags/accidents_etl.py
[2023-01-03T23:31:35.480+0000] {processor.py:743} INFO - Processing file /opt/airflow/dags/accidents_etl.py for tasks to queue
[2023-01-03T23:31:35.481+0000] {logging_mixin.py:137} INFO - [2023-01-03T23:31:35.480+0000] {dagbag.py:538} INFO - Filling up the DagBag from /opt/airflow/dags/accidents_etl.py
[2023-01-03T23:31:36.197+0000] {logging_mixin.py:137} INFO - [2023-01-03T23:31:36.194+0000] {dagbag.py:343} ERROR - Failed to import: /opt/airflow/dags/accidents_etl.py
Traceback (most recent call last):
  File "/home/airflow/.local/lib/python3.7/site-packages/airflow/models/dagbag.py", line 339, in parse
    loader.exec_module(new_module)
  File "<frozen importlib._bootstrap_external>", line 728, in exec_module
  File "<frozen importlib._bootstrap>", line 219, in _call_with_frames_removed
  File "/opt/airflow/dags/accidents_etl.py", line 17, in <module>
    'start_date': datetime(2022, 1, 1),
NameError: name 'datetime' is not defined
[2023-01-03T23:31:36.198+0000] {processor.py:755} WARNING - No viable dags retrieved from /opt/airflow/dags/accidents_etl.py
[2023-01-03T23:31:36.218+0000] {processor.py:175} INFO - Processing /opt/airflow/dags/accidents_etl.py took 0.742 seconds
[2023-01-03T23:32:06.424+0000] {processor.py:153} INFO - Started process (PID=7667) to work on /opt/airflow/dags/accidents_etl.py
[2023-01-03T23:32:06.426+0000] {processor.py:743} INFO - Processing file /opt/airflow/dags/accidents_etl.py for tasks to queue
[2023-01-03T23:32:06.427+0000] {logging_mixin.py:137} INFO - [2023-01-03T23:32:06.426+0000] {dagbag.py:538} INFO - Filling up the DagBag from /opt/airflow/dags/accidents_etl.py
[2023-01-03T23:32:07.122+0000] {logging_mixin.py:137} INFO - [2023-01-03T23:32:07.118+0000] {dagbag.py:343} ERROR - Failed to import: /opt/airflow/dags/accidents_etl.py
Traceback (most recent call last):
  File "/home/airflow/.local/lib/python3.7/site-packages/airflow/models/dagbag.py", line 339, in parse
    loader.exec_module(new_module)
  File "<frozen importlib._bootstrap_external>", line 728, in exec_module
  File "<frozen importlib._bootstrap>", line 219, in _call_with_frames_removed
  File "/opt/airflow/dags/accidents_etl.py", line 17, in <module>
    'start_date': datetime(2022, 1, 1),
NameError: name 'datetime' is not defined
[2023-01-03T23:32:07.123+0000] {processor.py:755} WARNING - No viable dags retrieved from /opt/airflow/dags/accidents_etl.py
[2023-01-03T23:32:07.139+0000] {processor.py:175} INFO - Processing /opt/airflow/dags/accidents_etl.py took 0.718 seconds
[2023-01-03T23:32:37.321+0000] {processor.py:153} INFO - Started process (PID=7721) to work on /opt/airflow/dags/accidents_etl.py
[2023-01-03T23:32:37.322+0000] {processor.py:743} INFO - Processing file /opt/airflow/dags/accidents_etl.py for tasks to queue
[2023-01-03T23:32:37.323+0000] {logging_mixin.py:137} INFO - [2023-01-03T23:32:37.323+0000] {dagbag.py:538} INFO - Filling up the DagBag from /opt/airflow/dags/accidents_etl.py
[2023-01-03T23:32:38.009+0000] {logging_mixin.py:137} INFO - [2023-01-03T23:32:38.005+0000] {dagbag.py:343} ERROR - Failed to import: /opt/airflow/dags/accidents_etl.py
Traceback (most recent call last):
  File "/home/airflow/.local/lib/python3.7/site-packages/airflow/models/dagbag.py", line 339, in parse
    loader.exec_module(new_module)
  File "<frozen importlib._bootstrap_external>", line 728, in exec_module
  File "<frozen importlib._bootstrap>", line 219, in _call_with_frames_removed
  File "/opt/airflow/dags/accidents_etl.py", line 17, in <module>
    'start_date': datetime(2022, 1, 1),
NameError: name 'datetime' is not defined
[2023-01-03T23:32:38.010+0000] {processor.py:755} WARNING - No viable dags retrieved from /opt/airflow/dags/accidents_etl.py
[2023-01-03T23:32:38.028+0000] {processor.py:175} INFO - Processing /opt/airflow/dags/accidents_etl.py took 0.709 seconds
[2023-01-03T23:33:08.214+0000] {processor.py:153} INFO - Started process (PID=7799) to work on /opt/airflow/dags/accidents_etl.py
[2023-01-03T23:33:08.215+0000] {processor.py:743} INFO - Processing file /opt/airflow/dags/accidents_etl.py for tasks to queue
[2023-01-03T23:33:08.215+0000] {logging_mixin.py:137} INFO - [2023-01-03T23:33:08.215+0000] {dagbag.py:538} INFO - Filling up the DagBag from /opt/airflow/dags/accidents_etl.py
[2023-01-03T23:33:08.915+0000] {logging_mixin.py:137} INFO - [2023-01-03T23:33:08.912+0000] {dagbag.py:343} ERROR - Failed to import: /opt/airflow/dags/accidents_etl.py
Traceback (most recent call last):
  File "/home/airflow/.local/lib/python3.7/site-packages/airflow/models/dagbag.py", line 339, in parse
    loader.exec_module(new_module)
  File "<frozen importlib._bootstrap_external>", line 728, in exec_module
  File "<frozen importlib._bootstrap>", line 219, in _call_with_frames_removed
  File "/opt/airflow/dags/accidents_etl.py", line 17, in <module>
    'start_date': datetime(2022, 1, 1),
NameError: name 'datetime' is not defined
[2023-01-03T23:33:08.916+0000] {processor.py:755} WARNING - No viable dags retrieved from /opt/airflow/dags/accidents_etl.py
[2023-01-03T23:33:08.935+0000] {processor.py:175} INFO - Processing /opt/airflow/dags/accidents_etl.py took 0.725 seconds
[2023-01-03T23:33:39.114+0000] {processor.py:153} INFO - Started process (PID=7853) to work on /opt/airflow/dags/accidents_etl.py
[2023-01-03T23:33:39.115+0000] {processor.py:743} INFO - Processing file /opt/airflow/dags/accidents_etl.py for tasks to queue
[2023-01-03T23:33:39.116+0000] {logging_mixin.py:137} INFO - [2023-01-03T23:33:39.116+0000] {dagbag.py:538} INFO - Filling up the DagBag from /opt/airflow/dags/accidents_etl.py
[2023-01-03T23:33:39.814+0000] {logging_mixin.py:137} INFO - [2023-01-03T23:33:39.810+0000] {dagbag.py:343} ERROR - Failed to import: /opt/airflow/dags/accidents_etl.py
Traceback (most recent call last):
  File "/home/airflow/.local/lib/python3.7/site-packages/airflow/models/dagbag.py", line 339, in parse
    loader.exec_module(new_module)
  File "<frozen importlib._bootstrap_external>", line 728, in exec_module
  File "<frozen importlib._bootstrap>", line 219, in _call_with_frames_removed
  File "/opt/airflow/dags/accidents_etl.py", line 17, in <module>
    'start_date': datetime(2022, 1, 1),
NameError: name 'datetime' is not defined
[2023-01-03T23:33:39.815+0000] {processor.py:755} WARNING - No viable dags retrieved from /opt/airflow/dags/accidents_etl.py
[2023-01-03T23:33:39.837+0000] {processor.py:175} INFO - Processing /opt/airflow/dags/accidents_etl.py took 0.727 seconds
[2023-01-03T23:34:10.040+0000] {processor.py:153} INFO - Started process (PID=7931) to work on /opt/airflow/dags/accidents_etl.py
[2023-01-03T23:34:10.041+0000] {processor.py:743} INFO - Processing file /opt/airflow/dags/accidents_etl.py for tasks to queue
[2023-01-03T23:34:10.042+0000] {logging_mixin.py:137} INFO - [2023-01-03T23:34:10.042+0000] {dagbag.py:538} INFO - Filling up the DagBag from /opt/airflow/dags/accidents_etl.py
[2023-01-03T23:34:10.750+0000] {logging_mixin.py:137} INFO - [2023-01-03T23:34:10.746+0000] {dagbag.py:343} ERROR - Failed to import: /opt/airflow/dags/accidents_etl.py
Traceback (most recent call last):
  File "/home/airflow/.local/lib/python3.7/site-packages/airflow/models/dagbag.py", line 339, in parse
    loader.exec_module(new_module)
  File "<frozen importlib._bootstrap_external>", line 728, in exec_module
  File "<frozen importlib._bootstrap>", line 219, in _call_with_frames_removed
  File "/opt/airflow/dags/accidents_etl.py", line 17, in <module>
    'start_date': datetime(2022, 1, 1),
NameError: name 'datetime' is not defined
[2023-01-03T23:34:10.751+0000] {processor.py:755} WARNING - No viable dags retrieved from /opt/airflow/dags/accidents_etl.py
[2023-01-03T23:34:10.779+0000] {processor.py:175} INFO - Processing /opt/airflow/dags/accidents_etl.py took 0.743 seconds
[2023-01-03T23:34:40.977+0000] {processor.py:153} INFO - Started process (PID=7985) to work on /opt/airflow/dags/accidents_etl.py
[2023-01-03T23:34:40.978+0000] {processor.py:743} INFO - Processing file /opt/airflow/dags/accidents_etl.py for tasks to queue
[2023-01-03T23:34:40.979+0000] {logging_mixin.py:137} INFO - [2023-01-03T23:34:40.979+0000] {dagbag.py:538} INFO - Filling up the DagBag from /opt/airflow/dags/accidents_etl.py
[2023-01-03T23:34:41.686+0000] {logging_mixin.py:137} INFO - [2023-01-03T23:34:41.682+0000] {dagbag.py:343} ERROR - Failed to import: /opt/airflow/dags/accidents_etl.py
Traceback (most recent call last):
  File "/home/airflow/.local/lib/python3.7/site-packages/airflow/models/dagbag.py", line 339, in parse
    loader.exec_module(new_module)
  File "<frozen importlib._bootstrap_external>", line 728, in exec_module
  File "<frozen importlib._bootstrap>", line 219, in _call_with_frames_removed
  File "/opt/airflow/dags/accidents_etl.py", line 17, in <module>
    'start_date': datetime(2022, 1, 1),
NameError: name 'datetime' is not defined
[2023-01-03T23:34:41.687+0000] {processor.py:755} WARNING - No viable dags retrieved from /opt/airflow/dags/accidents_etl.py
[2023-01-03T23:34:41.711+0000] {processor.py:175} INFO - Processing /opt/airflow/dags/accidents_etl.py took 0.737 seconds
[2023-01-03T23:35:11.892+0000] {processor.py:153} INFO - Started process (PID=8063) to work on /opt/airflow/dags/accidents_etl.py
[2023-01-03T23:35:11.893+0000] {processor.py:743} INFO - Processing file /opt/airflow/dags/accidents_etl.py for tasks to queue
[2023-01-03T23:35:11.894+0000] {logging_mixin.py:137} INFO - [2023-01-03T23:35:11.893+0000] {dagbag.py:538} INFO - Filling up the DagBag from /opt/airflow/dags/accidents_etl.py
[2023-01-03T23:35:12.642+0000] {logging_mixin.py:137} INFO - [2023-01-03T23:35:12.640+0000] {dagbag.py:343} ERROR - Failed to import: /opt/airflow/dags/accidents_etl.py
Traceback (most recent call last):
  File "/home/airflow/.local/lib/python3.7/site-packages/airflow/models/dagbag.py", line 339, in parse
    loader.exec_module(new_module)
  File "<frozen importlib._bootstrap_external>", line 728, in exec_module
  File "<frozen importlib._bootstrap>", line 219, in _call_with_frames_removed
  File "/opt/airflow/dags/accidents_etl.py", line 17, in <module>
    'start_date': datetime(2022, 1, 1),
NameError: name 'datetime' is not defined
[2023-01-03T23:35:12.643+0000] {processor.py:755} WARNING - No viable dags retrieved from /opt/airflow/dags/accidents_etl.py
[2023-01-03T23:35:12.664+0000] {processor.py:175} INFO - Processing /opt/airflow/dags/accidents_etl.py took 0.775 seconds
[2023-01-03T23:35:42.747+0000] {processor.py:153} INFO - Started process (PID=8117) to work on /opt/airflow/dags/accidents_etl.py
[2023-01-03T23:35:42.748+0000] {processor.py:743} INFO - Processing file /opt/airflow/dags/accidents_etl.py for tasks to queue
[2023-01-03T23:35:42.749+0000] {logging_mixin.py:137} INFO - [2023-01-03T23:35:42.749+0000] {dagbag.py:538} INFO - Filling up the DagBag from /opt/airflow/dags/accidents_etl.py
[2023-01-03T23:35:43.507+0000] {logging_mixin.py:137} INFO - [2023-01-03T23:35:43.503+0000] {dagbag.py:343} ERROR - Failed to import: /opt/airflow/dags/accidents_etl.py
Traceback (most recent call last):
  File "/home/airflow/.local/lib/python3.7/site-packages/airflow/models/dagbag.py", line 339, in parse
    loader.exec_module(new_module)
  File "<frozen importlib._bootstrap_external>", line 728, in exec_module
  File "<frozen importlib._bootstrap>", line 219, in _call_with_frames_removed
  File "/opt/airflow/dags/accidents_etl.py", line 17, in <module>
    'start_date': datetime(2022, 1, 1),
NameError: name 'datetime' is not defined
[2023-01-03T23:35:43.509+0000] {processor.py:755} WARNING - No viable dags retrieved from /opt/airflow/dags/accidents_etl.py
[2023-01-03T23:35:43.526+0000] {processor.py:175} INFO - Processing /opt/airflow/dags/accidents_etl.py took 0.783 seconds
[2023-01-03T23:36:13.718+0000] {processor.py:153} INFO - Started process (PID=8196) to work on /opt/airflow/dags/accidents_etl.py
[2023-01-03T23:36:13.719+0000] {processor.py:743} INFO - Processing file /opt/airflow/dags/accidents_etl.py for tasks to queue
[2023-01-03T23:36:13.720+0000] {logging_mixin.py:137} INFO - [2023-01-03T23:36:13.720+0000] {dagbag.py:538} INFO - Filling up the DagBag from /opt/airflow/dags/accidents_etl.py
[2023-01-03T23:36:14.451+0000] {logging_mixin.py:137} INFO - [2023-01-03T23:36:14.447+0000] {dagbag.py:343} ERROR - Failed to import: /opt/airflow/dags/accidents_etl.py
Traceback (most recent call last):
  File "/home/airflow/.local/lib/python3.7/site-packages/airflow/models/dagbag.py", line 339, in parse
    loader.exec_module(new_module)
  File "<frozen importlib._bootstrap_external>", line 728, in exec_module
  File "<frozen importlib._bootstrap>", line 219, in _call_with_frames_removed
  File "/opt/airflow/dags/accidents_etl.py", line 17, in <module>
    'start_date': datetime(2022, 1, 1),
NameError: name 'datetime' is not defined
[2023-01-03T23:36:14.452+0000] {processor.py:755} WARNING - No viable dags retrieved from /opt/airflow/dags/accidents_etl.py
[2023-01-03T23:36:14.470+0000] {processor.py:175} INFO - Processing /opt/airflow/dags/accidents_etl.py took 0.755 seconds
[2023-01-03T23:36:44.659+0000] {processor.py:153} INFO - Started process (PID=8250) to work on /opt/airflow/dags/accidents_etl.py
[2023-01-03T23:36:44.660+0000] {processor.py:743} INFO - Processing file /opt/airflow/dags/accidents_etl.py for tasks to queue
[2023-01-03T23:36:44.661+0000] {logging_mixin.py:137} INFO - [2023-01-03T23:36:44.661+0000] {dagbag.py:538} INFO - Filling up the DagBag from /opt/airflow/dags/accidents_etl.py
[2023-01-03T23:36:45.379+0000] {logging_mixin.py:137} INFO - [2023-01-03T23:36:45.375+0000] {dagbag.py:343} ERROR - Failed to import: /opt/airflow/dags/accidents_etl.py
Traceback (most recent call last):
  File "/home/airflow/.local/lib/python3.7/site-packages/airflow/models/dagbag.py", line 339, in parse
    loader.exec_module(new_module)
  File "<frozen importlib._bootstrap_external>", line 728, in exec_module
  File "<frozen importlib._bootstrap>", line 219, in _call_with_frames_removed
  File "/opt/airflow/dags/accidents_etl.py", line 17, in <module>
    'start_date': datetime(2022, 1, 1),
NameError: name 'datetime' is not defined
[2023-01-03T23:36:45.380+0000] {processor.py:755} WARNING - No viable dags retrieved from /opt/airflow/dags/accidents_etl.py
[2023-01-03T23:36:45.401+0000] {processor.py:175} INFO - Processing /opt/airflow/dags/accidents_etl.py took 0.745 seconds
[2023-01-03T23:37:15.624+0000] {processor.py:153} INFO - Started process (PID=8328) to work on /opt/airflow/dags/accidents_etl.py
[2023-01-03T23:37:15.626+0000] {processor.py:743} INFO - Processing file /opt/airflow/dags/accidents_etl.py for tasks to queue
[2023-01-03T23:37:15.627+0000] {logging_mixin.py:137} INFO - [2023-01-03T23:37:15.627+0000] {dagbag.py:538} INFO - Filling up the DagBag from /opt/airflow/dags/accidents_etl.py
[2023-01-03T23:37:16.381+0000] {logging_mixin.py:137} INFO - [2023-01-03T23:37:16.378+0000] {dagbag.py:343} ERROR - Failed to import: /opt/airflow/dags/accidents_etl.py
Traceback (most recent call last):
  File "/home/airflow/.local/lib/python3.7/site-packages/airflow/models/dagbag.py", line 339, in parse
    loader.exec_module(new_module)
  File "<frozen importlib._bootstrap_external>", line 728, in exec_module
  File "<frozen importlib._bootstrap>", line 219, in _call_with_frames_removed
  File "/opt/airflow/dags/accidents_etl.py", line 17, in <module>
    'start_date': datetime(2022, 1, 1),
NameError: name 'datetime' is not defined
[2023-01-03T23:37:16.382+0000] {processor.py:755} WARNING - No viable dags retrieved from /opt/airflow/dags/accidents_etl.py
[2023-01-03T23:37:16.405+0000] {processor.py:175} INFO - Processing /opt/airflow/dags/accidents_etl.py took 0.786 seconds
[2023-01-03T23:37:46.480+0000] {processor.py:153} INFO - Started process (PID=8382) to work on /opt/airflow/dags/accidents_etl.py
[2023-01-03T23:37:46.481+0000] {processor.py:743} INFO - Processing file /opt/airflow/dags/accidents_etl.py for tasks to queue
[2023-01-03T23:37:46.482+0000] {logging_mixin.py:137} INFO - [2023-01-03T23:37:46.482+0000] {dagbag.py:538} INFO - Filling up the DagBag from /opt/airflow/dags/accidents_etl.py
[2023-01-03T23:37:47.146+0000] {logging_mixin.py:137} INFO - [2023-01-03T23:37:47.142+0000] {dagbag.py:343} ERROR - Failed to import: /opt/airflow/dags/accidents_etl.py
Traceback (most recent call last):
  File "/home/airflow/.local/lib/python3.7/site-packages/airflow/models/dagbag.py", line 339, in parse
    loader.exec_module(new_module)
  File "<frozen importlib._bootstrap_external>", line 728, in exec_module
  File "<frozen importlib._bootstrap>", line 219, in _call_with_frames_removed
  File "/opt/airflow/dags/accidents_etl.py", line 17, in <module>
    'start_date': datetime(2022, 1, 1),
NameError: name 'datetime' is not defined
[2023-01-03T23:37:47.147+0000] {processor.py:755} WARNING - No viable dags retrieved from /opt/airflow/dags/accidents_etl.py
[2023-01-03T23:37:47.167+0000] {processor.py:175} INFO - Processing /opt/airflow/dags/accidents_etl.py took 0.691 seconds
[2023-01-03T23:38:17.373+0000] {processor.py:153} INFO - Started process (PID=8461) to work on /opt/airflow/dags/accidents_etl.py
[2023-01-03T23:38:17.375+0000] {processor.py:743} INFO - Processing file /opt/airflow/dags/accidents_etl.py for tasks to queue
[2023-01-03T23:38:17.381+0000] {logging_mixin.py:137} INFO - [2023-01-03T23:38:17.381+0000] {dagbag.py:538} INFO - Filling up the DagBag from /opt/airflow/dags/accidents_etl.py
[2023-01-03T23:38:18.147+0000] {logging_mixin.py:137} INFO - [2023-01-03T23:38:18.143+0000] {dagbag.py:343} ERROR - Failed to import: /opt/airflow/dags/accidents_etl.py
Traceback (most recent call last):
  File "/home/airflow/.local/lib/python3.7/site-packages/airflow/models/dagbag.py", line 339, in parse
    loader.exec_module(new_module)
  File "<frozen importlib._bootstrap_external>", line 728, in exec_module
  File "<frozen importlib._bootstrap>", line 219, in _call_with_frames_removed
  File "/opt/airflow/dags/accidents_etl.py", line 17, in <module>
    'start_date': datetime(2022, 1, 1),
NameError: name 'datetime' is not defined
[2023-01-03T23:38:18.148+0000] {processor.py:755} WARNING - No viable dags retrieved from /opt/airflow/dags/accidents_etl.py
[2023-01-03T23:38:18.169+0000] {processor.py:175} INFO - Processing /opt/airflow/dags/accidents_etl.py took 0.799 seconds
[2023-01-03T23:38:48.342+0000] {processor.py:153} INFO - Started process (PID=8515) to work on /opt/airflow/dags/accidents_etl.py
[2023-01-03T23:38:48.343+0000] {processor.py:743} INFO - Processing file /opt/airflow/dags/accidents_etl.py for tasks to queue
[2023-01-03T23:38:48.345+0000] {logging_mixin.py:137} INFO - [2023-01-03T23:38:48.344+0000] {dagbag.py:538} INFO - Filling up the DagBag from /opt/airflow/dags/accidents_etl.py
[2023-01-03T23:38:49.089+0000] {logging_mixin.py:137} INFO - [2023-01-03T23:38:49.086+0000] {dagbag.py:343} ERROR - Failed to import: /opt/airflow/dags/accidents_etl.py
Traceback (most recent call last):
  File "/home/airflow/.local/lib/python3.7/site-packages/airflow/models/dagbag.py", line 339, in parse
    loader.exec_module(new_module)
  File "<frozen importlib._bootstrap_external>", line 728, in exec_module
  File "<frozen importlib._bootstrap>", line 219, in _call_with_frames_removed
  File "/opt/airflow/dags/accidents_etl.py", line 17, in <module>
    'start_date': datetime(2022, 1, 1),
NameError: name 'datetime' is not defined
[2023-01-03T23:38:49.090+0000] {processor.py:755} WARNING - No viable dags retrieved from /opt/airflow/dags/accidents_etl.py
[2023-01-03T23:38:49.115+0000] {processor.py:175} INFO - Processing /opt/airflow/dags/accidents_etl.py took 0.776 seconds
[2023-01-03T23:39:19.287+0000] {processor.py:153} INFO - Started process (PID=8578) to work on /opt/airflow/dags/accidents_etl.py
[2023-01-03T23:39:19.288+0000] {processor.py:743} INFO - Processing file /opt/airflow/dags/accidents_etl.py for tasks to queue
[2023-01-03T23:39:19.289+0000] {logging_mixin.py:137} INFO - [2023-01-03T23:39:19.289+0000] {dagbag.py:538} INFO - Filling up the DagBag from /opt/airflow/dags/accidents_etl.py
[2023-01-03T23:39:20.006+0000] {logging_mixin.py:137} INFO - [2023-01-03T23:39:20.000+0000] {dagbag.py:343} ERROR - Failed to import: /opt/airflow/dags/accidents_etl.py
Traceback (most recent call last):
  File "/home/airflow/.local/lib/python3.7/site-packages/airflow/models/dagbag.py", line 339, in parse
    loader.exec_module(new_module)
  File "<frozen importlib._bootstrap_external>", line 728, in exec_module
  File "<frozen importlib._bootstrap>", line 219, in _call_with_frames_removed
  File "/opt/airflow/dags/accidents_etl.py", line 17, in <module>
    'start_date': datetime(2022, 1, 1),
NameError: name 'datetime' is not defined
[2023-01-03T23:39:20.007+0000] {processor.py:755} WARNING - No viable dags retrieved from /opt/airflow/dags/accidents_etl.py
[2023-01-03T23:39:20.027+0000] {processor.py:175} INFO - Processing /opt/airflow/dags/accidents_etl.py took 0.744 seconds
[2023-01-03T23:39:50.228+0000] {processor.py:153} INFO - Started process (PID=8647) to work on /opt/airflow/dags/accidents_etl.py
[2023-01-03T23:39:50.228+0000] {processor.py:743} INFO - Processing file /opt/airflow/dags/accidents_etl.py for tasks to queue
[2023-01-03T23:39:50.229+0000] {logging_mixin.py:137} INFO - [2023-01-03T23:39:50.229+0000] {dagbag.py:538} INFO - Filling up the DagBag from /opt/airflow/dags/accidents_etl.py
[2023-01-03T23:39:50.965+0000] {logging_mixin.py:137} INFO - [2023-01-03T23:39:50.960+0000] {dagbag.py:343} ERROR - Failed to import: /opt/airflow/dags/accidents_etl.py
Traceback (most recent call last):
  File "/home/airflow/.local/lib/python3.7/site-packages/airflow/models/dagbag.py", line 339, in parse
    loader.exec_module(new_module)
  File "<frozen importlib._bootstrap_external>", line 728, in exec_module
  File "<frozen importlib._bootstrap>", line 219, in _call_with_frames_removed
  File "/opt/airflow/dags/accidents_etl.py", line 17, in <module>
    'start_date': datetime(2022, 1, 1),
NameError: name 'datetime' is not defined
[2023-01-03T23:39:50.966+0000] {processor.py:755} WARNING - No viable dags retrieved from /opt/airflow/dags/accidents_etl.py
[2023-01-03T23:39:50.991+0000] {processor.py:175} INFO - Processing /opt/airflow/dags/accidents_etl.py took 0.767 seconds
[2023-01-03T23:40:21.181+0000] {processor.py:153} INFO - Started process (PID=8701) to work on /opt/airflow/dags/accidents_etl.py
[2023-01-03T23:40:21.182+0000] {processor.py:743} INFO - Processing file /opt/airflow/dags/accidents_etl.py for tasks to queue
[2023-01-03T23:40:21.183+0000] {logging_mixin.py:137} INFO - [2023-01-03T23:40:21.183+0000] {dagbag.py:538} INFO - Filling up the DagBag from /opt/airflow/dags/accidents_etl.py
[2023-01-03T23:40:21.879+0000] {logging_mixin.py:137} INFO - [2023-01-03T23:40:21.875+0000] {dagbag.py:343} ERROR - Failed to import: /opt/airflow/dags/accidents_etl.py
Traceback (most recent call last):
  File "/home/airflow/.local/lib/python3.7/site-packages/airflow/models/dagbag.py", line 339, in parse
    loader.exec_module(new_module)
  File "<frozen importlib._bootstrap_external>", line 728, in exec_module
  File "<frozen importlib._bootstrap>", line 219, in _call_with_frames_removed
  File "/opt/airflow/dags/accidents_etl.py", line 17, in <module>
    'start_date': datetime(2022, 1, 1),
NameError: name 'datetime' is not defined
[2023-01-03T23:40:21.880+0000] {processor.py:755} WARNING - No viable dags retrieved from /opt/airflow/dags/accidents_etl.py
[2023-01-03T23:40:21.902+0000] {processor.py:175} INFO - Processing /opt/airflow/dags/accidents_etl.py took 0.724 seconds
[2023-01-03T23:40:52.096+0000] {processor.py:153} INFO - Started process (PID=8779) to work on /opt/airflow/dags/accidents_etl.py
[2023-01-03T23:40:52.097+0000] {processor.py:743} INFO - Processing file /opt/airflow/dags/accidents_etl.py for tasks to queue
[2023-01-03T23:40:52.099+0000] {logging_mixin.py:137} INFO - [2023-01-03T23:40:52.099+0000] {dagbag.py:538} INFO - Filling up the DagBag from /opt/airflow/dags/accidents_etl.py
[2023-01-03T23:40:52.912+0000] {logging_mixin.py:137} INFO - [2023-01-03T23:40:52.907+0000] {dagbag.py:343} ERROR - Failed to import: /opt/airflow/dags/accidents_etl.py
Traceback (most recent call last):
  File "/home/airflow/.local/lib/python3.7/site-packages/airflow/models/dagbag.py", line 339, in parse
    loader.exec_module(new_module)
  File "<frozen importlib._bootstrap_external>", line 728, in exec_module
  File "<frozen importlib._bootstrap>", line 219, in _call_with_frames_removed
  File "/opt/airflow/dags/accidents_etl.py", line 17, in <module>
    'start_date': datetime(2022, 1, 1),
NameError: name 'datetime' is not defined
[2023-01-03T23:40:52.913+0000] {processor.py:755} WARNING - No viable dags retrieved from /opt/airflow/dags/accidents_etl.py
[2023-01-03T23:40:52.935+0000] {processor.py:175} INFO - Processing /opt/airflow/dags/accidents_etl.py took 0.843 seconds
[2023-01-03T23:41:23.121+0000] {processor.py:153} INFO - Started process (PID=8833) to work on /opt/airflow/dags/accidents_etl.py
[2023-01-03T23:41:23.123+0000] {processor.py:743} INFO - Processing file /opt/airflow/dags/accidents_etl.py for tasks to queue
[2023-01-03T23:41:23.124+0000] {logging_mixin.py:137} INFO - [2023-01-03T23:41:23.123+0000] {dagbag.py:538} INFO - Filling up the DagBag from /opt/airflow/dags/accidents_etl.py
[2023-01-03T23:41:23.934+0000] {logging_mixin.py:137} INFO - [2023-01-03T23:41:23.929+0000] {dagbag.py:343} ERROR - Failed to import: /opt/airflow/dags/accidents_etl.py
Traceback (most recent call last):
  File "/home/airflow/.local/lib/python3.7/site-packages/airflow/models/dagbag.py", line 339, in parse
    loader.exec_module(new_module)
  File "<frozen importlib._bootstrap_external>", line 728, in exec_module
  File "<frozen importlib._bootstrap>", line 219, in _call_with_frames_removed
  File "/opt/airflow/dags/accidents_etl.py", line 17, in <module>
    'start_date': datetime(2022, 1, 1),
NameError: name 'datetime' is not defined
[2023-01-03T23:41:23.937+0000] {processor.py:755} WARNING - No viable dags retrieved from /opt/airflow/dags/accidents_etl.py
[2023-01-03T23:41:23.956+0000] {processor.py:175} INFO - Processing /opt/airflow/dags/accidents_etl.py took 0.839 seconds
[2023-01-03T23:41:54.139+0000] {processor.py:153} INFO - Started process (PID=8911) to work on /opt/airflow/dags/accidents_etl.py
[2023-01-03T23:41:54.140+0000] {processor.py:743} INFO - Processing file /opt/airflow/dags/accidents_etl.py for tasks to queue
[2023-01-03T23:41:54.141+0000] {logging_mixin.py:137} INFO - [2023-01-03T23:41:54.141+0000] {dagbag.py:538} INFO - Filling up the DagBag from /opt/airflow/dags/accidents_etl.py
[2023-01-03T23:41:54.848+0000] {logging_mixin.py:137} INFO - [2023-01-03T23:41:54.843+0000] {dagbag.py:343} ERROR - Failed to import: /opt/airflow/dags/accidents_etl.py
Traceback (most recent call last):
  File "/home/airflow/.local/lib/python3.7/site-packages/airflow/models/dagbag.py", line 339, in parse
    loader.exec_module(new_module)
  File "<frozen importlib._bootstrap_external>", line 728, in exec_module
  File "<frozen importlib._bootstrap>", line 219, in _call_with_frames_removed
  File "/opt/airflow/dags/accidents_etl.py", line 17, in <module>
    'start_date': datetime(2022, 1, 1),
NameError: name 'datetime' is not defined
[2023-01-03T23:41:54.848+0000] {processor.py:755} WARNING - No viable dags retrieved from /opt/airflow/dags/accidents_etl.py
[2023-01-03T23:41:54.869+0000] {processor.py:175} INFO - Processing /opt/airflow/dags/accidents_etl.py took 0.735 seconds
[2023-01-03T23:42:25.077+0000] {processor.py:153} INFO - Started process (PID=8965) to work on /opt/airflow/dags/accidents_etl.py
[2023-01-03T23:42:25.078+0000] {processor.py:743} INFO - Processing file /opt/airflow/dags/accidents_etl.py for tasks to queue
[2023-01-03T23:42:25.079+0000] {logging_mixin.py:137} INFO - [2023-01-03T23:42:25.079+0000] {dagbag.py:538} INFO - Filling up the DagBag from /opt/airflow/dags/accidents_etl.py
[2023-01-03T23:42:25.781+0000] {logging_mixin.py:137} INFO - [2023-01-03T23:42:25.777+0000] {dagbag.py:343} ERROR - Failed to import: /opt/airflow/dags/accidents_etl.py
Traceback (most recent call last):
  File "/home/airflow/.local/lib/python3.7/site-packages/airflow/models/dagbag.py", line 339, in parse
    loader.exec_module(new_module)
  File "<frozen importlib._bootstrap_external>", line 728, in exec_module
  File "<frozen importlib._bootstrap>", line 219, in _call_with_frames_removed
  File "/opt/airflow/dags/accidents_etl.py", line 17, in <module>
    'start_date': datetime(2022, 1, 1),
NameError: name 'datetime' is not defined
[2023-01-03T23:42:25.782+0000] {processor.py:755} WARNING - No viable dags retrieved from /opt/airflow/dags/accidents_etl.py
[2023-01-03T23:42:25.797+0000] {processor.py:175} INFO - Processing /opt/airflow/dags/accidents_etl.py took 0.724 seconds
[2023-01-03T23:42:55.995+0000] {processor.py:153} INFO - Started process (PID=9043) to work on /opt/airflow/dags/accidents_etl.py
[2023-01-03T23:42:55.997+0000] {processor.py:743} INFO - Processing file /opt/airflow/dags/accidents_etl.py for tasks to queue
[2023-01-03T23:42:55.998+0000] {logging_mixin.py:137} INFO - [2023-01-03T23:42:55.998+0000] {dagbag.py:538} INFO - Filling up the DagBag from /opt/airflow/dags/accidents_etl.py
[2023-01-03T23:42:56.724+0000] {logging_mixin.py:137} INFO - [2023-01-03T23:42:56.721+0000] {dagbag.py:343} ERROR - Failed to import: /opt/airflow/dags/accidents_etl.py
Traceback (most recent call last):
  File "/home/airflow/.local/lib/python3.7/site-packages/airflow/models/dagbag.py", line 339, in parse
    loader.exec_module(new_module)
  File "<frozen importlib._bootstrap_external>", line 728, in exec_module
  File "<frozen importlib._bootstrap>", line 219, in _call_with_frames_removed
  File "/opt/airflow/dags/accidents_etl.py", line 17, in <module>
    'start_date': datetime(2022, 1, 1),
NameError: name 'datetime' is not defined
[2023-01-03T23:42:56.726+0000] {processor.py:755} WARNING - No viable dags retrieved from /opt/airflow/dags/accidents_etl.py
[2023-01-03T23:42:56.742+0000] {processor.py:175} INFO - Processing /opt/airflow/dags/accidents_etl.py took 0.750 seconds
[2023-01-03T23:43:26.923+0000] {processor.py:153} INFO - Started process (PID=9097) to work on /opt/airflow/dags/accidents_etl.py
[2023-01-03T23:43:26.924+0000] {processor.py:743} INFO - Processing file /opt/airflow/dags/accidents_etl.py for tasks to queue
[2023-01-03T23:43:26.925+0000] {logging_mixin.py:137} INFO - [2023-01-03T23:43:26.925+0000] {dagbag.py:538} INFO - Filling up the DagBag from /opt/airflow/dags/accidents_etl.py
[2023-01-03T23:43:27.644+0000] {logging_mixin.py:137} INFO - [2023-01-03T23:43:27.638+0000] {dagbag.py:343} ERROR - Failed to import: /opt/airflow/dags/accidents_etl.py
Traceback (most recent call last):
  File "/home/airflow/.local/lib/python3.7/site-packages/airflow/models/dagbag.py", line 339, in parse
    loader.exec_module(new_module)
  File "<frozen importlib._bootstrap_external>", line 728, in exec_module
  File "<frozen importlib._bootstrap>", line 219, in _call_with_frames_removed
  File "/opt/airflow/dags/accidents_etl.py", line 17, in <module>
    'start_date': datetime(2022, 1, 1),
NameError: name 'datetime' is not defined
[2023-01-03T23:43:27.645+0000] {processor.py:755} WARNING - No viable dags retrieved from /opt/airflow/dags/accidents_etl.py
[2023-01-03T23:43:27.660+0000] {processor.py:175} INFO - Processing /opt/airflow/dags/accidents_etl.py took 0.741 seconds
[2023-01-03T23:43:57.777+0000] {processor.py:153} INFO - Started process (PID=9176) to work on /opt/airflow/dags/accidents_etl.py
[2023-01-03T23:43:57.779+0000] {processor.py:743} INFO - Processing file /opt/airflow/dags/accidents_etl.py for tasks to queue
[2023-01-03T23:43:57.780+0000] {logging_mixin.py:137} INFO - [2023-01-03T23:43:57.780+0000] {dagbag.py:538} INFO - Filling up the DagBag from /opt/airflow/dags/accidents_etl.py
[2023-01-03T23:43:58.543+0000] {logging_mixin.py:137} INFO - [2023-01-03T23:43:58.539+0000] {dagbag.py:343} ERROR - Failed to import: /opt/airflow/dags/accidents_etl.py
Traceback (most recent call last):
  File "/home/airflow/.local/lib/python3.7/site-packages/airflow/models/dagbag.py", line 339, in parse
    loader.exec_module(new_module)
  File "<frozen importlib._bootstrap_external>", line 728, in exec_module
  File "<frozen importlib._bootstrap>", line 219, in _call_with_frames_removed
  File "/opt/airflow/dags/accidents_etl.py", line 17, in <module>
    'start_date': datetime(2022, 1, 1),
NameError: name 'datetime' is not defined
[2023-01-03T23:43:58.544+0000] {processor.py:755} WARNING - No viable dags retrieved from /opt/airflow/dags/accidents_etl.py
[2023-01-03T23:43:58.566+0000] {processor.py:175} INFO - Processing /opt/airflow/dags/accidents_etl.py took 0.792 seconds
[2023-01-03T23:44:28.764+0000] {processor.py:153} INFO - Started process (PID=9230) to work on /opt/airflow/dags/accidents_etl.py
[2023-01-03T23:44:28.766+0000] {processor.py:743} INFO - Processing file /opt/airflow/dags/accidents_etl.py for tasks to queue
[2023-01-03T23:44:28.768+0000] {logging_mixin.py:137} INFO - [2023-01-03T23:44:28.767+0000] {dagbag.py:538} INFO - Filling up the DagBag from /opt/airflow/dags/accidents_etl.py
[2023-01-03T23:44:29.514+0000] {logging_mixin.py:137} INFO - [2023-01-03T23:44:29.510+0000] {dagbag.py:343} ERROR - Failed to import: /opt/airflow/dags/accidents_etl.py
Traceback (most recent call last):
  File "/home/airflow/.local/lib/python3.7/site-packages/airflow/models/dagbag.py", line 339, in parse
    loader.exec_module(new_module)
  File "<frozen importlib._bootstrap_external>", line 728, in exec_module
  File "<frozen importlib._bootstrap>", line 219, in _call_with_frames_removed
  File "/opt/airflow/dags/accidents_etl.py", line 17, in <module>
    'start_date': datetime(2022, 1, 1),
NameError: name 'datetime' is not defined
[2023-01-03T23:44:29.515+0000] {processor.py:755} WARNING - No viable dags retrieved from /opt/airflow/dags/accidents_etl.py
[2023-01-03T23:44:29.532+0000] {processor.py:175} INFO - Processing /opt/airflow/dags/accidents_etl.py took 0.773 seconds
[2023-01-03T23:44:59.726+0000] {processor.py:153} INFO - Started process (PID=9309) to work on /opt/airflow/dags/accidents_etl.py
[2023-01-03T23:44:59.728+0000] {processor.py:743} INFO - Processing file /opt/airflow/dags/accidents_etl.py for tasks to queue
[2023-01-03T23:44:59.729+0000] {logging_mixin.py:137} INFO - [2023-01-03T23:44:59.728+0000] {dagbag.py:538} INFO - Filling up the DagBag from /opt/airflow/dags/accidents_etl.py
[2023-01-03T23:45:00.448+0000] {logging_mixin.py:137} INFO - [2023-01-03T23:45:00.442+0000] {dagbag.py:343} ERROR - Failed to import: /opt/airflow/dags/accidents_etl.py
Traceback (most recent call last):
  File "/home/airflow/.local/lib/python3.7/site-packages/airflow/models/dagbag.py", line 339, in parse
    loader.exec_module(new_module)
  File "<frozen importlib._bootstrap_external>", line 728, in exec_module
  File "<frozen importlib._bootstrap>", line 219, in _call_with_frames_removed
  File "/opt/airflow/dags/accidents_etl.py", line 17, in <module>
    'start_date': datetime(2022, 1, 1),
NameError: name 'datetime' is not defined
[2023-01-03T23:45:00.450+0000] {processor.py:755} WARNING - No viable dags retrieved from /opt/airflow/dags/accidents_etl.py
[2023-01-03T23:45:00.482+0000] {processor.py:175} INFO - Processing /opt/airflow/dags/accidents_etl.py took 0.759 seconds
[2023-01-03T23:45:30.686+0000] {processor.py:153} INFO - Started process (PID=9363) to work on /opt/airflow/dags/accidents_etl.py
[2023-01-03T23:45:30.688+0000] {processor.py:743} INFO - Processing file /opt/airflow/dags/accidents_etl.py for tasks to queue
[2023-01-03T23:45:30.690+0000] {logging_mixin.py:137} INFO - [2023-01-03T23:45:30.690+0000] {dagbag.py:538} INFO - Filling up the DagBag from /opt/airflow/dags/accidents_etl.py
[2023-01-03T23:45:31.425+0000] {logging_mixin.py:137} INFO - [2023-01-03T23:45:31.421+0000] {dagbag.py:343} ERROR - Failed to import: /opt/airflow/dags/accidents_etl.py
Traceback (most recent call last):
  File "/home/airflow/.local/lib/python3.7/site-packages/airflow/models/dagbag.py", line 339, in parse
    loader.exec_module(new_module)
  File "<frozen importlib._bootstrap_external>", line 728, in exec_module
  File "<frozen importlib._bootstrap>", line 219, in _call_with_frames_removed
  File "/opt/airflow/dags/accidents_etl.py", line 17, in <module>
    'start_date': datetime(2022, 1, 1),
NameError: name 'datetime' is not defined
[2023-01-03T23:45:31.426+0000] {processor.py:755} WARNING - No viable dags retrieved from /opt/airflow/dags/accidents_etl.py
[2023-01-03T23:45:31.452+0000] {processor.py:175} INFO - Processing /opt/airflow/dags/accidents_etl.py took 0.773 seconds
[2023-01-03T23:46:01.654+0000] {processor.py:153} INFO - Started process (PID=9441) to work on /opt/airflow/dags/accidents_etl.py
[2023-01-03T23:46:01.655+0000] {processor.py:743} INFO - Processing file /opt/airflow/dags/accidents_etl.py for tasks to queue
[2023-01-03T23:46:01.656+0000] {logging_mixin.py:137} INFO - [2023-01-03T23:46:01.656+0000] {dagbag.py:538} INFO - Filling up the DagBag from /opt/airflow/dags/accidents_etl.py
[2023-01-03T23:46:02.349+0000] {logging_mixin.py:137} INFO - [2023-01-03T23:46:02.346+0000] {dagbag.py:343} ERROR - Failed to import: /opt/airflow/dags/accidents_etl.py
Traceback (most recent call last):
  File "/home/airflow/.local/lib/python3.7/site-packages/airflow/models/dagbag.py", line 339, in parse
    loader.exec_module(new_module)
  File "<frozen importlib._bootstrap_external>", line 728, in exec_module
  File "<frozen importlib._bootstrap>", line 219, in _call_with_frames_removed
  File "/opt/airflow/dags/accidents_etl.py", line 17, in <module>
    'start_date': datetime(2022, 1, 1),
NameError: name 'datetime' is not defined
[2023-01-03T23:46:02.350+0000] {processor.py:755} WARNING - No viable dags retrieved from /opt/airflow/dags/accidents_etl.py
[2023-01-03T23:46:02.371+0000] {processor.py:175} INFO - Processing /opt/airflow/dags/accidents_etl.py took 0.720 seconds
[2023-01-03T23:46:32.564+0000] {processor.py:153} INFO - Started process (PID=9495) to work on /opt/airflow/dags/accidents_etl.py
[2023-01-03T23:46:32.565+0000] {processor.py:743} INFO - Processing file /opt/airflow/dags/accidents_etl.py for tasks to queue
[2023-01-03T23:46:32.567+0000] {logging_mixin.py:137} INFO - [2023-01-03T23:46:32.566+0000] {dagbag.py:538} INFO - Filling up the DagBag from /opt/airflow/dags/accidents_etl.py
[2023-01-03T23:46:33.286+0000] {logging_mixin.py:137} INFO - [2023-01-03T23:46:33.282+0000] {dagbag.py:343} ERROR - Failed to import: /opt/airflow/dags/accidents_etl.py
Traceback (most recent call last):
  File "/home/airflow/.local/lib/python3.7/site-packages/airflow/models/dagbag.py", line 339, in parse
    loader.exec_module(new_module)
  File "<frozen importlib._bootstrap_external>", line 728, in exec_module
  File "<frozen importlib._bootstrap>", line 219, in _call_with_frames_removed
  File "/opt/airflow/dags/accidents_etl.py", line 17, in <module>
    'start_date': datetime(2022, 1, 1),
NameError: name 'datetime' is not defined
[2023-01-03T23:46:33.287+0000] {processor.py:755} WARNING - No viable dags retrieved from /opt/airflow/dags/accidents_etl.py
[2023-01-03T23:46:33.311+0000] {processor.py:175} INFO - Processing /opt/airflow/dags/accidents_etl.py took 0.750 seconds
[2023-01-03T23:47:03.497+0000] {processor.py:153} INFO - Started process (PID=9573) to work on /opt/airflow/dags/accidents_etl.py
[2023-01-03T23:47:03.498+0000] {processor.py:743} INFO - Processing file /opt/airflow/dags/accidents_etl.py for tasks to queue
[2023-01-03T23:47:03.499+0000] {logging_mixin.py:137} INFO - [2023-01-03T23:47:03.499+0000] {dagbag.py:538} INFO - Filling up the DagBag from /opt/airflow/dags/accidents_etl.py
[2023-01-03T23:47:04.182+0000] {logging_mixin.py:137} INFO - [2023-01-03T23:47:04.179+0000] {dagbag.py:343} ERROR - Failed to import: /opt/airflow/dags/accidents_etl.py
Traceback (most recent call last):
  File "/home/airflow/.local/lib/python3.7/site-packages/airflow/models/dagbag.py", line 339, in parse
    loader.exec_module(new_module)
  File "<frozen importlib._bootstrap_external>", line 728, in exec_module
  File "<frozen importlib._bootstrap>", line 219, in _call_with_frames_removed
  File "/opt/airflow/dags/accidents_etl.py", line 17, in <module>
    'start_date': datetime(2022, 1, 1),
NameError: name 'datetime' is not defined
[2023-01-03T23:47:04.183+0000] {processor.py:755} WARNING - No viable dags retrieved from /opt/airflow/dags/accidents_etl.py
[2023-01-03T23:47:04.203+0000] {processor.py:175} INFO - Processing /opt/airflow/dags/accidents_etl.py took 0.710 seconds
[2023-01-03T23:47:34.378+0000] {processor.py:153} INFO - Started process (PID=9627) to work on /opt/airflow/dags/accidents_etl.py
[2023-01-03T23:47:34.379+0000] {processor.py:743} INFO - Processing file /opt/airflow/dags/accidents_etl.py for tasks to queue
[2023-01-03T23:47:34.380+0000] {logging_mixin.py:137} INFO - [2023-01-03T23:47:34.380+0000] {dagbag.py:538} INFO - Filling up the DagBag from /opt/airflow/dags/accidents_etl.py
[2023-01-03T23:47:35.120+0000] {logging_mixin.py:137} INFO - [2023-01-03T23:47:35.117+0000] {dagbag.py:343} ERROR - Failed to import: /opt/airflow/dags/accidents_etl.py
Traceback (most recent call last):
  File "/home/airflow/.local/lib/python3.7/site-packages/airflow/models/dagbag.py", line 339, in parse
    loader.exec_module(new_module)
  File "<frozen importlib._bootstrap_external>", line 728, in exec_module
  File "<frozen importlib._bootstrap>", line 219, in _call_with_frames_removed
  File "/opt/airflow/dags/accidents_etl.py", line 17, in <module>
    'start_date': datetime(2022, 1, 1),
NameError: name 'datetime' is not defined
[2023-01-03T23:47:35.121+0000] {processor.py:755} WARNING - No viable dags retrieved from /opt/airflow/dags/accidents_etl.py
[2023-01-03T23:47:35.145+0000] {processor.py:175} INFO - Processing /opt/airflow/dags/accidents_etl.py took 0.771 seconds
[2023-01-03T23:48:05.332+0000] {processor.py:153} INFO - Started process (PID=9705) to work on /opt/airflow/dags/accidents_etl.py
[2023-01-03T23:48:05.334+0000] {processor.py:743} INFO - Processing file /opt/airflow/dags/accidents_etl.py for tasks to queue
[2023-01-03T23:48:05.334+0000] {logging_mixin.py:137} INFO - [2023-01-03T23:48:05.334+0000] {dagbag.py:538} INFO - Filling up the DagBag from /opt/airflow/dags/accidents_etl.py
[2023-01-03T23:48:06.111+0000] {logging_mixin.py:137} INFO - [2023-01-03T23:48:06.106+0000] {dagbag.py:343} ERROR - Failed to import: /opt/airflow/dags/accidents_etl.py
Traceback (most recent call last):
  File "/home/airflow/.local/lib/python3.7/site-packages/airflow/models/dagbag.py", line 339, in parse
    loader.exec_module(new_module)
  File "<frozen importlib._bootstrap_external>", line 728, in exec_module
  File "<frozen importlib._bootstrap>", line 219, in _call_with_frames_removed
  File "/opt/airflow/dags/accidents_etl.py", line 17, in <module>
    'start_date': datetime(2022, 1, 1),
NameError: name 'datetime' is not defined
[2023-01-03T23:48:06.111+0000] {processor.py:755} WARNING - No viable dags retrieved from /opt/airflow/dags/accidents_etl.py
[2023-01-03T23:48:06.127+0000] {processor.py:175} INFO - Processing /opt/airflow/dags/accidents_etl.py took 0.798 seconds
[2023-01-03T23:48:36.322+0000] {processor.py:153} INFO - Started process (PID=9759) to work on /opt/airflow/dags/accidents_etl.py
[2023-01-03T23:48:36.323+0000] {processor.py:743} INFO - Processing file /opt/airflow/dags/accidents_etl.py for tasks to queue
[2023-01-03T23:48:36.324+0000] {logging_mixin.py:137} INFO - [2023-01-03T23:48:36.324+0000] {dagbag.py:538} INFO - Filling up the DagBag from /opt/airflow/dags/accidents_etl.py
[2023-01-03T23:48:37.035+0000] {logging_mixin.py:137} INFO - [2023-01-03T23:48:37.030+0000] {dagbag.py:343} ERROR - Failed to import: /opt/airflow/dags/accidents_etl.py
Traceback (most recent call last):
  File "/home/airflow/.local/lib/python3.7/site-packages/airflow/models/dagbag.py", line 339, in parse
    loader.exec_module(new_module)
  File "<frozen importlib._bootstrap_external>", line 728, in exec_module
  File "<frozen importlib._bootstrap>", line 219, in _call_with_frames_removed
  File "/opt/airflow/dags/accidents_etl.py", line 17, in <module>
    'start_date': datetime(2022, 1, 1),
NameError: name 'datetime' is not defined
[2023-01-03T23:48:37.036+0000] {processor.py:755} WARNING - No viable dags retrieved from /opt/airflow/dags/accidents_etl.py
[2023-01-03T23:48:37.056+0000] {processor.py:175} INFO - Processing /opt/airflow/dags/accidents_etl.py took 0.739 seconds
[2023-01-03T23:49:07.237+0000] {processor.py:153} INFO - Started process (PID=9837) to work on /opt/airflow/dags/accidents_etl.py
[2023-01-03T23:49:07.239+0000] {processor.py:743} INFO - Processing file /opt/airflow/dags/accidents_etl.py for tasks to queue
[2023-01-03T23:49:07.240+0000] {logging_mixin.py:137} INFO - [2023-01-03T23:49:07.240+0000] {dagbag.py:538} INFO - Filling up the DagBag from /opt/airflow/dags/accidents_etl.py
[2023-01-03T23:49:08.058+0000] {logging_mixin.py:137} INFO - [2023-01-03T23:49:08.054+0000] {dagbag.py:343} ERROR - Failed to import: /opt/airflow/dags/accidents_etl.py
Traceback (most recent call last):
  File "/home/airflow/.local/lib/python3.7/site-packages/airflow/models/dagbag.py", line 339, in parse
    loader.exec_module(new_module)
  File "<frozen importlib._bootstrap_external>", line 728, in exec_module
  File "<frozen importlib._bootstrap>", line 219, in _call_with_frames_removed
  File "/opt/airflow/dags/accidents_etl.py", line 17, in <module>
    'start_date': datetime(2022, 1, 1),
NameError: name 'datetime' is not defined
[2023-01-03T23:49:08.059+0000] {processor.py:755} WARNING - No viable dags retrieved from /opt/airflow/dags/accidents_etl.py
[2023-01-03T23:49:08.084+0000] {processor.py:175} INFO - Processing /opt/airflow/dags/accidents_etl.py took 0.852 seconds
[2023-01-03T23:49:38.262+0000] {processor.py:153} INFO - Started process (PID=9891) to work on /opt/airflow/dags/accidents_etl.py
[2023-01-03T23:49:38.263+0000] {processor.py:743} INFO - Processing file /opt/airflow/dags/accidents_etl.py for tasks to queue
[2023-01-03T23:49:38.264+0000] {logging_mixin.py:137} INFO - [2023-01-03T23:49:38.264+0000] {dagbag.py:538} INFO - Filling up the DagBag from /opt/airflow/dags/accidents_etl.py
[2023-01-03T23:49:38.952+0000] {logging_mixin.py:137} INFO - [2023-01-03T23:49:38.949+0000] {dagbag.py:343} ERROR - Failed to import: /opt/airflow/dags/accidents_etl.py
Traceback (most recent call last):
  File "/home/airflow/.local/lib/python3.7/site-packages/airflow/models/dagbag.py", line 339, in parse
    loader.exec_module(new_module)
  File "<frozen importlib._bootstrap_external>", line 728, in exec_module
  File "<frozen importlib._bootstrap>", line 219, in _call_with_frames_removed
  File "/opt/airflow/dags/accidents_etl.py", line 17, in <module>
    'start_date': datetime(2022, 1, 1),
NameError: name 'datetime' is not defined
[2023-01-03T23:49:38.953+0000] {processor.py:755} WARNING - No viable dags retrieved from /opt/airflow/dags/accidents_etl.py
[2023-01-03T23:49:38.971+0000] {processor.py:175} INFO - Processing /opt/airflow/dags/accidents_etl.py took 0.712 seconds
[2023-01-03T23:50:09.141+0000] {processor.py:153} INFO - Started process (PID=9969) to work on /opt/airflow/dags/accidents_etl.py
[2023-01-03T23:50:09.142+0000] {processor.py:743} INFO - Processing file /opt/airflow/dags/accidents_etl.py for tasks to queue
[2023-01-03T23:50:09.143+0000] {logging_mixin.py:137} INFO - [2023-01-03T23:50:09.143+0000] {dagbag.py:538} INFO - Filling up the DagBag from /opt/airflow/dags/accidents_etl.py
[2023-01-03T23:50:09.958+0000] {logging_mixin.py:137} INFO - [2023-01-03T23:50:09.954+0000] {dagbag.py:343} ERROR - Failed to import: /opt/airflow/dags/accidents_etl.py
Traceback (most recent call last):
  File "/home/airflow/.local/lib/python3.7/site-packages/airflow/models/dagbag.py", line 339, in parse
    loader.exec_module(new_module)
  File "<frozen importlib._bootstrap_external>", line 728, in exec_module
  File "<frozen importlib._bootstrap>", line 219, in _call_with_frames_removed
  File "/opt/airflow/dags/accidents_etl.py", line 17, in <module>
    'start_date': datetime(2022, 1, 1),
NameError: name 'datetime' is not defined
[2023-01-03T23:50:09.959+0000] {processor.py:755} WARNING - No viable dags retrieved from /opt/airflow/dags/accidents_etl.py
[2023-01-03T23:50:09.984+0000] {processor.py:175} INFO - Processing /opt/airflow/dags/accidents_etl.py took 0.847 seconds
[2023-01-03T23:50:40.122+0000] {processor.py:153} INFO - Started process (PID=10023) to work on /opt/airflow/dags/accidents_etl.py
[2023-01-03T23:50:40.124+0000] {processor.py:743} INFO - Processing file /opt/airflow/dags/accidents_etl.py for tasks to queue
[2023-01-03T23:50:40.125+0000] {logging_mixin.py:137} INFO - [2023-01-03T23:50:40.125+0000] {dagbag.py:538} INFO - Filling up the DagBag from /opt/airflow/dags/accidents_etl.py
[2023-01-03T23:50:40.829+0000] {logging_mixin.py:137} INFO - [2023-01-03T23:50:40.825+0000] {dagbag.py:343} ERROR - Failed to import: /opt/airflow/dags/accidents_etl.py
Traceback (most recent call last):
  File "/home/airflow/.local/lib/python3.7/site-packages/airflow/models/dagbag.py", line 339, in parse
    loader.exec_module(new_module)
  File "<frozen importlib._bootstrap_external>", line 728, in exec_module
  File "<frozen importlib._bootstrap>", line 219, in _call_with_frames_removed
  File "/opt/airflow/dags/accidents_etl.py", line 17, in <module>
    'start_date': datetime(2022, 1, 1),
NameError: name 'datetime' is not defined
[2023-01-03T23:50:40.830+0000] {processor.py:755} WARNING - No viable dags retrieved from /opt/airflow/dags/accidents_etl.py
[2023-01-03T23:50:40.851+0000] {processor.py:175} INFO - Processing /opt/airflow/dags/accidents_etl.py took 0.735 seconds
[2023-01-03T23:51:11.055+0000] {processor.py:153} INFO - Started process (PID=10086) to work on /opt/airflow/dags/accidents_etl.py
[2023-01-03T23:51:11.056+0000] {processor.py:743} INFO - Processing file /opt/airflow/dags/accidents_etl.py for tasks to queue
[2023-01-03T23:51:11.057+0000] {logging_mixin.py:137} INFO - [2023-01-03T23:51:11.057+0000] {dagbag.py:538} INFO - Filling up the DagBag from /opt/airflow/dags/accidents_etl.py
[2023-01-03T23:51:11.885+0000] {logging_mixin.py:137} INFO - [2023-01-03T23:51:11.881+0000] {dagbag.py:343} ERROR - Failed to import: /opt/airflow/dags/accidents_etl.py
Traceback (most recent call last):
  File "/home/airflow/.local/lib/python3.7/site-packages/airflow/models/dagbag.py", line 339, in parse
    loader.exec_module(new_module)
  File "<frozen importlib._bootstrap_external>", line 728, in exec_module
  File "<frozen importlib._bootstrap>", line 219, in _call_with_frames_removed
  File "/opt/airflow/dags/accidents_etl.py", line 17, in <module>
    'start_date': datetime(2022, 1, 1),
NameError: name 'datetime' is not defined
[2023-01-03T23:51:11.886+0000] {processor.py:755} WARNING - No viable dags retrieved from /opt/airflow/dags/accidents_etl.py
[2023-01-03T23:51:11.907+0000] {processor.py:175} INFO - Processing /opt/airflow/dags/accidents_etl.py took 0.856 seconds
[2023-01-03T23:51:42.104+0000] {processor.py:153} INFO - Started process (PID=10155) to work on /opt/airflow/dags/accidents_etl.py
[2023-01-03T23:51:42.106+0000] {processor.py:743} INFO - Processing file /opt/airflow/dags/accidents_etl.py for tasks to queue
[2023-01-03T23:51:42.107+0000] {logging_mixin.py:137} INFO - [2023-01-03T23:51:42.107+0000] {dagbag.py:538} INFO - Filling up the DagBag from /opt/airflow/dags/accidents_etl.py
[2023-01-03T23:51:42.786+0000] {logging_mixin.py:137} INFO - [2023-01-03T23:51:42.781+0000] {dagbag.py:343} ERROR - Failed to import: /opt/airflow/dags/accidents_etl.py
Traceback (most recent call last):
  File "/home/airflow/.local/lib/python3.7/site-packages/airflow/models/dagbag.py", line 339, in parse
    loader.exec_module(new_module)
  File "<frozen importlib._bootstrap_external>", line 728, in exec_module
  File "<frozen importlib._bootstrap>", line 219, in _call_with_frames_removed
  File "/opt/airflow/dags/accidents_etl.py", line 17, in <module>
    'start_date': datetime(2022, 1, 1),
NameError: name 'datetime' is not defined
[2023-01-03T23:51:42.787+0000] {processor.py:755} WARNING - No viable dags retrieved from /opt/airflow/dags/accidents_etl.py
[2023-01-03T23:51:42.807+0000] {processor.py:175} INFO - Processing /opt/airflow/dags/accidents_etl.py took 0.708 seconds
[2023-01-03T23:52:12.998+0000] {processor.py:153} INFO - Started process (PID=10209) to work on /opt/airflow/dags/accidents_etl.py
[2023-01-03T23:52:12.998+0000] {processor.py:743} INFO - Processing file /opt/airflow/dags/accidents_etl.py for tasks to queue
[2023-01-03T23:52:12.999+0000] {logging_mixin.py:137} INFO - [2023-01-03T23:52:12.999+0000] {dagbag.py:538} INFO - Filling up the DagBag from /opt/airflow/dags/accidents_etl.py
[2023-01-03T23:52:13.787+0000] {logging_mixin.py:137} INFO - [2023-01-03T23:52:13.783+0000] {dagbag.py:343} ERROR - Failed to import: /opt/airflow/dags/accidents_etl.py
Traceback (most recent call last):
  File "/home/airflow/.local/lib/python3.7/site-packages/airflow/models/dagbag.py", line 339, in parse
    loader.exec_module(new_module)
  File "<frozen importlib._bootstrap_external>", line 728, in exec_module
  File "<frozen importlib._bootstrap>", line 219, in _call_with_frames_removed
  File "/opt/airflow/dags/accidents_etl.py", line 17, in <module>
    'start_date': datetime(2022, 1, 1),
NameError: name 'datetime' is not defined
[2023-01-03T23:52:13.789+0000] {processor.py:755} WARNING - No viable dags retrieved from /opt/airflow/dags/accidents_etl.py
[2023-01-03T23:52:13.813+0000] {processor.py:175} INFO - Processing /opt/airflow/dags/accidents_etl.py took 0.819 seconds
[2023-01-03T23:52:43.996+0000] {processor.py:153} INFO - Started process (PID=10287) to work on /opt/airflow/dags/accidents_etl.py
[2023-01-03T23:52:43.997+0000] {processor.py:743} INFO - Processing file /opt/airflow/dags/accidents_etl.py for tasks to queue
[2023-01-03T23:52:43.998+0000] {logging_mixin.py:137} INFO - [2023-01-03T23:52:43.997+0000] {dagbag.py:538} INFO - Filling up the DagBag from /opt/airflow/dags/accidents_etl.py
[2023-01-03T23:52:44.705+0000] {logging_mixin.py:137} INFO - [2023-01-03T23:52:44.700+0000] {dagbag.py:343} ERROR - Failed to import: /opt/airflow/dags/accidents_etl.py
Traceback (most recent call last):
  File "/home/airflow/.local/lib/python3.7/site-packages/airflow/models/dagbag.py", line 339, in parse
    loader.exec_module(new_module)
  File "<frozen importlib._bootstrap_external>", line 728, in exec_module
  File "<frozen importlib._bootstrap>", line 219, in _call_with_frames_removed
  File "/opt/airflow/dags/accidents_etl.py", line 17, in <module>
    'start_date': datetime(2022, 1, 1),
NameError: name 'datetime' is not defined
[2023-01-03T23:52:44.706+0000] {processor.py:755} WARNING - No viable dags retrieved from /opt/airflow/dags/accidents_etl.py
[2023-01-03T23:52:44.728+0000] {processor.py:175} INFO - Processing /opt/airflow/dags/accidents_etl.py took 0.735 seconds
[2023-01-03T23:53:14.926+0000] {processor.py:153} INFO - Started process (PID=10341) to work on /opt/airflow/dags/accidents_etl.py
[2023-01-03T23:53:14.927+0000] {processor.py:743} INFO - Processing file /opt/airflow/dags/accidents_etl.py for tasks to queue
[2023-01-03T23:53:14.928+0000] {logging_mixin.py:137} INFO - [2023-01-03T23:53:14.928+0000] {dagbag.py:538} INFO - Filling up the DagBag from /opt/airflow/dags/accidents_etl.py
[2023-01-03T23:53:15.644+0000] {logging_mixin.py:137} INFO - [2023-01-03T23:53:15.639+0000] {dagbag.py:343} ERROR - Failed to import: /opt/airflow/dags/accidents_etl.py
Traceback (most recent call last):
  File "/home/airflow/.local/lib/python3.7/site-packages/airflow/models/dagbag.py", line 339, in parse
    loader.exec_module(new_module)
  File "<frozen importlib._bootstrap_external>", line 728, in exec_module
  File "<frozen importlib._bootstrap>", line 219, in _call_with_frames_removed
  File "/opt/airflow/dags/accidents_etl.py", line 17, in <module>
    'start_date': datetime(2022, 1, 1),
NameError: name 'datetime' is not defined
[2023-01-03T23:53:15.645+0000] {processor.py:755} WARNING - No viable dags retrieved from /opt/airflow/dags/accidents_etl.py
[2023-01-03T23:53:15.663+0000] {processor.py:175} INFO - Processing /opt/airflow/dags/accidents_etl.py took 0.740 seconds
[2023-01-03T23:53:45.883+0000] {processor.py:153} INFO - Started process (PID=10419) to work on /opt/airflow/dags/accidents_etl.py
[2023-01-03T23:53:45.885+0000] {processor.py:743} INFO - Processing file /opt/airflow/dags/accidents_etl.py for tasks to queue
[2023-01-03T23:53:45.885+0000] {logging_mixin.py:137} INFO - [2023-01-03T23:53:45.885+0000] {dagbag.py:538} INFO - Filling up the DagBag from /opt/airflow/dags/accidents_etl.py
[2023-01-03T23:53:46.643+0000] {logging_mixin.py:137} INFO - [2023-01-03T23:53:46.636+0000] {dagbag.py:343} ERROR - Failed to import: /opt/airflow/dags/accidents_etl.py
Traceback (most recent call last):
  File "/home/airflow/.local/lib/python3.7/site-packages/airflow/models/dagbag.py", line 339, in parse
    loader.exec_module(new_module)
  File "<frozen importlib._bootstrap_external>", line 728, in exec_module
  File "<frozen importlib._bootstrap>", line 219, in _call_with_frames_removed
  File "/opt/airflow/dags/accidents_etl.py", line 17, in <module>
    'start_date': datetime(2022, 1, 1),
NameError: name 'datetime' is not defined
[2023-01-03T23:53:46.644+0000] {processor.py:755} WARNING - No viable dags retrieved from /opt/airflow/dags/accidents_etl.py
[2023-01-03T23:53:46.664+0000] {processor.py:175} INFO - Processing /opt/airflow/dags/accidents_etl.py took 0.784 seconds
[2023-01-03T23:54:16.849+0000] {processor.py:153} INFO - Started process (PID=10473) to work on /opt/airflow/dags/accidents_etl.py
[2023-01-03T23:54:16.850+0000] {processor.py:743} INFO - Processing file /opt/airflow/dags/accidents_etl.py for tasks to queue
[2023-01-03T23:54:16.851+0000] {logging_mixin.py:137} INFO - [2023-01-03T23:54:16.851+0000] {dagbag.py:538} INFO - Filling up the DagBag from /opt/airflow/dags/accidents_etl.py
[2023-01-03T23:54:17.531+0000] {logging_mixin.py:137} INFO - [2023-01-03T23:54:17.528+0000] {dagbag.py:343} ERROR - Failed to import: /opt/airflow/dags/accidents_etl.py
Traceback (most recent call last):
  File "/home/airflow/.local/lib/python3.7/site-packages/airflow/models/dagbag.py", line 339, in parse
    loader.exec_module(new_module)
  File "<frozen importlib._bootstrap_external>", line 728, in exec_module
  File "<frozen importlib._bootstrap>", line 219, in _call_with_frames_removed
  File "/opt/airflow/dags/accidents_etl.py", line 17, in <module>
    'start_date': datetime(2022, 1, 1),
NameError: name 'datetime' is not defined
[2023-01-03T23:54:17.532+0000] {processor.py:755} WARNING - No viable dags retrieved from /opt/airflow/dags/accidents_etl.py
[2023-01-03T23:54:17.556+0000] {processor.py:175} INFO - Processing /opt/airflow/dags/accidents_etl.py took 0.712 seconds
[2023-01-03T23:54:47.620+0000] {processor.py:153} INFO - Started process (PID=10551) to work on /opt/airflow/dags/accidents_etl.py
[2023-01-03T23:54:47.622+0000] {processor.py:743} INFO - Processing file /opt/airflow/dags/accidents_etl.py for tasks to queue
[2023-01-03T23:54:47.623+0000] {logging_mixin.py:137} INFO - [2023-01-03T23:54:47.623+0000] {dagbag.py:538} INFO - Filling up the DagBag from /opt/airflow/dags/accidents_etl.py
[2023-01-03T23:54:48.315+0000] {logging_mixin.py:137} INFO - [2023-01-03T23:54:48.311+0000] {dagbag.py:343} ERROR - Failed to import: /opt/airflow/dags/accidents_etl.py
Traceback (most recent call last):
  File "/home/airflow/.local/lib/python3.7/site-packages/airflow/models/dagbag.py", line 339, in parse
    loader.exec_module(new_module)
  File "<frozen importlib._bootstrap_external>", line 728, in exec_module
  File "<frozen importlib._bootstrap>", line 219, in _call_with_frames_removed
  File "/opt/airflow/dags/accidents_etl.py", line 17, in <module>
    'start_date': datetime(2022, 1, 1),
NameError: name 'datetime' is not defined
[2023-01-03T23:54:48.317+0000] {processor.py:755} WARNING - No viable dags retrieved from /opt/airflow/dags/accidents_etl.py
[2023-01-03T23:54:48.337+0000] {processor.py:175} INFO - Processing /opt/airflow/dags/accidents_etl.py took 0.720 seconds
[2023-01-03T23:55:18.527+0000] {processor.py:153} INFO - Started process (PID=10605) to work on /opt/airflow/dags/accidents_etl.py
[2023-01-03T23:55:18.528+0000] {processor.py:743} INFO - Processing file /opt/airflow/dags/accidents_etl.py for tasks to queue
[2023-01-03T23:55:18.529+0000] {logging_mixin.py:137} INFO - [2023-01-03T23:55:18.529+0000] {dagbag.py:538} INFO - Filling up the DagBag from /opt/airflow/dags/accidents_etl.py
[2023-01-03T23:55:19.211+0000] {logging_mixin.py:137} INFO - [2023-01-03T23:55:19.208+0000] {dagbag.py:343} ERROR - Failed to import: /opt/airflow/dags/accidents_etl.py
Traceback (most recent call last):
  File "/home/airflow/.local/lib/python3.7/site-packages/airflow/models/dagbag.py", line 339, in parse
    loader.exec_module(new_module)
  File "<frozen importlib._bootstrap_external>", line 728, in exec_module
  File "<frozen importlib._bootstrap>", line 219, in _call_with_frames_removed
  File "/opt/airflow/dags/accidents_etl.py", line 17, in <module>
    'start_date': datetime(2022, 1, 1),
NameError: name 'datetime' is not defined
[2023-01-03T23:55:19.212+0000] {processor.py:755} WARNING - No viable dags retrieved from /opt/airflow/dags/accidents_etl.py
[2023-01-03T23:55:19.232+0000] {processor.py:175} INFO - Processing /opt/airflow/dags/accidents_etl.py took 0.709 seconds
[2023-01-03T23:55:49.407+0000] {processor.py:153} INFO - Started process (PID=10684) to work on /opt/airflow/dags/accidents_etl.py
[2023-01-03T23:55:49.408+0000] {processor.py:743} INFO - Processing file /opt/airflow/dags/accidents_etl.py for tasks to queue
[2023-01-03T23:55:49.409+0000] {logging_mixin.py:137} INFO - [2023-01-03T23:55:49.409+0000] {dagbag.py:538} INFO - Filling up the DagBag from /opt/airflow/dags/accidents_etl.py
[2023-01-03T23:55:50.075+0000] {logging_mixin.py:137} INFO - [2023-01-03T23:55:50.071+0000] {dagbag.py:343} ERROR - Failed to import: /opt/airflow/dags/accidents_etl.py
Traceback (most recent call last):
  File "/home/airflow/.local/lib/python3.7/site-packages/airflow/models/dagbag.py", line 339, in parse
    loader.exec_module(new_module)
  File "<frozen importlib._bootstrap_external>", line 728, in exec_module
  File "<frozen importlib._bootstrap>", line 219, in _call_with_frames_removed
  File "/opt/airflow/dags/accidents_etl.py", line 17, in <module>
    'start_date': datetime(2022, 1, 1),
NameError: name 'datetime' is not defined
[2023-01-03T23:55:50.076+0000] {processor.py:755} WARNING - No viable dags retrieved from /opt/airflow/dags/accidents_etl.py
[2023-01-03T23:55:50.095+0000] {processor.py:175} INFO - Processing /opt/airflow/dags/accidents_etl.py took 0.691 seconds
[2023-01-03T23:56:20.182+0000] {processor.py:153} INFO - Started process (PID=10738) to work on /opt/airflow/dags/accidents_etl.py
[2023-01-03T23:56:20.191+0000] {processor.py:743} INFO - Processing file /opt/airflow/dags/accidents_etl.py for tasks to queue
[2023-01-03T23:56:20.193+0000] {logging_mixin.py:137} INFO - [2023-01-03T23:56:20.193+0000] {dagbag.py:538} INFO - Filling up the DagBag from /opt/airflow/dags/accidents_etl.py
[2023-01-03T23:56:20.853+0000] {logging_mixin.py:137} INFO - [2023-01-03T23:56:20.851+0000] {dagbag.py:343} ERROR - Failed to import: /opt/airflow/dags/accidents_etl.py
Traceback (most recent call last):
  File "/home/airflow/.local/lib/python3.7/site-packages/airflow/models/dagbag.py", line 339, in parse
    loader.exec_module(new_module)
  File "<frozen importlib._bootstrap_external>", line 728, in exec_module
  File "<frozen importlib._bootstrap>", line 219, in _call_with_frames_removed
  File "/opt/airflow/dags/accidents_etl.py", line 17, in <module>
    'start_date': datetime(2022, 1, 1),
NameError: name 'datetime' is not defined
[2023-01-03T23:56:20.854+0000] {processor.py:755} WARNING - No viable dags retrieved from /opt/airflow/dags/accidents_etl.py
[2023-01-03T23:56:20.882+0000] {processor.py:175} INFO - Processing /opt/airflow/dags/accidents_etl.py took 0.703 seconds
[2023-01-03T23:56:51.077+0000] {processor.py:153} INFO - Started process (PID=10816) to work on /opt/airflow/dags/accidents_etl.py
[2023-01-03T23:56:51.078+0000] {processor.py:743} INFO - Processing file /opt/airflow/dags/accidents_etl.py for tasks to queue
[2023-01-03T23:56:51.079+0000] {logging_mixin.py:137} INFO - [2023-01-03T23:56:51.079+0000] {dagbag.py:538} INFO - Filling up the DagBag from /opt/airflow/dags/accidents_etl.py
[2023-01-03T23:56:51.846+0000] {logging_mixin.py:137} INFO - [2023-01-03T23:56:51.842+0000] {dagbag.py:343} ERROR - Failed to import: /opt/airflow/dags/accidents_etl.py
Traceback (most recent call last):
  File "/home/airflow/.local/lib/python3.7/site-packages/airflow/models/dagbag.py", line 339, in parse
    loader.exec_module(new_module)
  File "<frozen importlib._bootstrap_external>", line 728, in exec_module
  File "<frozen importlib._bootstrap>", line 219, in _call_with_frames_removed
  File "/opt/airflow/dags/accidents_etl.py", line 17, in <module>
    'start_date': datetime(2022, 1, 1),
NameError: name 'datetime' is not defined
[2023-01-03T23:56:51.847+0000] {processor.py:755} WARNING - No viable dags retrieved from /opt/airflow/dags/accidents_etl.py
[2023-01-03T23:56:51.880+0000] {processor.py:175} INFO - Processing /opt/airflow/dags/accidents_etl.py took 0.807 seconds
[2023-01-03T23:57:22.117+0000] {processor.py:153} INFO - Started process (PID=10870) to work on /opt/airflow/dags/accidents_etl.py
[2023-01-03T23:57:22.118+0000] {processor.py:743} INFO - Processing file /opt/airflow/dags/accidents_etl.py for tasks to queue
[2023-01-03T23:57:22.119+0000] {logging_mixin.py:137} INFO - [2023-01-03T23:57:22.118+0000] {dagbag.py:538} INFO - Filling up the DagBag from /opt/airflow/dags/accidents_etl.py
[2023-01-03T23:57:22.800+0000] {logging_mixin.py:137} INFO - [2023-01-03T23:57:22.796+0000] {dagbag.py:343} ERROR - Failed to import: /opt/airflow/dags/accidents_etl.py
Traceback (most recent call last):
  File "/home/airflow/.local/lib/python3.7/site-packages/airflow/models/dagbag.py", line 339, in parse
    loader.exec_module(new_module)
  File "<frozen importlib._bootstrap_external>", line 728, in exec_module
  File "<frozen importlib._bootstrap>", line 219, in _call_with_frames_removed
  File "/opt/airflow/dags/accidents_etl.py", line 17, in <module>
    'start_date': datetime(2022, 1, 1),
NameError: name 'datetime' is not defined
[2023-01-03T23:57:22.802+0000] {processor.py:755} WARNING - No viable dags retrieved from /opt/airflow/dags/accidents_etl.py
[2023-01-03T23:57:22.825+0000] {processor.py:175} INFO - Processing /opt/airflow/dags/accidents_etl.py took 0.712 seconds
[2023-01-03T23:57:53.003+0000] {processor.py:153} INFO - Started process (PID=10949) to work on /opt/airflow/dags/accidents_etl.py
[2023-01-03T23:57:53.004+0000] {processor.py:743} INFO - Processing file /opt/airflow/dags/accidents_etl.py for tasks to queue
[2023-01-03T23:57:53.005+0000] {logging_mixin.py:137} INFO - [2023-01-03T23:57:53.005+0000] {dagbag.py:538} INFO - Filling up the DagBag from /opt/airflow/dags/accidents_etl.py
[2023-01-03T23:57:53.753+0000] {logging_mixin.py:137} INFO - [2023-01-03T23:57:53.750+0000] {dagbag.py:343} ERROR - Failed to import: /opt/airflow/dags/accidents_etl.py
Traceback (most recent call last):
  File "/home/airflow/.local/lib/python3.7/site-packages/airflow/models/dagbag.py", line 339, in parse
    loader.exec_module(new_module)
  File "<frozen importlib._bootstrap_external>", line 728, in exec_module
  File "<frozen importlib._bootstrap>", line 219, in _call_with_frames_removed
  File "/opt/airflow/dags/accidents_etl.py", line 17, in <module>
    'start_date': datetime(2022, 1, 1),
NameError: name 'datetime' is not defined
[2023-01-03T23:57:53.753+0000] {processor.py:755} WARNING - No viable dags retrieved from /opt/airflow/dags/accidents_etl.py
[2023-01-03T23:57:53.770+0000] {processor.py:175} INFO - Processing /opt/airflow/dags/accidents_etl.py took 0.772 seconds
[2023-01-03T23:58:23.910+0000] {processor.py:153} INFO - Started process (PID=11003) to work on /opt/airflow/dags/accidents_etl.py
[2023-01-03T23:58:23.912+0000] {processor.py:743} INFO - Processing file /opt/airflow/dags/accidents_etl.py for tasks to queue
[2023-01-03T23:58:23.912+0000] {logging_mixin.py:137} INFO - [2023-01-03T23:58:23.912+0000] {dagbag.py:538} INFO - Filling up the DagBag from /opt/airflow/dags/accidents_etl.py
[2023-01-03T23:58:24.617+0000] {logging_mixin.py:137} INFO - [2023-01-03T23:58:24.613+0000] {dagbag.py:343} ERROR - Failed to import: /opt/airflow/dags/accidents_etl.py
Traceback (most recent call last):
  File "/home/airflow/.local/lib/python3.7/site-packages/airflow/models/dagbag.py", line 339, in parse
    loader.exec_module(new_module)
  File "<frozen importlib._bootstrap_external>", line 728, in exec_module
  File "<frozen importlib._bootstrap>", line 219, in _call_with_frames_removed
  File "/opt/airflow/dags/accidents_etl.py", line 17, in <module>
    'start_date': datetime(2022, 1, 1),
NameError: name 'datetime' is not defined
[2023-01-03T23:58:24.618+0000] {processor.py:755} WARNING - No viable dags retrieved from /opt/airflow/dags/accidents_etl.py
[2023-01-03T23:58:24.640+0000] {processor.py:175} INFO - Processing /opt/airflow/dags/accidents_etl.py took 0.734 seconds
[2023-01-03T23:58:54.842+0000] {processor.py:153} INFO - Started process (PID=11081) to work on /opt/airflow/dags/accidents_etl.py
[2023-01-03T23:58:54.843+0000] {processor.py:743} INFO - Processing file /opt/airflow/dags/accidents_etl.py for tasks to queue
[2023-01-03T23:58:54.844+0000] {logging_mixin.py:137} INFO - [2023-01-03T23:58:54.844+0000] {dagbag.py:538} INFO - Filling up the DagBag from /opt/airflow/dags/accidents_etl.py
[2023-01-03T23:58:55.559+0000] {logging_mixin.py:137} INFO - [2023-01-03T23:58:55.556+0000] {dagbag.py:343} ERROR - Failed to import: /opt/airflow/dags/accidents_etl.py
Traceback (most recent call last):
  File "/home/airflow/.local/lib/python3.7/site-packages/airflow/models/dagbag.py", line 339, in parse
    loader.exec_module(new_module)
  File "<frozen importlib._bootstrap_external>", line 728, in exec_module
  File "<frozen importlib._bootstrap>", line 219, in _call_with_frames_removed
  File "/opt/airflow/dags/accidents_etl.py", line 17, in <module>
    'start_date': datetime(2022, 1, 1),
NameError: name 'datetime' is not defined
[2023-01-03T23:58:55.560+0000] {processor.py:755} WARNING - No viable dags retrieved from /opt/airflow/dags/accidents_etl.py
[2023-01-03T23:58:55.580+0000] {processor.py:175} INFO - Processing /opt/airflow/dags/accidents_etl.py took 0.741 seconds
[2023-01-03T23:59:25.779+0000] {processor.py:153} INFO - Started process (PID=11135) to work on /opt/airflow/dags/accidents_etl.py
[2023-01-03T23:59:25.780+0000] {processor.py:743} INFO - Processing file /opt/airflow/dags/accidents_etl.py for tasks to queue
[2023-01-03T23:59:25.781+0000] {logging_mixin.py:137} INFO - [2023-01-03T23:59:25.781+0000] {dagbag.py:538} INFO - Filling up the DagBag from /opt/airflow/dags/accidents_etl.py
[2023-01-03T23:59:26.522+0000] {logging_mixin.py:137} INFO - [2023-01-03T23:59:26.517+0000] {dagbag.py:343} ERROR - Failed to import: /opt/airflow/dags/accidents_etl.py
Traceback (most recent call last):
  File "/home/airflow/.local/lib/python3.7/site-packages/airflow/models/dagbag.py", line 339, in parse
    loader.exec_module(new_module)
  File "<frozen importlib._bootstrap_external>", line 728, in exec_module
  File "<frozen importlib._bootstrap>", line 219, in _call_with_frames_removed
  File "/opt/airflow/dags/accidents_etl.py", line 17, in <module>
    'start_date': datetime(2022, 1, 1),
NameError: name 'datetime' is not defined
[2023-01-03T23:59:26.523+0000] {processor.py:755} WARNING - No viable dags retrieved from /opt/airflow/dags/accidents_etl.py
[2023-01-03T23:59:26.546+0000] {processor.py:175} INFO - Processing /opt/airflow/dags/accidents_etl.py took 0.771 seconds
[2023-01-03T23:59:56.724+0000] {processor.py:153} INFO - Started process (PID=11213) to work on /opt/airflow/dags/accidents_etl.py
[2023-01-03T23:59:56.726+0000] {processor.py:743} INFO - Processing file /opt/airflow/dags/accidents_etl.py for tasks to queue
[2023-01-03T23:59:56.727+0000] {logging_mixin.py:137} INFO - [2023-01-03T23:59:56.726+0000] {dagbag.py:538} INFO - Filling up the DagBag from /opt/airflow/dags/accidents_etl.py
[2023-01-03T23:59:57.475+0000] {logging_mixin.py:137} INFO - [2023-01-03T23:59:57.471+0000] {dagbag.py:343} ERROR - Failed to import: /opt/airflow/dags/accidents_etl.py
Traceback (most recent call last):
  File "/home/airflow/.local/lib/python3.7/site-packages/airflow/models/dagbag.py", line 339, in parse
    loader.exec_module(new_module)
  File "<frozen importlib._bootstrap_external>", line 728, in exec_module
  File "<frozen importlib._bootstrap>", line 219, in _call_with_frames_removed
  File "/opt/airflow/dags/accidents_etl.py", line 17, in <module>
    'start_date': datetime(2022, 1, 1),
NameError: name 'datetime' is not defined
[2023-01-03T23:59:57.477+0000] {processor.py:755} WARNING - No viable dags retrieved from /opt/airflow/dags/accidents_etl.py
[2023-01-03T23:59:57.495+0000] {processor.py:175} INFO - Processing /opt/airflow/dags/accidents_etl.py took 0.774 seconds
