[2023-01-04T11:36:11.758+0000] {taskinstance.py:1087} INFO - Dependencies all met for <TaskInstance: accidents_etl_pipeline.augment_dataset_task scheduled__2023-01-02T00:00:00+00:00 [queued]>
[2023-01-04T11:36:11.769+0000] {taskinstance.py:1087} INFO - Dependencies all met for <TaskInstance: accidents_etl_pipeline.augment_dataset_task scheduled__2023-01-02T00:00:00+00:00 [queued]>
[2023-01-04T11:36:11.770+0000] {taskinstance.py:1283} INFO - 
--------------------------------------------------------------------------------
[2023-01-04T11:36:11.770+0000] {taskinstance.py:1284} INFO - Starting attempt 1 of 2
[2023-01-04T11:36:11.770+0000] {taskinstance.py:1285} INFO - 
--------------------------------------------------------------------------------
[2023-01-04T11:36:11.786+0000] {taskinstance.py:1304} INFO - Executing <Task(PythonOperator): augment_dataset_task> on 2023-01-02 00:00:00+00:00
[2023-01-04T11:36:11.793+0000] {standard_task_runner.py:55} INFO - Started process 496 to run task
[2023-01-04T11:36:11.797+0000] {standard_task_runner.py:82} INFO - Running: ['***', 'tasks', 'run', 'accidents_etl_pipeline', 'augment_dataset_task', 'scheduled__2023-01-02T00:00:00+00:00', '--job-id', '15', '--raw', '--subdir', 'DAGS_FOLDER/accidents_etl.py', '--cfg-path', '/tmp/tmpwr48z8gx']
[2023-01-04T11:36:11.799+0000] {standard_task_runner.py:83} INFO - Job 15: Subtask augment_dataset_task
[2023-01-04T11:36:11.869+0000] {task_command.py:389} INFO - Running <TaskInstance: accidents_etl_pipeline.augment_dataset_task scheduled__2023-01-02T00:00:00+00:00 [running]> on host 523cb283ca0d
[2023-01-04T11:36:11.957+0000] {taskinstance.py:1513} INFO - Exporting the following env vars:
AIRFLOW_CTX_DAG_OWNER=***
AIRFLOW_CTX_DAG_ID=accidents_etl_pipeline
AIRFLOW_CTX_TASK_ID=augment_dataset_task
AIRFLOW_CTX_EXECUTION_DATE=2023-01-02T00:00:00+00:00
AIRFLOW_CTX_TRY_NUMBER=1
AIRFLOW_CTX_DAG_RUN_ID=scheduled__2023-01-02T00:00:00+00:00
[2023-01-04T11:36:12.104+0000] {logging_mixin.py:137} WARNING - /home/***/.local/lib/python3.7/site-packages/pandas/core/frame.py:4913 SettingWithCopyWarning:
A value is trying to be set on a copy of a slice from a DataFrame

See the caveats in the documentation: https://pandas.pydata.org/pandas-docs/stable/user_guide/indexing.html#returning-a-view-versus-a-copy
[2023-01-04T11:36:12.106+0000] {logging_mixin.py:137} WARNING - /opt/***/dags/Milestone3_2.py:64 SettingWithCopyWarning: 
A value is trying to be set on a copy of a slice from a DataFrame.
Try using .loc[row_indexer,col_indexer] = value instead

See the caveats in the documentation: https://pandas.pydata.org/pandas-docs/stable/user_guide/indexing.html#returning-a-view-versus-a-copy
[2023-01-04T11:36:13.917+0000] {logging_mixin.py:137} WARNING - /home/***/.local/lib/python3.7/site-packages/pandas/core/frame.py:5047 SettingWithCopyWarning:
A value is trying to be set on a copy of a slice from a DataFrame

See the caveats in the documentation: https://pandas.pydata.org/pandas-docs/stable/user_guide/indexing.html#returning-a-view-versus-a-copy
[2023-01-04T11:36:41.222+0000] {logging_mixin.py:137} WARNING - /opt/***/dags/Milestone3_2.py:77 SettingWithCopyWarning: 
A value is trying to be set on a copy of a slice from a DataFrame.
Try using .loc[row_indexer,col_indexer] = value instead

See the caveats in the documentation: https://pandas.pydata.org/pandas-docs/stable/user_guide/indexing.html#returning-a-view-versus-a-copy
[2023-01-04T11:36:41.330+0000] {logging_mixin.py:137} WARNING - /home/***/.local/lib/python3.7/site-packages/pandas/core/reshape/merge.py:1208 UserWarning: You are merging on int and float columns where the float values are not equal to their int representation
[2023-01-04T11:36:41.339+0000] {taskinstance.py:1772} ERROR - Task failed with exception
Traceback (most recent call last):
  File "/home/airflow/.local/lib/python3.7/site-packages/airflow/operators/python.py", line 175, in execute
    return_value = self.execute_callable()
  File "/home/airflow/.local/lib/python3.7/site-packages/airflow/operators/python.py", line 192, in execute_callable
    return self.python_callable(*self.op_args, **self.op_kwargs)
  File "/opt/airflow/dags/Milestone3_2.py", line 110, in augment_dataset
    df_accidents_augmented,df_look_up = integrate_sources(cleaned_transformed,df_lsao,df_look_up,df_look_up_lsoa)
  File "/opt/airflow/dags/Milestone3_2.py", line 85, in integrate_sources
    df_accidents_augmented['Education_level'] = pd.cut(df_accidents_augmented['Education_Deprivation_Score'], 4,labels = ['Highly Deprived','Deprived','Educated','Highly Educated'])
  File "/home/airflow/.local/lib/python3.7/site-packages/pandas/core/reshape/tile.py", line 250, in cut
    raise ValueError("Cannot cut empty array")
ValueError: Cannot cut empty array
[2023-01-04T11:36:41.355+0000] {taskinstance.py:1327} INFO - Marking task as UP_FOR_RETRY. dag_id=accidents_etl_pipeline, task_id=augment_dataset_task, execution_date=20230102T000000, start_date=20230104T113611, end_date=20230104T113641
[2023-01-04T11:36:41.366+0000] {standard_task_runner.py:105} ERROR - Failed to execute job 15 for task augment_dataset_task (Cannot cut empty array; 496)
[2023-01-04T11:36:41.431+0000] {local_task_job.py:159} INFO - Task exited with return code 1
[2023-01-04T11:36:41.446+0000] {taskinstance.py:2582} INFO - 0 downstream tasks scheduled from follow-on schedule check
