[2023-01-04T11:41:42.982+0000] {taskinstance.py:1087} INFO - Dependencies all met for <TaskInstance: accidents_etl_pipeline.augment_dataset_task scheduled__2023-01-02T00:00:00+00:00 [queued]>
[2023-01-04T11:41:42.992+0000] {taskinstance.py:1087} INFO - Dependencies all met for <TaskInstance: accidents_etl_pipeline.augment_dataset_task scheduled__2023-01-02T00:00:00+00:00 [queued]>
[2023-01-04T11:41:42.993+0000] {taskinstance.py:1283} INFO - 
--------------------------------------------------------------------------------
[2023-01-04T11:41:42.993+0000] {taskinstance.py:1284} INFO - Starting attempt 2 of 2
[2023-01-04T11:41:42.994+0000] {taskinstance.py:1285} INFO - 
--------------------------------------------------------------------------------
[2023-01-04T11:41:43.006+0000] {taskinstance.py:1304} INFO - Executing <Task(PythonOperator): augment_dataset_task> on 2023-01-02 00:00:00+00:00
[2023-01-04T11:41:43.013+0000] {standard_task_runner.py:55} INFO - Started process 387 to run task
[2023-01-04T11:41:43.016+0000] {standard_task_runner.py:82} INFO - Running: ['***', 'tasks', 'run', 'accidents_etl_pipeline', 'augment_dataset_task', 'scheduled__2023-01-02T00:00:00+00:00', '--job-id', '19', '--raw', '--subdir', 'DAGS_FOLDER/accidents_etl.py', '--cfg-path', '/tmp/tmp8ykp48z6']
[2023-01-04T11:41:43.018+0000] {standard_task_runner.py:83} INFO - Job 19: Subtask augment_dataset_task
[2023-01-04T11:41:43.085+0000] {task_command.py:389} INFO - Running <TaskInstance: accidents_etl_pipeline.augment_dataset_task scheduled__2023-01-02T00:00:00+00:00 [running]> on host 523cb283ca0d
[2023-01-04T11:41:43.153+0000] {taskinstance.py:1513} INFO - Exporting the following env vars:
AIRFLOW_CTX_DAG_OWNER=***
AIRFLOW_CTX_DAG_ID=accidents_etl_pipeline
AIRFLOW_CTX_TASK_ID=augment_dataset_task
AIRFLOW_CTX_EXECUTION_DATE=2023-01-02T00:00:00+00:00
AIRFLOW_CTX_TRY_NUMBER=2
AIRFLOW_CTX_DAG_RUN_ID=scheduled__2023-01-02T00:00:00+00:00
[2023-01-04T11:41:43.279+0000] {taskinstance.py:1772} ERROR - Task failed with exception
Traceback (most recent call last):
  File "/home/airflow/.local/lib/python3.7/site-packages/airflow/operators/python.py", line 175, in execute
    return_value = self.execute_callable()
  File "/home/airflow/.local/lib/python3.7/site-packages/airflow/operators/python.py", line 192, in execute_callable
    return self.python_callable(*self.op_args, **self.op_kwargs)
  File "/opt/airflow/dags/Milestone3_2.py", line 109, in augment_dataset
    df_look_up,df_look_up_lsoa= read_look_up(look_up_table)
  File "/opt/airflow/dags/Milestone3_2.py", line 61, in read_look_up
    df_look_up = pd.read_csv(look_up_table_name)
  File "/home/airflow/.local/lib/python3.7/site-packages/pandas/util/_decorators.py", line 311, in wrapper
    return func(*args, **kwargs)
  File "/home/airflow/.local/lib/python3.7/site-packages/pandas/io/parsers/readers.py", line 586, in read_csv
    return _read(filepath_or_buffer, kwds)
  File "/home/airflow/.local/lib/python3.7/site-packages/pandas/io/parsers/readers.py", line 482, in _read
    parser = TextFileReader(filepath_or_buffer, **kwds)
  File "/home/airflow/.local/lib/python3.7/site-packages/pandas/io/parsers/readers.py", line 811, in __init__
    self._engine = self._make_engine(self.engine)
  File "/home/airflow/.local/lib/python3.7/site-packages/pandas/io/parsers/readers.py", line 1040, in _make_engine
    return mapping[engine](self.f, **self.options)  # type: ignore[call-arg]
  File "/home/airflow/.local/lib/python3.7/site-packages/pandas/io/parsers/c_parser_wrapper.py", line 51, in __init__
    self._open_handles(src, kwds)
  File "/home/airflow/.local/lib/python3.7/site-packages/pandas/io/parsers/base_parser.py", line 229, in _open_handles
    errors=kwds.get("encoding_errors", "strict"),
  File "/home/airflow/.local/lib/python3.7/site-packages/pandas/io/common.py", line 707, in get_handle
    newline="",
FileNotFoundError: [Errno 2] No such file or directory: '/opt/airflow/data/look_up_table.csv'
[2023-01-04T11:41:43.291+0000] {taskinstance.py:1327} INFO - Marking task as FAILED. dag_id=accidents_etl_pipeline, task_id=augment_dataset_task, execution_date=20230102T000000, start_date=20230104T114142, end_date=20230104T114143
[2023-01-04T11:41:43.309+0000] {standard_task_runner.py:105} ERROR - Failed to execute job 19 for task augment_dataset_task ([Errno 2] No such file or directory: '/opt/airflow/data/look_up_table.csv'; 387)
[2023-01-04T11:41:43.344+0000] {local_task_job.py:159} INFO - Task exited with return code 1
[2023-01-04T11:41:43.369+0000] {taskinstance.py:2582} INFO - 0 downstream tasks scheduled from follow-on schedule check
