[2023-01-04T20:19:35.043+0000] {taskinstance.py:1087} INFO - Dependencies all met for <TaskInstance: accidents_etl_pipeline.create_dashboard_task manual__2023-01-04T20:11:07.718241+00:00 [queued]>
[2023-01-04T20:19:35.054+0000] {taskinstance.py:1087} INFO - Dependencies all met for <TaskInstance: accidents_etl_pipeline.create_dashboard_task manual__2023-01-04T20:11:07.718241+00:00 [queued]>
[2023-01-04T20:19:35.054+0000] {taskinstance.py:1283} INFO - 
--------------------------------------------------------------------------------
[2023-01-04T20:19:35.054+0000] {taskinstance.py:1284} INFO - Starting attempt 2 of 2
[2023-01-04T20:19:35.061+0000] {taskinstance.py:1285} INFO - 
--------------------------------------------------------------------------------
[2023-01-04T20:19:35.081+0000] {taskinstance.py:1304} INFO - Executing <Task(PythonOperator): create_dashboard_task> on 2023-01-04 20:11:07.718241+00:00
[2023-01-04T20:19:35.088+0000] {standard_task_runner.py:55} INFO - Started process 2191 to run task
[2023-01-04T20:19:35.091+0000] {standard_task_runner.py:82} INFO - Running: ['***', 'tasks', 'run', 'accidents_etl_pipeline', 'create_dashboard_task', 'manual__2023-01-04T20:11:07.718241+00:00', '--job-id', '106', '--raw', '--subdir', 'DAGS_FOLDER/accidents_etl.py', '--cfg-path', '/tmp/tmp5sfnugu7']
[2023-01-04T20:19:35.093+0000] {standard_task_runner.py:83} INFO - Job 106: Subtask create_dashboard_task
[2023-01-04T20:19:35.161+0000] {task_command.py:389} INFO - Running <TaskInstance: accidents_etl_pipeline.create_dashboard_task manual__2023-01-04T20:11:07.718241+00:00 [running]> on host 575b47a6f644
[2023-01-04T20:19:35.256+0000] {taskinstance.py:1513} INFO - Exporting the following env vars:
AIRFLOW_CTX_DAG_OWNER=***
AIRFLOW_CTX_DAG_ID=accidents_etl_pipeline
AIRFLOW_CTX_TASK_ID=create_dashboard_task
AIRFLOW_CTX_EXECUTION_DATE=2023-01-04T20:11:07.718241+00:00
AIRFLOW_CTX_TRY_NUMBER=2
AIRFLOW_CTX_DAG_RUN_ID=manual__2023-01-04T20:11:07.718241+00:00
[2023-01-04T20:19:35.259+0000] {taskinstance.py:1772} ERROR - Task failed with exception
Traceback (most recent call last):
  File "/home/airflow/.local/lib/python3.7/site-packages/airflow/operators/python.py", line 175, in execute
    return_value = self.execute_callable()
  File "/home/airflow/.local/lib/python3.7/site-packages/airflow/operators/python.py", line 192, in execute_callable
    return self.python_callable(*self.op_args, **self.op_kwargs)
  File "/opt/airflow/dags/DashboardCreator.py", line 85, in createDashboard
    df = pd.read_csv(filename)
  File "/home/airflow/.local/lib/python3.7/site-packages/pandas/util/_decorators.py", line 311, in wrapper
    return func(*args, **kwargs)
  File "/home/airflow/.local/lib/python3.7/site-packages/pandas/io/parsers/readers.py", line 586, in read_csv
    return _read(filepath_or_buffer, kwds)
  File "/home/airflow/.local/lib/python3.7/site-packages/pandas/io/parsers/readers.py", line 482, in _read
    parser = TextFileReader(filepath_or_buffer, **kwds)
  File "/home/airflow/.local/lib/python3.7/site-packages/pandas/io/parsers/readers.py", line 811, in __init__
    self._engine = self._make_engine(self.engine)
  File "/home/airflow/.local/lib/python3.7/site-packages/pandas/io/parsers/readers.py", line 1040, in _make_engine
    return mapping[engine](self.f, **self.options)  # type: ignore[call-arg]
  File "/home/airflow/.local/lib/python3.7/site-packages/pandas/io/parsers/c_parser_wrapper.py", line 51, in __init__
    self._open_handles(src, kwds)
  File "/home/airflow/.local/lib/python3.7/site-packages/pandas/io/parsers/base_parser.py", line 229, in _open_handles
    errors=kwds.get("encoding_errors", "strict"),
  File "/home/airflow/.local/lib/python3.7/site-packages/pandas/io/common.py", line 707, in get_handle
    newline="",
FileNotFoundError: [Errno 2] No such file or directory: '/opt/airflow/data/processed_accidents_2011.csv'
[2023-01-04T20:19:35.272+0000] {taskinstance.py:1327} INFO - Marking task as FAILED. dag_id=accidents_etl_pipeline, task_id=create_dashboard_task, execution_date=20230104T201107, start_date=20230104T201935, end_date=20230104T201935
[2023-01-04T20:19:35.284+0000] {standard_task_runner.py:105} ERROR - Failed to execute job 106 for task create_dashboard_task ([Errno 2] No such file or directory: '/opt/airflow/data/processed_accidents_2011.csv'; 2191)
[2023-01-04T20:19:35.304+0000] {local_task_job.py:159} INFO - Task exited with return code 1
[2023-01-04T20:19:35.325+0000] {taskinstance.py:2582} INFO - 0 downstream tasks scheduled from follow-on schedule check
