[2023-01-04T19:47:12.847+0000] {taskinstance.py:1087} INFO - Dependencies all met for <TaskInstance: accidents_etl_pipeline.create_dashboard_task manual__2023-01-04T19:38:20.609062+00:00 [queued]>
[2023-01-04T19:47:12.857+0000] {taskinstance.py:1087} INFO - Dependencies all met for <TaskInstance: accidents_etl_pipeline.create_dashboard_task manual__2023-01-04T19:38:20.609062+00:00 [queued]>
[2023-01-04T19:47:12.858+0000] {taskinstance.py:1283} INFO - 
--------------------------------------------------------------------------------
[2023-01-04T19:47:12.858+0000] {taskinstance.py:1284} INFO - Starting attempt 3 of 3
[2023-01-04T19:47:12.858+0000] {taskinstance.py:1285} INFO - 
--------------------------------------------------------------------------------
[2023-01-04T19:47:12.872+0000] {taskinstance.py:1304} INFO - Executing <Task(PythonOperator): create_dashboard_task> on 2023-01-04 19:38:20.609062+00:00
[2023-01-04T19:47:12.877+0000] {standard_task_runner.py:55} INFO - Started process 474 to run task
[2023-01-04T19:47:12.881+0000] {standard_task_runner.py:82} INFO - Running: ['***', 'tasks', 'run', 'accidents_etl_pipeline', 'create_dashboard_task', 'manual__2023-01-04T19:38:20.609062+00:00', '--job-id', '76', '--raw', '--subdir', 'DAGS_FOLDER/accidents_etl.py', '--cfg-path', '/tmp/tmpsnmuomcy']
[2023-01-04T19:47:12.883+0000] {standard_task_runner.py:83} INFO - Job 76: Subtask create_dashboard_task
[2023-01-04T19:47:12.949+0000] {task_command.py:389} INFO - Running <TaskInstance: accidents_etl_pipeline.create_dashboard_task manual__2023-01-04T19:38:20.609062+00:00 [running]> on host 4de77850e514
[2023-01-04T19:47:13.032+0000] {taskinstance.py:1513} INFO - Exporting the following env vars:
AIRFLOW_CTX_DAG_OWNER=***
AIRFLOW_CTX_DAG_ID=accidents_etl_pipeline
AIRFLOW_CTX_TASK_ID=create_dashboard_task
AIRFLOW_CTX_EXECUTION_DATE=2023-01-04T19:38:20.609062+00:00
AIRFLOW_CTX_TRY_NUMBER=3
AIRFLOW_CTX_DAG_RUN_ID=manual__2023-01-04T19:38:20.609062+00:00
[2023-01-04T19:47:13.934+0000] {logging_mixin.py:137} WARNING - /home/***/.local/lib/python3.7/site-packages/pandas/core/frame.py:4913 SettingWithCopyWarning:
A value is trying to be set on a copy of a slice from a DataFrame

See the caveats in the documentation: https://pandas.pydata.org/pandas-docs/stable/user_guide/indexing.html#returning-a-view-versus-a-copy
[2023-01-04T19:47:14.065+0000] {logging_mixin.py:137} INFO - 0         Kensington and Chelsea
1         Kensington and Chelsea
2         Kensington and Chelsea
3         Kensington and Chelsea
4         Kensington and Chelsea
                   ...          
148932                     Powys
148933                     Powys
148934                     Powys
148935                     Powys
148936                     Powys
Name: local_authority_ons_district, Length: 148937, dtype: object
[2023-01-04T19:47:14.186+0000] {logging_mixin.py:137} INFO - 0          Slight
1         Serious
2          Slight
3          Slight
4          Slight
           ...   
148932     Slight
148933     Slight
148934     Slight
148935     Slight
148936     Slight
Name: accident_severity, Length: 148937, dtype: object
[2023-01-04T19:47:14.216+0000] {logging_mixin.py:137} INFO - 0         30.0
1         30.0
2         30.0
3         30.0
4         30.0
          ... 
148932    60.0
148933    60.0
148934    30.0
148935    60.0
148936    60.0
Name: speed_limit, Length: 148937, dtype: object
[2023-01-04T19:47:15.512+0000] {logging_mixin.py:137} INFO - Dash is running on http://0.0.0.0:8050/
[2023-01-04T19:47:15.512+0000] {dash.py:1968} INFO - Dash is running on http://0.0.0.0:8050/

[2023-01-04T19:47:15.518+0000] {logging_mixin.py:137} INFO -  * Serving Flask app '***'
[2023-01-04T19:47:15.518+0000] {logging_mixin.py:137} INFO -  * Debug mode: off
[2023-01-04T19:47:15.519+0000] {_internal.py:224} INFO - [31m[1mWARNING: This is a development server. Do not use it in a production deployment. Use a production WSGI server instead.[0m
 * Running on all addresses (0.0.0.0)
 * Running on http://127.0.0.1:8050
 * Running on http://172.18.0.5:8050
[2023-01-04T19:47:15.519+0000] {_internal.py:224} INFO - [33mPress CTRL+C to quit[0m
[2023-01-04T19:47:35.081+0000] {_internal.py:224} INFO - 172.18.0.1 - - [04/Jan/2023 19:47:35] "GET / HTTP/1.1" 200 -
[2023-01-04T19:47:35.263+0000] {_internal.py:224} INFO - 172.18.0.1 - - [04/Jan/2023 19:47:35] "GET /_dash-dependencies HTTP/1.1" 200 -
[2023-01-04T19:47:35.508+0000] {_internal.py:224} INFO - 172.18.0.1 - - [04/Jan/2023 19:47:35] "GET /_dash-layout HTTP/1.1" 200 -
[2023-01-04T19:47:35.598+0000] {_internal.py:224} INFO - 172.18.0.1 - - [04/Jan/2023 19:47:35] "[36mGET /_dash-component-suites/dash/dcc/async-graph.js HTTP/1.1[0m" 304 -
[2023-01-04T19:47:35.605+0000] {_internal.py:224} INFO - 172.18.0.1 - - [04/Jan/2023 19:47:35] "[36mGET /_dash-component-suites/dash/dcc/async-plotlyjs.js HTTP/1.1[0m" 304 -
[2023-01-04T19:55:11.771+0000] {local_task_job.py:82} ERROR - Received SIGTERM. Terminating subprocesses
[2023-01-04T19:55:11.775+0000] {process_utils.py:133} INFO - Sending Signals.SIGTERM to group 474. PIDs of all processes in the group: [474]
[2023-01-04T19:55:11.776+0000] {process_utils.py:84} INFO - Sending the signal Signals.SIGTERM to group 474
[2023-01-04T19:55:11.777+0000] {taskinstance.py:1483} ERROR - Received SIGTERM. Terminating subprocesses.
[2023-01-04T19:55:11.793+0000] {taskinstance.py:1772} ERROR - Task failed with exception
Traceback (most recent call last):
  File "/home/airflow/.local/lib/python3.7/site-packages/airflow/operators/python.py", line 175, in execute
    return_value = self.execute_callable()
  File "/home/airflow/.local/lib/python3.7/site-packages/airflow/operators/python.py", line 192, in execute_callable
    return self.python_callable(*self.op_args, **self.op_kwargs)
  File "/opt/airflow/dags/DashboardCreator.py", line 107, in createDashboard
    app.run_server(host = "0.0.0.0")
  File "/home/airflow/.local/lib/python3.7/site-packages/dash/dash.py", line 2133, in run_server
    self.run(*args, **kwargs)
  File "/home/airflow/.local/lib/python3.7/site-packages/dash/dash.py", line 1980, in run
    self.server.run(host=host, port=port, debug=debug, **flask_run_options)
  File "/home/airflow/.local/lib/python3.7/site-packages/flask/app.py", line 1188, in run
    run_simple(t.cast(str, host), port, self, **options)
  File "/home/airflow/.local/lib/python3.7/site-packages/werkzeug/serving.py", line 1098, in run_simple
    srv.serve_forever()
  File "/home/airflow/.local/lib/python3.7/site-packages/werkzeug/serving.py", line 741, in serve_forever
    super().serve_forever(poll_interval=poll_interval)
  File "/usr/local/lib/python3.7/socketserver.py", line 232, in serve_forever
    ready = selector.select(poll_interval)
  File "/usr/local/lib/python3.7/selectors.py", line 415, in select
    fd_event_list = self._selector.poll(timeout)
  File "/home/airflow/.local/lib/python3.7/site-packages/airflow/models/taskinstance.py", line 1485, in signal_handler
    raise AirflowException("Task received SIGTERM signal")
airflow.exceptions.AirflowException: Task received SIGTERM signal
[2023-01-04T19:55:11.807+0000] {taskinstance.py:1327} INFO - Marking task as FAILED. dag_id=accidents_etl_pipeline, task_id=create_dashboard_task, execution_date=20230104T193820, start_date=20230104T194712, end_date=20230104T195511
[2023-01-04T19:55:11.844+0000] {standard_task_runner.py:105} ERROR - Failed to execute job 76 for task create_dashboard_task (Task received SIGTERM signal; 474)
[2023-01-04T19:55:11.912+0000] {process_utils.py:79} INFO - Process psutil.Process(pid=474, status='terminated', exitcode=1, started='19:47:12') (474) terminated with exit code 1
[2023-01-04T19:55:11.913+0000] {local_task_job.py:159} INFO - Task exited with return code 143
[2023-01-04T19:55:11.946+0000] {taskinstance.py:2582} INFO - 0 downstream tasks scheduled from follow-on schedule check
